Workbook

Sheet Reports
A1: Aton Aire Trading Corporation
A2: 2026 | B2: January | C2: February | D2: March | E2: April
A3: Operation
A4: Sales | B4: ='2026 IS'!C5 -> 405325.97 | C4: ='2026 IS'!D5 -> 314994.6 | D4: ='2026 IS'!E5 -> 676068 | E4: ='2026 IS'!F5 -> 664972.26
A5: Cost of Sales | B5: ='2026 IS'!C6 -> -280718.4 | C5: ='2026 IS'!D6 -> -206326.08 | D5: ='2026 IS'!E6+'2026 IS'!E7 -> -527192.8 | E5: ='2026 IS'!F6 -> -500048.32
A6: Gross Margin | B6: ='2026 IS'!C8 -> 124607.57 | C6: ='2026 IS'!D8 -> 108668.52 | D6: ='2026 IS'!E8 -> 148875.2 | E6: ='2026 IS'!F8 -> 164923.94
A7: Opex | B7: =-'2026 IS'!C35 -> -86778.602 | C7: =-'2026 IS'!D35 -> -95045.817 | D7: =-'2026 IS'!E35 -> -149782.08 | E7: =-'2026 IS'!F35 -> -86517.733
A8: Net Income (Loss) | B8: ='2026 IS'!C39 -> 30263.174 | C8: ='2026 IS'!D39 -> 10898.162 | D8: ='2026 IS'!E36 -> -906.88333 | E8: ='2026 IS'!F39 -> 62724.965
A10: Inventory
A11: Beg Balance | B11: ='2026 Purch'!K2 -> 582521.5 | C11: =B14 -> 563271.1 | D11: =C14 -> 576346.62
A12: Purchases | B12: ='2026 Purch'!H20 -> 261468 | C12: ='2026 Purch'!H34 -> 219401.6 | D12: ='2026 Purch'!H53 -> 548340.12
A13: Sold | B13: =-'2026 Purch'!I20 -> -280718.4 | C13: =-'2026 Purch'!I34 -> -206326.08 | D13: =-'2026 Purch'!I53 -> -521692.8
A14: End Balance | B14: =sum(B11:B13) -> 563271.1 | C14: =sum(C11:C13) -> 576346.62 | D14: =sum(D11:D13) -> 602993.94 | E14: =sum(E11:E13) -> 0
A16: Payable
A17: Beg Balance | B17: ='2026 AP'!J15 -> 534000.2 | C17: =B20 -> 462098.8 | D17: =C20 -> 462705.6
A18: Purchases | B18: ='2026 Purch'!H20 -> 261468 | C18: ='2026 Purch'!H34 -> 219401.6 | D18: =D12 -> 548340.12
A19: Payments | B19: =-sum('2026 AP'!H16:H50) -> -333369.4 | C19: =-sum('2026 AP'!H51:H74) -> -218794.8 | D19: =-sum('2026 AP'!H75:H93) -> -504266.72
A20: End Balance | B20: =sum(B17:B19) -> 462098.8 | C20: =sum(C17:C19) -> 462705.6 | D20: =sum(D17:D19) -> 506779 | E20: =sum(E17:E19) -> 0
A22: Receivable
A23: Beg Balance
A24: Additions
A25: Collected
A26: End Balance

Sheet 2026CF
E1: 17329.53
A2: Date | B2: Description | C2: In | D2: Out | E2: Balance | F2: Remarks
C3: =SUM(C5:C1048649) -> 1398388.6 | D3: =SUM(D5:#REF!) -> 1817994.9 | E3: =E1+C3-D3 -> -402276.77
A4: 2026 | B4: Beginning Balance
E5: =E1 -> 17329.53
A6: 46053 | B6: January Cash Sales | C6: 405325.97 | E6: =E5+C6-D6 -> 422655.5
A7: 46029 | B7: Cash Purchase | D7: 15600 | E7: =E6+C7-D7 -> 407055.5 | F7: Uniwestech 2 tanks 134A
A8: 46030 | B8: Expenses for the month | D8: 20538 | E8: =E7+C8-D8 -> 386517.5 | F8: Lalamove from Cubao
A9: 46037 | B9: Salaries Jan 15 2026 | D9: 6000 | E9: =E8+C9-D9 -> 380517.5 | F9: Jocelyn
A10: 46037 | B10: Salaries Jan 15 2026 | D10: 6600 | E10: =E9+C10-D10 -> 373917.5 | F10: Pastor Jun
A11: 46037 | B11: Salaries Jan 15 2026 | D11: 500 | E11: =E10+C11-D11 -> 373417.5 | F11: Christia
A12: 46037 | B12: Salaries Jan 15 2026 | D12: 2500 | E12: =E11+C12-D12 -> 370917.5 | F12: Ishabella JC
A13: 46044 | B13: Payment | D13: 26928 | E13: =E12+C13-D13 -> 343989.5 | F13: Entalpia replacement for check #942972
A14: 46042 | B14: Payment | D14: 20000 | E14: =E13+C14-D14 -> 323989.5 | F14: 938017 Centralworld
A15: 45669 | B15: Payment | D15: 11800 | E15: =E14+C15-D15 -> 312189.5 | F15: 938046 JYQL
A16: 45670 | B16: Payment | D16: 13800 | E16: =E15+C16-D16 -> 298389.5 | F16: 942956 JYQL
A17: 45670 | B17: Payment | D17: 16300 | E17: =E16+C17-D17 -> 282089.5 | F17: 942957 JYQL
A18: 46041 | B18: Payment | D18: 5310 | E18: =E17+C18-D18 -> 276779.5 | F18: 917636 STAL
... A32: 46048 | B32: Payment | D32: 25600 | E32: =E31+C32-D32 -> 10620.1 | F32: 938036 Uniwestech
E33: =E32+C33-D33 -> 10620.1
E34: =E33+C34-D34 -> 10620.1
A35: 46052 | B35: Business Permit | D35: 34000 | E35: =E34+C35-D35 -> -23379.9
A36: 46052 | B36: Salaries Jan 30 2026 | D36: 6600 | E36: =E35+C36-D36 -> -29979.9 | F36: Pastor Jun
A37: 46052 | B37: Salaries Jan 30 2026 | D37: 5000 | E37: =E36+C37-D37 -> -34979.9 | F37: Jocelyn
A38: 46052 | B38: Salaries Jan 30 2026 | D38: 1000 | E38: =E37+C38-D38 -> -35979.9 | F38: Christia
A39: 46052 | B39: Salaries Jan 30 2026 | D39: 5000 | E39: =E38+C39-D39 -> -40979.9 | F39: Rocky
A40: 46055 | B40: LTO Renewal | D40: 9000 | E40: =E39+C40-D40 -> -49979.9 | F40: OR Renewal Suzuki with penalty (2023-2025)
A41: 46056 | B41: Payment | D41: 9854.8 | E41: =E40+C41-D41 -> -59834.7 | F41: Ishabella full payment 4 pcs korea pump
A42: 46058 | B42: Delivery Expense | D42: 531 | E42: =E41+C42-D42 -> -60365.7 | F42: Lalamove from Cubao
A43: 46058 | B43: Cash Collection / Sales | C43: 17839.29 | E43: =E42+C43-D43 -> -42526.41 | F43: Drench, check payment
A44: 46058 | B44: Payment | D44: 27450 | E44: =E43+C44-D44 -> -69976.41 | F44: JYQL
A45: 46058 | B45: Payment | D45: 18610 | E45: =E44+C45-D45 -> -88586.41 | F45: JYQL
A46: 46059 | B46: Payment | D46: 35000 | E46: =E45+C46-D46 -> -123586.41 | F46: Uniwestech replacement for check #942952
A47: 46059 | B47: Bank Charges | D47: 2600 | E47: =E46+C47-D47 -> -126186.41 | F47: JYQL bounced check
A48: 46059 | B48: Delivery Expense | D48: 364 | E48: =E47+C48-D48 -> -126550.41 | F48: Lalamove from Cubao
A49: 46060 | B49: Payment | D49: 12850 | E49: =E48+C49-D49 -> -139400.41 | F49: JYQL replacement for check #942982
A50: 46065 | B50: Delivery Expense | D50: 1000 | E50: =E49+C50-D50 -> -140400.41 | F50: Lalamove from Cubao
A51: 46065 | B51: Cash Collection / Sales | C51: 8000 | E51: =E50+C51-D51 -> -132400.41 | F51: Drench, check payment
A52: 46065 | B52: Payment | D52: 23500 | E52: =E51+C52-D52 -> -155900.41 | F52: JYQL
A53: 46065 | B53: Bank Charges | D53: 2200 | E53: =E52+C53-D53 -> -158100.41 | F53: Winterpine bounced check
...

Sheet 2026 IS
A1: Aton Aire Trading Corporation
A2: Monthly Income/Loss
A3: For the Year 2026
C4: January | D4: February | E4: March | F4: April | G4: May | H4: June | I4: July | J4: August | K4: September | L4: October | M4: November | N4: December | O4: Total
B5: Sales | C5: ='2026 DS'!$F$3 -> 405325.97 | D5: ='2026 DS'!F44 -> 314994.6 | E5: ='2026 DS'!F103 -> 676068 | F5: ='2026 DS'!F170 -> 664972.26 | G5: ='2026 DS'!F239 -> 341484.6 | H5: ='2026 DS'!F291 -> 461234 | I5: ='2026 DS'!F358 -> 799834.6 | O5: =SUM(C5:N5) -> 3663914
B6: Cost of Sales | C6: =-'2026 DS'!$G$3 -> -280718.4 | D6: =-'2026 DS'!G44 -> -206326.08 | E6: =-'2026 DS'!G103 -> -521692.8 | F6: =-'2026 DS'!G170 -> -500048.32 | G6: =-'2026 DS'!G239 -> -222972 | H6: =-'2026 DS'!G291 -> -319265.8 | I6: =-'2026 DS'!G358 -> -593187 | O6: =SUM(C6:N6) -> -2644210.4
B7: Expenses Related to Sales | C7: =-'2026 DS'!$H$3 -> 0 | D7: =-'2026 DS'!H44 -> 0 | E7: =-'2026 DS'!H103 -> -5500 | F7: =-'2026 DS'!H170 -> 0 | G7: =-'2026 DS'!H239 -> 0 | H7: =-'2026 DS'!H291 -> 0 | I7: =-'2026 DS'!H358 -> 0 | O7: =SUM(C7:N7) -> -5500
B8: Gross Margin | C8: =SUM(C5:C7) -> 124607.57 | D8: =SUM(D5:D7) -> 108668.52 | E8: =SUM(E5:E7) -> 148875.2 | F8: =SUM(F5:F7) -> 164923.94 | G8: =SUM(G5:G7) -> 118512.6 | H8: =SUM(H5:H7) -> 141968.2 | I8: =SUM(I5:I7) -> 206647.6 | J8: =SUM(J5:J7) -> 0 | ... O8: =SUM(O5:O7) -> 1014203.6
B9: Gross Profit Ratio | C9: =C8/C5 -> 0.30742558 | D9: =D8/D5 -> 0.34498534 | E9: =E8/E5 -> 0.22020743 | F9: =F8/F5 -> 0.24801627 | G9: =G8/G5 -> 0.34705108 | H9: =H8/H5 -> 0.30780081 | I9: =I8/I5 -> 0.25836292 | J9: =J8/J5 -> #DIV/0! | ... O9: =O8/O5 -> 0.2768088
B11: Operating Expenses (cash)
B13: Salaries | C13: ='2026 Exp'!C6 -> 33200 | D13: ='2026 Exp'!C29 -> 36500 | E13: ='2026 Exp'!C52 -> 37700 | F13: ='2026 Exp'!C76 -> 40000 | G13: ='2026 Exp'!C100 -> 41000 | H13: ='2026 Exp'!C124 -> 40489.62 | I13: ='2026 Exp'!C148 -> 43250 | O13: =SUM(C13:N13) -> 272139.62
B14: 13th Month | C14: ='2026 Exp'!C7 -> 3000 | D14: ='2026 Exp'!C30 -> 3000 | E14: ='2026 Exp'!C53 -> 3000 | F14: ='2026 Exp'!C77 -> 3000 | G14: ='2026 Exp'!C101 -> 3000 | H14: ='2026 Exp'!C125 -> 3000 | I14: ='2026 Exp'!C149 -> 3000 | O14: =SUM(C14:N14) -> 21000
B15: Christmas Expenses | C15: ='2026 Exp'!C8 -> 2000 | D15: ='2026 Exp'!C31 -> 2000 | E15: ='2026 Exp'!C54 -> 2000 | F15: ='2026 Exp'!C78 -> 2000 | G15: ='2026 Exp'!C102 -> 2000 | H15: ='2026 Exp'!C126 -> 2000 | I15: ='2026 Exp'!C150 -> 2000 | O15: =SUM(C15:N15) -> 14000
B16: Business Permit | C16: ='2026 Exp'!C9 -> 2833.3333 | D16: ='2026 Exp'!C32 -> 2833.3333 | E16: ='2026 Exp'!C55 -> 2833.3333 | F16: ='2026 Exp'!C79 -> 2833.3333 | G16: ='2026 Exp'!C103 -> 2833.3333 | H16: ='2026 Exp'!C127 -> 2833.3333 | I16: ='2026 Exp'!C151 -> 2833.3333 | O16: =SUM(C16:N16) -> 19833.333
B17: Percentage tax | C17: ='2026 Exp'!C10 -> 13548.149 | D17: ='2026 Exp'!C33 -> 1855.5 | E17: ='2026 Exp'!C56 -> 11692.65 | F17: ='2026 Exp'!C80 -> 5000 | G17: ='2026 Exp'!C104 -> 5000 | H17: ='2026 Exp'!C128 -> 5000 | I17: ='2026 Exp'!C152 -> 5000 | O17: =SUM(C17:N17) -> 47096.299
B18: Rent | C18: ='2026 Exp'!C11 -> 5000 | D18: ='2026 Exp'!C34 -> 5000 | E18: ='2026 Exp'!C57 -> 5000 | F18: ='2026 Exp'!C81 -> 5000 | G18: ='2026 Exp'!C105 -> 5000 | H18: ='2026 Exp'!C129 -> 5000 | I18: ='2026 Exp'!C153 -> 5000 | O18: =SUM(C18:N18) -> 35000
B19: LTO Renewal | C19: ='2026 Exp'!C12 -> 0 | D19: ='2026 Exp'!C35 -> 9000 | E19: ='2026 Exp'!C58 -> 0 | F19: ='2026 Exp'!C82 -> 0 | G19: ='2026 Exp'!C106 -> 0 | H19: ='2026 Exp'!C130 -> 0 | I19: ='2026 Exp'!C154 -> 0 | O19: =SUM(C19:N19) -> 9000
B20: Electicity & Water | C20: ='2026 Exp'!C13 -> 0 | D20: ='2026 Exp'!C36 -> 0 | E20: ='2026 Exp'!C59 -> 0 | F20: ='2026 Exp'!C83 -> 0 | G20: ='2026 Exp'!C107 -> 0 | H20: ='2026 Exp'!C131 -> 0 | I20: ='2026 Exp'!C155 -> 0 | O20: =SUM(C20:N20) -> 0
B21: Internet | C21: ='2026 Exp'!C14 -> 2500 | D21: ='2026 Exp'!C37 -> 2500 | E21: ='2026 Exp'!C60 -> 2500 | F21: ='2026 Exp'!C84 -> 2500 | G21: ='2026 Exp'!C108 -> 2500 | H21: ='2026 Exp'!C132 -> 2500 | I21: ='2026 Exp'!C156 -> 2500 | O21: =SUM(C21:N21) -> 17500
B22: SSS Contribution | C22: ='2026 Exp'!C15 -> 1210 | D22: ='2026 Exp'!C38 -> 1210 | E22: ='2026 Exp'!C61 -> 1210 | F22: ='2026 Exp'!C85 -> 1210 | G22: ='2026 Exp'!C109 -> 1210 | H22: ='2026 Exp'!C133 -> 1210 | I22: ='2026 Exp'!C157 -> 1210 | O22: =SUM(C22:N22) -> 8470
B23: PHIC Contribution | C23: ='2026 Exp'!C16 -> 300 | D23: ='2026 Exp'!C39 -> 300 | E23: ='2026 Exp'!C62 -> 300 | F23: ='2026 Exp'!C86 -> 300 | G23: ='2026 Exp'!C110 -> 300 | H23: ='2026 Exp'!C134 -> 300 | I23: ='2026 Exp'!C158 -> 300 | O23: =SUM(C23:N23) -> 2100
B24: HDMF Contribution | C24: ='2026 Exp'!C17 -> 200 | D24: ='2026 Exp'!C40 -> 200 | E24: ='2026 Exp'!C63 -> 200 | F24: ='2026 Exp'!C87 -> 200 | G24: ='2026 Exp'!C111 -> 200 | H24: ='2026 Exp'!C135 -> 200 | I24: ='2026 Exp'!C159 -> 200 | O24: =SUM(C24:N24) -> 1400
... B32: Commissions | C32: ='2026 Exp'!C25 -> 7449.12 | D32: ='2026 Exp'!C48 -> 8046.984 | E32: ='2026 Exp'!C71 -> 3061.1 | F32: ='2026 Exp'!C95 -> 6234.4 | G32: ='2026 Exp'!C119 -> 6360.22 | H32: ='2026 Exp'!C143 -> 11371.94 | I32: ='2026 Exp'!C167 -> 11635.78 | O32: =SUM(C32:N32) -> 54159.544
B33: Allowances (Hospitalization) | E33: ='2026 Exp'!C72 -> 60000 | F33: ='2026 Exp'!C96 -> 0 | G33: ='2026 Exp'!C120 -> 0 | H33: ='2026 Exp'!C144 -> 0 | I33: ='2026 Exp'!C168 -> 45224.44 | O33: =SUM(C33:N33) -> 105224.44
B35: Total Opex (cash) | C35: =SUM(C12:C34) -> 86778.602 | D35: =SUM(D12:D34) -> 95045.817 | E35: =SUM(E12:E34) -> 149782.08 | F35: =SUM(F12:F34) -> 86517.733 | G35: =SUM(G12:G34) -> 84063.553 | H35: =SUM(H12:H34) -> 94864.893 | I35: =SUM(I12:I34) -> 153443.55 | J35: =SUM(J12:J34) -> 0 | ... O35: =SUM(O12:O34) -> 750496.24
B36: Income/(Loss) | C36: =C8-C35 -> 37828.968 | D36: =D8-D35 -> 13622.703 | E36: =E8-E35 -> -906.88333 | F36: =F8-F35 -> 78406.207 | G36: =G8-G35 -> 34449.047 | H36: =H8-H35 -> 47103.307 | I36: =I8-I35 -> 53204.047 | J36: =J8-J35 -> 0 | ... O36: =O8-O35 -> 263707.39
B37: Depreciation
B38: Income Tax (20%) | C38: =(C36-C37)*0.2 -> 7565.7935 | D38: =(D36-D37)*0.2 -> 2724.5405 | E38: 0 | F38: =(F36-F37)*0.2 -> 15681.241 | G38: =(G36-G37)*0.2 -> 6889.8093 | H38: =(H36-H37)*0.2 -> 9420.6613 | I38: =(I36-I37)*0.2 -> 10640.809 | J38: =(J36-J37)*0.2 -> 0 | K38: =(K36-K37)*0.2 -> 0 | L38: =(L36-L37)*0.2 -> 0 | M38: =(M36-M37)*0.2 -> 0 | ... O38: =(O36-O37)*0.2 -> 52741.479
B39: Final Net Income/(Loss) | C39: =C36-C37-C38 -> 30263.174 | D39: =D36-D37-D38 -> 10898.162 | E39: =E36-E37-E38 -> -906.88333 | F39: =F36-F37-F38 -> 62724.965 | G39: =G36-G37-G38 -> 27559.237 | H39: =H36-H37-H38 -> 37682.645 | I39: =I36-I37-I38 -> 42563.237 | J39: =J36-J37-J38 -> 0 | ... O39: =O36-O37-O38 -> 210965.91
B40: Net Profit Ratio

Sheet 2026 Exp
B1: Aton Aire Trading Corporation
B2: 2026 Expenses
A3: Month | C3: Total | D3: 1 | E3: 2 | F3: 3 | G3: 4 | H3: 5 | I3: 6 | J3: 7 | K3: 8 | L3: 9 | M3: 10 | N3: 11 | O3: 12 | P3: 13 | Q3: 14 | R3: 15 | S3: 16 | T3: 17 | U3: 18 | V3: 19 | W3: 20 | X3: 21 | Y3: 22 | Z3: 23 | AA3: 24 | AB3: 25 | AC3: 26 | AD3: 27 | AE3: 28 | AF3: 29 | AG3: 30 | AH3: 31
A4: January | B4: Total for the Month | C4: =SUM(C5:C26) -> 86778.602 | D4: =SUM(D5:D26) -> 0 | E4: =SUM(E5:E26) -> 500 | F4: =SUM(F5:F26) -> 0 | G4: =SUM(G5:G26) -> 0 | H4: =SUM(H5:H26) -> 1225 | I4: =SUM(I5:I26) -> 0 | J4: =SUM(J5:J26) -> 2025 | ... AH4: =SUM(AH5:AH26) -> 0
A5: January | B5: Cash | C5: =SUM(D5:AH5) -> 0
A6: January | B6: Salaries | C6: =SUM(D6:AH6) -> 33200 | R6: 15600 | AG6: 17600
A7: January | B7: 13th Month | C7: =SUM(D7:AH7) -> 3000 | AG7: 3000
A8: January | B8: Christmas Expenses | C8: =SUM(D8:AH8) -> 2000 | AG8: 2000
A9: January | B9: Business Permit | C9: =SUM(D9:AH9) -> 2833.3333 | AG9: =34000/12 -> 2833.3333
A10: January | B10: Percentage tax | C10: =SUM(D10:AH10) -> 13548.149 | AG10: ='2026 DS'!N3 -> 13548.149
A11: January | B11: Rent | C11: =SUM(D11:AH11) -> 5000 | AG11: 5000
A12: January | B12: LTO Renewal | C12: =SUM(D12:AH12) -> 0
A13: January | B13: Electicity & Water | C13: =SUM(D13:AH13) -> 0 | AG13: 0
A14: January | B14: Internet | C14: =SUM(D14:AH14) -> 2500 | AG14: 2500
A15: January | B15: SSS Contribution | C15: =SUM(D15:AH15) -> 1210 | AG15: 1210
A16: January | B16: PHIC Contribution | C16: =SUM(D16:AH16) -> 300 | AG16: =12000*0.025 -> 300
A17: January | B17: HDMF Contribution | C17: =SUM(D17:AH17) -> 200 | AG17: 200
A18: January | B18: Store supplies | C18: =SUM(D18:AH18) -> 0
A19: January | B19: Repairs & Maintenance | C19: =SUM(D19:AH19) -> 0
A20: January | B20: Bank Charges | C20: =SUM(D20:AH20) -> 5040 | E20: =500 -> 500 | H20: 25 | J20: 25 | R20: 30 | V20: 20 | Y20: 10 | AC20: =10+2200 -> 2210 | AF20: 2200 | AG20: 20
A21: January | B21: Communication | C21: =SUM(D21:AH21) -> 35 | W21: 35
A22: January | B22: Meals | C22: =SUM(D22:AH22) -> 1700 | J22: 800 | K22: 500 | O22: 100 | Q22: 300
A23: January | B23: Gasoline | C23: =SUM(D23:AH23) -> 4200 | H23: =1000+200 -> 1200 | J23: 1200 | K23: 800 | O23: 100 | R23: 600 | W23: 100 | AG23: 200
A24: January | B24: Deliveries | C24: =SUM(D24:AH24) -> 4563 | K24: 380 | Q24: =650+130 -> 780 | S24: =343+900 -> 1243 | V24: 250 | AD24: =100+720 -> 820 | AE24: =310+780 -> 1090
A25: January | B25: Commissions | C25: =SUM(D25:AH25) -> 7449.12 | AG25: ='2026 Comm'!C4 -> 7449.12
A27: February | B27: Total for the Month | C27: =SUM(C28:C49) -> 95045.817 | D27: =SUM(D28:D49) -> 0 | E27: =SUM(E28:E49) -> 10120 | F27: =SUM(F28:F49) -> 100 | G27: =SUM(G28:G49) -> 0 | H27: =SUM(H28:H49) -> 250 | I27: =SUM(I28:I49) -> 2610 | J27: =SUM(J28:J49) -> 0 | ... AH27: =SUM(AH28:AH49) -> 0
A28: February | B28: Cash | C28: =SUM(D28:AH28) -> 0
A29: February | B29: Salaries | C29: =SUM(D29:AH29) -> 36500 | Q29: 19500 | AE29: 17000
A30: February | B30: 13th Month | C30: =SUM(D30:AH30) -> 3000 | AE30: 3000
A31: February | B31: Christmas Expenses | C31: =SUM(D31:AH31) -> 2000 | AE31: 2000
A32: February | B32: Business Permit | C32: =SUM(D32:AH32) -> 2833.3333 | AE32: =34000/12 -> 2833.3333
A33: February | B33: Percentage tax | C33: =SUM(D33:AH33) -> 1855.5 | AE33: ='2026 DS'!N44 -> 1855.5
A34: February | B34: Rent | C34: =SUM(D34:AH34) -> 5000 | AE34: 5000
A35: February | B35: LTO Renewal | C35: =SUM(D35:AH35) -> 9000 | E35: 9000
A36: February | B36: Electicity & Water | C36: =SUM(D36:AH36) -> 0
A37: February | B37: Internet | C37: =SUM(D37:AH37) -> 2500 | AG37: 2500
A38: February | B38: SSS Contribution | C38: =SUM(D38:AH38) -> 1210 | AG38: 1210
A39: February | B39: PHIC Contribution | C39: =SUM(D39:AH39) -> 300 | AG39: =12000*0.025 -> 300
A40: February | B40: HDMF Contribution | C40: =SUM(D40:AH40) -> 200 | AG40: 200
A41: February | B41: Store supplies | C41: =SUM(D41:AH41) -> 0
...

Sheet 2026 DS
A1: Date | B1: DR # | C1: Customer Name | D1: Sales Agent | E1: Mode | F1: Sales | G1: Capital | H1: Sales related Exp | I1: Margin | J1: GPR | K1: Agents Comm | L1: Remarks | M1: BIR Sales | N1: Percentage Tax
I2: =F:F-G:G-H:H -> 0
A3: For the month of January 2026 | F3: =SUM(F4:F42) -> 405325.97 | G3: =SUM(G4:G42) -> 280718.4 | H3: =SUM(H4:H42) -> 0 | I3: =SUM(I4:I42) -> 124607.57 | J3: =I3/F3 -> 0.30742558 | K3: =SUM(K4:K42) -> 7449.12 | L3: Q1 2026 | M3: 451604.97 | N3: =M3*0.03 -> 13548.149
A4: 46037 | B4: 1559 | C4: TECHPRO | D4: Rocky | E4: Gcash | F4: 2400 | G4: 1500 | I4: =F:F-G:G-H:H -> 900 | J4: =I4/F4 -> 0.375 | K4: =I4*0.2 -> 180
B5: 1560 | C5: 46054 | I5: =F:F-G:G-H:H -> 0 | J5: =I5/F5 -> #DIV/0!
A6: 46030 | B6: 1612 | C6: Subic GS Auto | D6: Store | F6: 68880 | G6: 44145 | I6: =F:F-G:G-H:H -> 24735 | J6: =I6/F6 -> 0.35910279
A7: 46030 | B7: 1613 | C7: Drench | D7: Ikot | F7: 17600 | G7: 8000 | I7: =F:F-G:G-H:H -> 9600 | J7: =I7/F7 -> 0.54545455 | K7: =F7*0.01 -> 176
A8: 46030 | B8: 1614 | C8: RAJ | D8: Ikot | F8: 6600 | G8: 3625 | I8: =F:F-G:G-H:H -> 2975 | J8: =I8/F8 -> 0.45075758 | K8: =F8*0.01 -> 66
A9: 46030 | B9: 1615 | C9: D7A | D9: Ikot | F9: 17900 | G9: 13104 | I9: =F:F-G:G-H:H -> 4796 | J9: =I9/F9 -> 0.26793296 | K9: =F9*0.01 -> 179
A10: 46030 | B10: 1616 | C10: Vhong | D10: Ikot | F10: 7500 | G10: 6234 | I10: =F:F-G:G-H:H -> 1266 | J10: =I10/F10 -> 0.1688 | K10: =F10*0.01 -> 75
A11: 46031 | B11: 1617 | C11: Vhong | D11: Ikot | F11: 12100 | G11: 8620 | I11: =F:F-G:G-H:H -> 3480 | J11: =I11/F11 -> 0.28760331 | K11: =F11*0.01 -> 121
A12: 46034 | B12: 1618 | C12: RAJ | D12: Ikot | F12: 1500 | G12: 800 | I12: =F:F-G:G-H:H -> 700 | J12: =I12/F12 -> 0.46666667 | K12: =F12*0.01 -> 15
A13: 46037 | B13: 1619 | C13: Buenafe | D13: Ikot | F13: 4500 | G13: 2700 | I13: =F:F-G:G-H:H -> 1800 | J13: =I13/F13 -> 0.4 | K13: =F13*0.01 -> 45
A14: 46037 | B14: 1620 | C14: 2011 | D14: Ikot | F14: 800 | G14: 520 | I14: =F:F-G:G-H:H -> 280 | J14: =I14/F14 -> 0.35 | K14: =F14*0.01 -> 8
A15: 46037 | B15: 1621 | C15: D7A | D15: Ikot | F15: 16200 | G15: 12150 | I15: =F:F-G:G-H:H -> 4050 | J15: =I15/F15 -> 0.25 | K15: =F15*0.01 -> 162
A16: 46037 | B16: 1622 | C16: Drench | D16: Ikot | F16: 22600 | G16: =16000+2700 -> 18700 | I16: =F:F-G:G-H:H -> 3900 | J16: =I16/F16 -> 0.17256637 | K16: =F16*0.01 -> 226
A17: 46037 | B17: 1623 | C17: RAJ | D17: Ikot | F17: 1700 | G17: 1200 | I17: =F:F-G:G-H:H -> 500 | J17: =I17/F17 -> 0.29411765 | K17: =F17*0.01 -> 17
A18: 46037 | B18: 1624 | C18: Vhong | D18: Ikot | F18: 1700 | G18: 1400 | I18: =F:F-G:G-H:H -> 300 | J18: =I18/F18 -> 0.17647059 | K18: =F18*0.01 -> 17
A19: 46041 | B19: 1625 | C19: Auto Aire | D19: Ikot | F19: 5000 | G19: 3600 | I19: =F:F-G:G-H:H -> 1400 | J19: =I19/F19 -> 0.28 | K19: =F19*0.01 -> 50
A20: 46043 | B20: 1626 | C20: Buenafe | D20: Ikot | F20: 3000 | G20: 2180 | I20: =F:F-G:G-H:H -> 820 | J20: =I20/F20 -> 0.27333333 | K20: =F20*0.01 -> 30
A21: 46044 | B21: 1627 | C21: D7A | D21: Ikot | F21: 16400 | G21: 10290 | I21: =F:F-G:G-H:H -> 6110 | J21: =I21/F21 -> 0.37256098 | K21: =F21*0.01 -> 164 | L21: DR lacking in computation
A22: 46044 | B22: 1628 | C22: Drench | D22: Ikot | F22: 5000 | G22: 3500 | I22: =F:F-G:G-H:H -> 1500 | J22: =I22/F22 -> 0.3 | K22: =F22*0.01 -> 50
A23: 46045 | B23: 1629 | C23: Auto Aire | D23: Ikot | F23: 3600 | G23: 2450 | I23: =F:F-G:G-H:H -> 1150 | J23: =I23/F23 -> 0.31944444 | K23: =F23*0.01 -> 36
A24: 46048 | B24: 1630 | C24: Buenafe | D24: Ikot | F24: 1500 | G24: 1050 | I24: =F:F-G:G-H:H -> 450 | J24: =I24/F24 -> 0.3 | K24: =F24*0.01 -> 15
A25: 46048 | B25: 1631 | C25: Mervin Hilotin | D25: Ikot | F25: 7600 | G25: 5360 | I25: =F:F-G:G-H:H -> 2240 | J25: =I25/F25 -> 0.29473684 | K25: =F25*0.01 -> 76
A26: 46046 | B26: 1632 | C26: Vhong | D26: Ikot | F26: 8900 | G26: 6600 | I26: =F:F-G:G-H:H -> 2300 | J26: =I26/F26 -> 0.25842697 | K26: =F26*0.01 -> 89
A27: 46051 | B27: 1633 | C27: Auto Aire | D27: Ikot | F27: 1600 | G27: 1150 | I27: =F:F-G:G-H:H -> 450 | J27: =I27/F27 -> 0.28125 | K27: =F27*0.01 -> 16
A28: 46051 | B28: 1634 | C28: Auto Aire | D28: Ikot | F28: 1900 | G28: 1350 | I28: =F:F-G:G-H:H -> 550 | J28: =I28/F28 -> 0.28947368 | K28: =F28*0.01 -> 19
A29: 46051 | B29: 1635 | C29: D7A | D29: Ikot | F29: 8000 | G29: 4850 | I29: =F:F-G:G-H:H -> 3150 | J29: =I29/F29 -> 0.39375 | K29: =F29*0.01 -> 80
A30: 46051 | B30: 1636 | C30: Drench | D30: Ikot | F30: 18000 | G30: 16400 | I30: =F:F-G:G-H:H -> 1600 | J30: =I30/F30 -> 0.088888889 | K30: =F30*0.01 -> 180
A31: 46051 | B31: 1637 | C31: RAJ | D31: Ikot | F31: 7100 | G31: 5000 | I31: =F:F-G:G-H:H -> 2100 | J31: =I31/F31 -> 0.29577465 | K31: =F31*0.01 -> 71
A32: 46051 | B32: 1638 | C32: Darla | D32: Ikot | F32: 6860 | G32: 4850 | I32: =F:F-G:G-H:H -> 2010 | J32: =I32/F32 -> 0.29300292 | K32: =F32*0.01 -> 68.6
B33: 1655 | C33: cancelled | I33: =F:F-G:G-H:H -> 0 | J33: =I33/F33 -> #DIV/0!
B34: 1656 | C34: cancelled | I34: =F:F-G:G-H:H -> 0 | J34: =I34/F34 -> #DIV/0!
A35: 46036 | B35: 1657 | C35: Matthew Tan | D35: Rocky | E35: Gcash | F35: 4200 | G35: 2142.4 | I35: =F:F-G:G-H:H -> 2057.6 | J35: =I35/F35 -> 0.48990476 | K35: =I35*0.2 -> 411.52
A36: 46036 | B36: 1658 | C36: Subic GS Auto | D36: Store | E36: Check | F36: 3999.97 | G36: 1200 | I36: =F:F-G:G-H:H -> 2799.97 | J36: =I36/F36 -> 0.69999775
A37: 46036 | B37: 1659 | C37: Subic GS Auto | D37: Store | E37: Check | F37: 36786 | G37: 26928 | I37: =F:F-G:G-H:H -> 9858 | J37: =I37/F37 -> 0.26798238
A38: 46041 | B38: 1660 | C38: Vi N Vi | D38: Rocky | E38: Cash | F38: 12700 | G38: 7500 | I38: =F:F-G:G-H:H -> 5200 | J38: =I38/F38 -> 0.40944882 | K38: =I38*0.2 -> 1040
B39: 1661 | C39: cancelled | I39: =F:F-G:G-H:H -> 0 | J39: =I39/F39 -> #DIV/0!
A40: 46045 | B40: 1662 | C40: Marelco | D40: Rocky | E40: Cash | F40: 60000 | G40: 45000 | I40: =F:F-G:G-H:H -> 15000 | J40: =I40/F40 -> 0.25 | K40: =I40*0.2 -> 3000
...

Sheet 2026 Ikot
A1: 2025 Ikot Summary
A3: Sales: | F3: Collection
A4: DR # | B4: Customer Name | C4: Amount | D4: Mode | F4: CR # | G4: Customer Name | H4: Amount | I4: Mode | J4: Remarks
B5: Jan 8 2026 | C5: =SUM(C6:C17) -> 88100 | G5: Mervin Hilotin | H5: 3000 | I5: Gcash
A6: 1613 | B6: Drench | C6: 17600 | G6: June Tibayan | H6: 2000 | I6: Cash | J6: Rocky Expense 1400
A7: 1614 | B7: RAJ | C7: 6600 | G7: D7A | H7: 5000 | I7: Gcash
A8: 1615 | B8: D7A | C8: 17900 | D8: Gcash | G8: MHM | H8: 2000 | I8: Gcash
A9: 1616 | B9: Vhong | C9: 7500 | D9: Cash | G9: RAJ | H9: 6600 | I9: Cash | J9: expense 1300 gas & meal
A10: 1617 | B10: Vhong | C10: 12100
A11: 1618 | B11: RAJ | C11: 1500
A12: 1619 | B12: Buenafe | C12: 4500
A13: 1620 | B13: 2011 | C13: 800
A14: 1621 | B14: D7A | C14: 16200 | G14: 46058
A15: 1622 | F15: 664 | G15: D7A | H15: 13300
A16: 1623 | B16: RAJ | C16: 1700 | F16: 665 | G16: Drench | H16: 17839.29
A17: 1624 | B17: Vhong | C17: 1700 | F17: 666 | G17: VHONG | H17: 5000
G19: 46065
A20: 1625 | B20: Auto Aire | C20: 5000 | D20: Gcash | F20: 667 | G20: MESAR | H20: 1000
A21: 1626 | B21: Buenafe | C21: 3000 | D21: Gcash | F21: 668 | G21: D7A | H21: 9000
A22: 1627 | B22: Buenafe | C22: 1500 | F22: 669 | G22: Drench | H22: 8000
A23: 1628 | B23: Mervin Hilotin | C23: 7600 | F23: 670 | G23: VHONG | H23: 5000
A24: 1629 | B24: Vhong | C24: 8900 | F24: 671 | G24: Darla | H24: 5000
A25: 1630 | B25: Buenafe | C25: 1500
A26: 1631 | G26: 46072
A27: 1632 | F27: 672 | G27: D7A | H27: 9000
A28: 1633 | F28: 673 | G28: MHM | H28: 2000
A29: 1634 | F29: 674 | G29: VHONG | H29: 5000
G31: 46079
A32: 1635 | F32: 675 | G32: D7A | H32: 14050
A33: 1636 | F33: 676 | G33: VHONG | H33: 5000
A34: 1637 | F34: 677 | G34: Darla | H34: 5000
G36: 46083
F37: 682 | G37: Subic GS Auto | H37: 17982
G39: 46085
A40: 1638 | F40: 678 | G40: Subic GS Auto | H40: 5328
B41: February 03, 2026
A42: 1639 | B42: Auto Aire | C42: 1800 | G42: 46086
A43: 1640 | B43: Auto Aire | C43: 2800 | F43: 679 | G43: D7A | H43: 18000
F44: 680 | G44: Drench | H44: 18500
B45: 46058 | F45: 681 | G45: MHM | H45: 1500
...

Sheet 2026 Purch
A1: Date | B1: Ref # | C1: Suppliers Name | D1: Term | E1: Amount | F1: Payment | G1: Date | H1: Total Purchases Monthly | I1: Cost of Sales | J1: Inventory Balance | K1: End Balance Dec 31 2025
D2: Days | E2: =sum(E4:E1035) -> 3540492.6 | F2: =sum(F4:F1035) -> 0 | H2: =sum(H4:H1035) -> 2104151 | I2: =sum(I4:I1035) -> 2051023.4 | J2: =K2+H2-I2 -> 635649.14 | K2: 582521.5 | M2: Due Date | N2: Check #
A3: 45995 | B3: DR#191 | C3: STAL | D3: 90 | E3: 4750 | L3: issued check
A4: 45994 | B4: DR#189 | C4: STAL | D4: 90 | E4: 31350 | L4: issued check
A5: 46009 | B5: DR#197 | C5: STAL | D5: 90 | E5: 5100 | L5: issued check
A6: 46029 | B6: DR#94218 | C6: JYQL | D6: 30 | E6: 10290 | L6: issued check
A7: 46030 | B7: DR#002 | C7: ENTALPIA | D7: 15 | E7: 44145 | L7: paid
A8: 46035 | B8: DR#70746 | C8: JYQL | D8: 30 | E8: 9400 | L8: issued check
A9: 46036 | C9: UNIWESTECH | D9: 7 | E9: 16000 | L9: paid
A10: 46036 | B10: DR#108 | C10: STAL | D10: 90 | E10: 14550 | L10: issued check
A11: 46037 | B11: DR#001 | C11: ENTALPIA | D11: 15 | E11: 26928 | L11: paid
A12: 46038 | B12: DR#91780 | C12: JYQL | D12: 30 | E12: 19240 | L12: issued check
A13: 46041 | B13: DR#14429 | C13: JYQL | D13: 30 | E13: 9200 | L13: issued check
A14: 46042 | B14: DR#44561 | C14: JYQL | D14: 30 | E14: 45000 | L14: issued check
A15: 46043 | B15: DR#110 | C15: STAL | D15: 90 | E15: 6750 | L15: issued check
A16: 46044 | B16: DR#111 | C16: STAL | D16: 90 | E16: 5650 | L16: issued check
A17: 46044 | B17: DR#85619 | C17: JYQL | D17: 30 | E17: 6385 | L17: issued check
A18: 46049 | B18: DR#95150 | C18: JYQL | D18: 30 | E18: 20730 | L18: issued check
A19: 46049 | B19: DR#116 | C19: STAL | D19: 90 | E19: 10800 | L19: issued check
A20: 46051 | C20: UNIWESTECH | D20: 7 | E20: 16400 | H20: =sum(E6:E20) -> 261468 | I20: ='2026 DS'!G3 -> 280718.4 | J20: =K2+H20-I20 -> 563271.1 | L20: issued check
A21: 46051 | B21: DR#119 | C21: STAL | D21: 90 | E21: 8500 | L21: issued check | M21: =A21+D21 -> 46141
A22: 46056 | B22: DR#126 | C22: STAL | D22: 90 | E22: 10500 | L22: issued check | M22: =A22+D22 -> 46146 | N22: 943019
A23: 46056 | C23: ISHABELLA | D23: 0 | E23: =9854.8 -> 9854.8 | L23: paid
A24: 46057 | B24: DR#51328 | C24: JYQL | D24: 30 | E24: 2780 | L24: issued check | M24: =A24+D24+15 -> 46102
A25: 46057 | B25: DR#92794 | C25: JYQL | D25: 30 | E25: 4750 | L25: issued check | M25: =A25+D25+15 -> 46102
A26: 46058 | B26: DR#127 | C26: STAL | D26: 90 | E26: 15550 | L26: issued check | M26: =A26+D26 -> 46148
A27: 46065 | B27: DR#21733 | C27: JYQL | D27: 30 | E27: 17050 | L27: issued check | M27: =A27+D27+15 -> 46110
A28: 46071 | B28: DR#52984 | C28: JYQL | D28: 30 | E28: 18090 | L28: issued check | M28: =A28+D28+15 -> 46116
A29: 46071 | B29: DR#130 | C29: STAL | D29: 90 | E29: 11750 | L29: issued check | M29: =A29+D29 -> 46161
A30: 46073 | C30: UNIWESTECH | D30: 0 | E30: 16600 | L30: paid
A31: 46077 | B31: DR# 45034 | C31: JYQL | D31: 30 | E31: 7840 | L31: issued check | M31: =A31+D31+15 -> 46122
A32: 46076 | B32: DR# 0132 | C32: STAL | D32: 90 | E32: 43850 | L32: issued check | M32: =A32+D32 -> 46166 | O32: 46178 | P32: 20000/23850
A33: 46078 | C33: ISHABELLA | D33: 30 | E33: =9854.8+7072 -> 16926.8 | L33: paid | Q33: 2pcs DP 8m | R33: 5570
A34: 46078 | C34: ENTALPIA | D34: 10 | E34: =5*7072 -> 35360 | H34: =sum(E21:E34) -> 219401.6 | I34: ='2026 DS'!G44 -> 206326.08 | J34: =J20+H34-I34 -> 576346.62 | L34: c/o Ishabella | M34: =A34 -> 46078 | Q34: 1 tank 134A | R34: 7072
A35: 46084 | B35: DR# 93049 | C35: JYQL | D35: 38 | E35: 15095 | L35: issued check | M35: =A35+D35 -> 46122 | N35: 943020 | Q35: Total | R35: =SUM(P37:P42) -> 4284.8
A36: 46085 | B36: DR# 74013 | C36: JYQL | D36: 37 | E36: 5600 | L36: issued check | M36: =A36+D36 -> 46122 | O36: Ishabella | Q36: 2/18/2026 deposit | R36: -3964.29
A37: 46086 | B37: DR# 139 | C37: STAL | D37: 90 | E37: 20000 | L37: issued check | M37: =A37+D37 -> 46176 | N37: 943021 | O37: 2pcs DP 6m | P37: 4284.8 | Q37: 2/25/2026 deposit | R37: -3172.42
A38: 46092 | B38: DR# 61845 | C38: JYQL | D38: 37 | E38: 38530 | L38: issued check | M38: =A38+D38 -> 46129 | N38: 943022 | Q38: 03/02/2026 deposit | R38: -5328
A39: 46092 | B39: DR# 143 | C39: STAL | D39: 90 | E39: 20680 | L39: issued check | M39: =A39+D39 -> 46182 | N39: 943023 | Q39: 03/02/2026 full payment | R39: =-sum(R35:R38) -> 8179.91
A40: 46097 | B40: DR# 0117 | C40: HYSIS | D40: 10 | E40: 191644.12 | L40: issued check | M40: =A40+D40 -> 46107 | O40: 2 checks | Q40: Balance | R40: =sum(R35:R39) -> 0
...

Sheet 2026 AP
A1: Aton Aire Trading Corporation | G1: Summary | H1: Payment | I1: Purchases | J1: Balance
A2: 2026 Payable | G2: Ishabella | H2: =K12 -> 182141.6 | I2: =L12 -> 142471.2 | J2: =M12 -> -134107.4
A3: =TODAY() -> 46311 | G3: JYQL | H3: =N12 -> 594175 | I3: =O12 -> 675800 | J3: =P12 -> 284235
G4: STAL | H4: =Q12 -> 282470 | I4: =R12 -> 395940 | J4: =S12 -> 382490
G5: Winterpine | H5: =T12 -> 271260.32 | I5: =U12 -> 307449.12 | J5: =V12 -> 112396
G6: Hisys | H6: =W12 -> 246667.72 | I6: =X12 -> 246667.72 | J6: =Y12 -> 0
G7: Uniwestech | H7: =Z12 -> 129600 | I7: =AA12 -> 49000 | J7: =AB12 -> 0
G8: Entalpia | H8: =AC12 -> 71073 | I8: =AD12 -> 71073 | J8: =AE12 -> 0
G9: 3BMA | H9: =AF12 -> 69300 | I9: =AG12 -> 209500 | J9: =AH12 -> 140200
H11: =sum(H2:H10) -> 1846687.6 | I11: =sum(I2:I10) -> 2097901 | J11: =sum(J2:J10) -> 785213.6
H12: =SUM(H16:H1048583) -> 1846687.6 | I12: =SUM(I16:#REF!) -> 2097901 | J12: =J15+I12-H12 -> 785213.6 | K12: =SUM(K16:K1048583) -> 182141.6 | L12: =SUM(L16:#REF!) -> 142471.2 | M12: =M15+L12-K12 -> -134107.4 | N12: =SUM(N16:N1048583) -> 594175 | O12: =SUM(O16:#REF!) -> 675800 | P12: =P15+O12-N12 -> 284235 | Q12: =SUM(Q16:Q1048583) -> 282470 | R12: =SUM(R16:#REF!) -> 395940 | S12: =S15+R12-Q12 -> 382490 | T12: =SUM(T16:T1048583) -> 271260.32 | U12: =SUM(U16:#REF!) -> 307449.12 | V12: =V15+U12-T12 -> 112396 | W12: =SUM(W16:W1048583) -> 246667.72 | X12: =SUM(X16:#REF!) -> 246667.72 | Y12: =Y15+X12-W12 -> 0 | Z12: =SUM(Z16:Z1048583) -> 129600 | AA12: =SUM(AA16:#REF!) -> 49000 | AB12: =AB15+AA12-Z12 -> 0 | AC12: =SUM(AC16:AC1048583) -> 71073 | AD12: =SUM(AD16:#REF!) -> 71073 | AE12: =AE15+AD12-AC12 -> 0 | AF12: =SUM(AF16:AF1048583) -> 69300 | AG12: =SUM(AG16:#REF!) -> 209500 | AH12: =AH15+AG12-AF12 -> 140200 | AI12: =SUM(AI16:AI1048583) -> 0 | AJ12: =SUM(AJ16:#REF!) -> 0 | AK12: =AK15+AJ12-AI12 -> 0 | AL12: =SUM(AL16:AL1048583) -> 0 | AM12: =SUM(AM16:#REF!) -> 0 | AN12: =AN15+AM12-AL12 -> 0
I13: OverAll | K13: ISHABELLA | N13: JYQL AIRCON PARTS TRADING | Q13: STAL | T13: WINTERPINE AIR CONDITIONING CORP | W13: HISYS / KM AIRE ALLIANCE CORP | Z13: UNIWESTECH | AC13: ENTALPIA | AF13: 3BMA
A14: Term | B14: Date | C14: Due Date | D14: Particulars | E14: Supplier | F14: DR # | G14: Check # | H14: Debit | I14: Credit | J14: Balance | K14: Debit | L14: Credit | M14: Balance | N14: Debit | O14: Credit | P14: Balance | Q14: Debit | R14: Credit | S14: Balance | T14: Debit | U14: Credit | V14: Balance | W14: Debit | X14: Credit | Y14: Balance | Z14: Debit | AA14: Credit | AB14: Balance | AC14: Debit | AD14: Credit | AE14: Balance | AF14: Debit | AG14: Credit | AH14: Balance | AI14: Debit | AJ14: Credit | AK14: Balance | AL14: Debit | AM14: Credit | AN14: Balance
A15: Days | B15: 46024 | D15: Beg Bal | J15: =sum(M15,P15,S15,V15,Y15,AB15,AE15,AH15,AK15,AN15) -> 534000.2 | M15: -94437 | P15: 202610 | S15: 269020 | V15: =50976.4+25230.8 -> 76207.2 | Y15: 0 | AB15: 80600 | AE15: 0 | AH15: 0 | AK15: 0 | AN15: 0
A16: 30 | B16: 46029 | C16: =B16+A16 -> 46059 | D16: Purchases | F16: 94218 JYQL | H16: =sum(K16,N16,Q16,T16,W16,Z16,AC16,AF16,AI16,AL16) -> 0 | I16: =sum(L16,O16,R16,U16,X16,AA16,AD16,AG16,AJ16,AM16) -> 10290 | J16: =sum(M16,P16,S16,V16,Y16,AB16,AE16,AH16,AK16,AN16) -> 544290.2 | M16: =M15+L16-K16 -> -94437 | O16: 10290 | P16: =P15+O16-N16 -> 212900 | S16: =S15+R16-Q16 -> 269020 | V16: =V15+U16-T16 -> 76207.2 | Y16: =Y15+X16-W16 -> 0 | AB16: =AB15+AA16-Z16 -> 80600 | AE16: =AE15+AD16-AC16 -> 0 | AH16: =AH15+AG16-AF16 -> 0 | AK16: =AK15+AJ16-AI16 -> 0 | AN16: =AN15+AM16-AL16 -> 0
A17: 30 | B17: 46035 | C17: =B17+A17 -> 46065 | D17: Purchases | F17: 70746 JYQL | H17: =sum(K17,N17,Q17,T17,W17,Z17,AC17,AF17,AI17,AL17) -> 0 | I17: =sum(L17,O17,R17,U17,X17,AA17,AD17,AG17,AJ17,AM17) -> 9400 | J17: =sum(M17,P17,S17,V17,Y17,AB17,AE17,AH17,AK17,AN17) -> 553690.2 | M17: =M16+L17-K17 -> -94437 | O17: 9400 | P17: =P16+O17-N17 -> 222300 | S17: =S16+R17-Q17 -> 269020 | V17: =V16+U17-T17 -> 76207.2 | Y17: =Y16+X17-W17 -> 0 | AB17: =AB16+AA17-Z17 -> 80600 | AE17: =AE16+AD17-AC17 -> 0 | AH17: =AH16+AG17-AF17 -> 0 | AK17: =AK16+AJ17-AI17 -> 0 | AN17: =AN16+AM17-AL17 -> 0
A18: 30 | B18: 46038 | C18: =B18+A18 -> 46068 | D18: Purchases | F18: 91780 JYQL | H18: =sum(K18,N18,Q18,T18,W18,Z18,AC18,AF18,AI18,AL18) -> 0 | I18: =sum(L18,O18,R18,U18,X18,AA18,AD18,AG18,AJ18,AM18) -> 19240 | J18: =sum(M18,P18,S18,V18,Y18,AB18,AE18,AH18,AK18,AN18) -> 572930.2 | M18: =M17+L18-K18 -> -94437 | O18: 19240 | P18: =P17+O18-N18 -> 241540 | S18: =S17+R18-Q18 -> 269020 | V18: =V17+U18-T18 -> 76207.2 | Y18: =Y17+X18-W18 -> 0 | AB18: =AB17+AA18-Z18 -> 80600 | AE18: =AE17+AD18-AC18 -> 0 | AH18: =AH17+AG18-AF18 -> 0 | AK18: =AK17+AJ18-AI18 -> 0 | AN18: =AN17+AM18-AL18 -> 0
A19: 30 | B19: 46041 | C19: =B19+A19 -> 46071 | D19: Purchases | F19: 14429 JYQL | H19: =sum(K19,N19,Q19,T19,W19,Z19,AC19,AF19,AI19,AL19) -> 0 | I19: =sum(L19,O19,R19,U19,X19,AA19,AD19,AG19,AJ19,AM19) -> 9200 | J19: =sum(M19,P19,S19,V19,Y19,AB19,AE19,AH19,AK19,AN19) -> 582130.2 | M19: =M18+L19-K19 -> -94437 | O19: 9200 | P19: =P18+O19-N19 -> 250740 | S19: =S18+R19-Q19 -> 269020 | V19: =V18+U19-T19 -> 76207.2 | Y19: =Y18+X19-W19 -> 0 | AB19: =AB18+AA19-Z19 -> 80600 | AE19: =AE18+AD19-AC19 -> 0 | AH19: =AH18+AG19-AF19 -> 0 | AK19: =AK18+AJ19-AI19 -> 0 | AN19: =AN18+AM19-AL19 -> 0
A20: 30 | B20: 46042 | C20: =B20+A20 -> 46072 | D20: Purchases | F20: 44561 JYQL | H20: =sum(K20,N20,Q20,T20,W20,Z20,AC20,AF20,AI20,AL20) -> 0 | I20: =sum(L20,O20,R20,U20,X20,AA20,AD20,AG20,AJ20,AM20) -> 22500 | J20: =sum(M20,P20,S20,V20,Y20,AB20,AE20,AH20,AK20,AN20) -> 604630.2 | M20: =M19+L20-K20 -> -94437 | O20: 22500 | P20: =P19+O20-N20 -> 273240 | S20: =S19+R20-Q20 -> 269020 | V20: =V19+U20-T20 -> 76207.2 | Y20: =Y19+X20-W20 -> 0 | AB20: =AB19+AA20-Z20 -> 80600 | AE20: =AE19+AD20-AC20 -> 0 | AH20: =AH19+AG20-AF20 -> 0 | AK20: =AK19+AJ20-AI20 -> 0 | AN20: =AN19+AM20-AL20 -> 0
A21: 30 | B21: 46042 | C21: =B21+A21 -> 46072 | D21: Purchases | F21: 44561 JYQL | H21: =sum(K21,N21,Q21,T21,W21,Z21,AC21,AF21,AI21,AL21) -> 0 | I21: =sum(L21,O21,R21,U21,X21,AA21,AD21,AG21,AJ21,AM21) -> 22500 | J21: =sum(M21,P21,S21,V21,Y21,AB21,AE21,AH21,AK21,AN21) -> 627130.2 | M21: =M20+L21-K21 -> -94437 | O21: 22500 | P21: =P20+O21-N21 -> 295740 | S21: =S20+R21-Q21 -> 269020 | V21: =V20+U21-T21 -> 76207.2 | Y21: =Y20+X21-W21 -> 0 | AB21: =AB20+AA21-Z21 -> 80600 | AE21: =AE20+AD21-AC21 -> 0 | AH21: =AH20+AG21-AF21 -> 0 | AK21: =AK20+AJ21-AI21 -> 0 | AN21: =AN20+AM21-AL21 -> 0
A22: 30 | B22: 46044 | C22: =B22+A22 -> 46074 | D22: Purchases | F22: 85619 JYQL | H22: =sum(K22,N22,Q22,T22,W22,Z22,AC22,AF22,AI22,AL22) -> 0 | I22: =sum(L22,O22,R22,U22,X22,AA22,AD22,AG22,AJ22,AM22) -> 6385 | J22: =sum(M22,P22,S22,V22,Y22,AB22,AE22,AH22,AK22,AN22) -> 633515.2 | M22: =M21+L22-K22 -> -94437 | O22: 6385 | P22: =P21+O22-N22 -> 302125 | S22: =S21+R22-Q22 -> 269020 | V22: =V21+U22-T22 -> 76207.2 | Y22: =Y21+X22-W22 -> 0 | AB22: =AB21+AA22-Z22 -> 80600 | AE22: =AE21+AD22-AC22 -> 0 | AH22: =AH21+AG22-AF22 -> 0 | AK22: =AK21+AJ22-AI22 -> 0 | AN22: =AN21+AM22-AL22 -> 0
A23: 30 | B23: 46049 | C23: =B23+A23 -> 46079 | D23: Purchases | F23: 95150 JYQL | H23: =sum(K23,N23,Q23,T23,W23,Z23,AC23,AF23,AI23,AL23) -> 0 | I23: =sum(L23,O23,R23,U23,X23,AA23,AD23,AG23,AJ23,AM23) -> 20730 | J23: =sum(M23,P23,S23,V23,Y23,AB23,AE23,AH23,AK23,AN23) -> 654245.2 | M23: =M22+L23-K23 -> -94437 | O23: 20730 | P23: =P22+O23-N23 -> 322855 | S23: =S22+R23-Q23 -> 269020 | V23: =V22+U23-T23 -> 76207.2 | Y23: =Y22+X23-W23 -> 0 | AB23: =AB22+AA23-Z23 -> 80600 | AE23: =AE22+AD23-AC23 -> 0 | AH23: =AH22+AG23-AF23 -> 0 | AK23: =AK22+AJ23-AI23 -> 0 | AN23: =AN22+AM23-AL23 -> 0
B24: 46042 | D24: Payment | E24: Centralworld | G24: 938017 | H24: =sum(K24,N24,Q24,T24,W24,Z24,AC24,AF24,AI24,AL24) -> 20000 | I24: =sum(L24,O24,R24,U24,X24,AA24,AD24,AG24,AJ24,AM24) -> 0 | J24: =sum(M24,P24,S24,V24,Y24,AB24,AE24,AH24,AK24,AN24) -> 622445.2 | K24: 20000 | M24: =M23+L24-K24 -> -114437 | P24: =P23+O24-N25 -> 311055 | S24: =S23+R24-Q24 -> 269020 | V24: =V23+U24-T24 -> 76207.2 | Y24: =Y23+X24-W24 -> 0 | AB24: =AB23+AA24-Z24 -> 80600 | AE24: =AE23+AD24-AC24 -> 0 | AH24: =AH23+AG24-AF24 -> 0 | AK24: =AK23+AJ24-AI24 -> 0 | AN24: =AN23+AM24-AL24 -> 0
B25: 45669 | D25: Payment | E25: JYQL | G25: 938046 | H25: =sum(K25,N25,Q25,T25,W25,Z25,AC25,AF25,AI25,AL25) -> 11800 | I25: =sum(L25,O25,R25,U25,X25,AA25,AD25,AG25,AJ25,AM25) -> 0 | J25: =sum(M25,P25,S25,V25,Y25,AB25,AE25,AH25,AK25,AN25) -> 608645.2 | M25: =M24+L25-K25 -> -114437 | N25: 11800 | P25: =P24+O25-N26 -> 297255 | S25: =S24+R25-Q25 -> 269020 | V25: =V24+U25-T25 -> 76207.2 | Y25: =Y24+X25-W25 -> 0 | AB25: =AB24+AA25-Z25 -> 80600 | AE25: =AE24+AD25-AC25 -> 0 | AH25: =AH24+AG25-AF25 -> 0 | AK25: =AK24+AJ25-AI25 -> 0 | AN25: =AN24+AM25-AL25 -> 0
B26: 45670 | D26: Payment | E26: JYQL | G26: 942956 | H26: =sum(K26,N26,Q26,T26,W26,Z26,AC26,AF26,AI26,AL26) -> 13800 | I26: =sum(L26,O26,R26,U26,X26,AA26,AD26,AG26,AJ26,AM26) -> 0 | J26: =sum(M26,P26,S26,V26,Y26,AB26,AE26,AH26,AK26,AN26) -> 592345.2 | M26: =M25+L26-K26 -> -114437 | N26: 13800 | P26: =P25+O26-N27 -> 280955 | S26: =S25+R26-Q26 -> 269020 | V26: =V25+U26-T26 -> 76207.2 | Y26: =Y25+X26-W26 -> 0 | AB26: =AB25+AA26-Z26 -> 80600 | AE26: =AE25+AD26-AC26 -> 0 | AH26: =AH25+AG26-AF26 -> 0 | AK26: =AK25+AJ26-AI26 -> 0 | AN26: =AN25+AM26-AL26 -> 0
B27: 45670 | D27: Payment | E27: JYQL | G27: 942957 | H27: =sum(K27,N27,Q27,T27,W27,Z27,AC27,AF27,AI27,AL27) -> 16300 | I27: =sum(L27,O27,R27,U27,X27,AA27,AD27,AG27,AJ27,AM27) -> 0 | J27: =sum(M27,P27,S27,V27,Y27,AB27,AE27,AH27,AK27,AN27) -> 592345.2 | M27: =M26+L27-K27 -> -114437 | N27: 16300 | P27: =P26+O27-N28 -> 280955 | S27: =S26+R27-Q27 -> 269020 | V27: =V26+U27-T27 -> 76207.2 | Y27: =Y26+X27-W27 -> 0 | AB27: =AB26+AA27-Z27 -> 80600 | AE27: =AE26+AD27-AC27 -> 0 | AH27: =AH26+AG27-AF27 -> 0 | AK27: =AK26+AJ27-AI27 -> 0 | AN27: =AN26+AM27-AL27 -> 0
B28: 46041 | D28: Payment | E28: STAL | G28: 917636 | H28: =sum(K28,N28,Q28,T28,W28,Z28,AC28,AF28,AI28,AL28) -> 5310 | I28: =sum(L28,O28,R28,U28,X28,AA28,AD28,AG28,AJ28,AM28) -> 0 | J28: =sum(M28,P28,S28,V28,Y28,AB28,AE28,AH28,AK28,AN28) -> 587035.2 | M28: =M27+L28-K28 -> -114437 | P28: =P27+O28-N29 -> 280955 | Q28: 5310 | S28: =S27+R28-Q28 -> 263710 | V28: =V27+U28-T28 -> 76207.2 | Y28: =Y27+X28-W28 -> 0 | AB28: =AB27+AA28-Z28 -> 80600 | AE28: =AE27+AD28-AC28 -> 0 | AH28: =AH27+AG28-AF28 -> 0 | AK28: =AK27+AJ28-AI28 -> 0 | AN28: =AN27+AM28-AL28 -> 0
B29: 46041 | D29: Payment | E29: STAL | G29: 917637 | H29: =sum(K29,N29,Q29,T29,W29,Z29,AC29,AF29,AI29,AL29) -> 18760 | I29: =sum(L29,O29,R29,U29,X29,AA29,AD29,AG29,AJ29,AM29) -> 0 | J29: =sum(M29,P29,S29,V29,Y29,AB29,AE29,AH29,AK29,AN29) -> 568275.2 | M29: =M28+L29-K29 -> -114437 | P29: =P28+O29-N30 -> 280955 | Q29: 18760 | S29: =S28+R29-Q29 -> 244950 | V29: =V28+U29-T29 -> 76207.2 | Y29: =Y28+X29-W29 -> 0 | AB29: =AB28+AA29-Z29 -> 80600 | AE29: =AE28+AD29-AC29 -> 0 | AH29: =AH28+AG29-AF29 -> 0 | AK29: =AK28+AJ29-AI29 -> 0 | AN29: =AN28+AM29-AL29 -> 0
B30: 46041 | D30: Payment | E30: STAL | G30: 917646 | H30: =sum(K30,N30,Q30,T30,W30,Z30,AC30,AF30,AI30,AL30) -> 10020 | I30: =sum(L30,O30,R30,U30,X30,AA30,AD30,AG30,AJ30,AM30) -> 0 | J30: =sum(M30,P30,S30,V30,Y30,AB30,AE30,AH30,AK30,AN30) -> 558255.2 | M30: =M29+L30-K30 -> -114437 | P30: =P29+O30-N30 -> 280955 | Q30: 10020 | S30: =S29+R30-Q30 -> 234930 | V30: =V29+U30-T30 -> 76207.2 | Y30: =Y29+X30-W30 -> 0 | AB30: =AB29+AA30-Z30 -> 80600 | AE30: =AE29+AD30-AC30 -> 0 | AH30: =AH29+AG30-AF30 -> 0 | AK30: =AK29+AJ30-AI30 -> 0 | AN30: =AN29+AM30-AL30 -> 0
B31: 46036 | D31: Payment | E31: Winterpine | G31: 942953 | H31: =sum(K31,N31,Q31,T31,W31,Z31,AC31,AF31,AI31,AL31) -> 32118 | I31: =sum(L31,O31,R31,U31,X31,AA31,AD31,AG31,AJ31,AM31) -> 0 | J31: =sum(M31,P31,S31,V31,Y31,AB31,AE31,AH31,AK31,AN31) -> 526137.2 | M31: =M30+L31-K31 -> -114437 | P31: =P30+O31-N31 -> 280955 | S31: =S30+R31-Q31 -> 234930 | T31: 32118 | V31: =V30+U31-T31 -> 44089.2 | Y31: =Y30+X31-W31 -> 0 | AB31: =AB30+AA31-Z31 -> 80600 | AE31: =AE30+AD31-AC31 -> 0 | AH31: =AH30+AG31-AF31 -> 0 | AK31: =AK30+AJ31-AI31 -> 0 | AN31: =AN30+AM31-AL31 -> 0
A32: 10 | B32: 46030 | C32: =B32+A32 -> 46040 | D32: Purchases | E32: Entalpia | H32: =sum(K32,N32,Q32,T32,W32,Z32,AC32,AF32,AI32,AL32) -> 0 | I32: =sum(L32,O32,R32,U32,X32,AA32,AD32,AG32,AJ32,AM32) -> 44145 | J32: =sum(M32,P32,S32,V32,Y32,AB32,AE32,AH32,AK32,AN32) -> 570282.2 | M32: =M31+L32-K32 -> -114437 | P32: =P31+O32-N32 -> 280955 | S32: =S31+R32-Q32 -> 234930 | V32: =V31+U32-T32 -> 44089.2 | Y32: =Y31+X32-W32 -> 0 | AB32: =AB31+AA32-Z32 -> 80600 | AD32: 44145 | AE32: =AE31+AD32-AC32 -> 44145 | AH32: =AH31+AG32-AF32 -> 0 | AK32: =AK31+AJ32-AI32 -> 0 | AN32: =AN31+AM32-AL32 -> 0
A33: 10 | B33: 46037 | C33: =B33+A33 -> 46047 | D33: Purchases | E33: Entalpia | H33: =sum(K33,N33,Q33,T33,W33,Z33,AC33,AF33,AI33,AL33) -> 0 | I33: =sum(L33,O33,R33,U33,X33,AA33,AD33,AG33,AJ33,AM33) -> 26928 | J33: =sum(M33,P33,S33,V33,Y33,AB33,AE33,AH33,AK33,AN33) -> 597210.2 | M33: =M32+L33-K33 -> -114437 | P33: =P32+O33-N33 -> 280955 | S33: =S32+R33-Q33 -> 234930 | V33: =V32+U33-T33 -> 44089.2 | Y33: =Y32+X33-W33 -> 0 | AB33: =AB32+AA33-Z33 -> 80600 | AD33: 26928 | AE33: =AE32+AD33-AC33 -> 71073 | AH33: =AH32+AG33-AF33 -> 0 | AK33: =AK32+AJ33-AI33 -> 0 | AN33: =AN32+AM33-AL33 -> 0
B34: 46044 | D34: Payment | E34: Entalpia | G34: 942970 | H34: =sum(K34,N34,Q34,T34,W34,Z34,AC34,AF34,AI34,AL34) -> 44145 | I34: =sum(L34,O34,R34,U34,X34,AA34,AD34,AG34,AJ34,AM34) -> 0 | J34: =sum(M34,P34,S34,V34,Y34,AB34,AE34,AH34,AK34,AN34) -> 553065.2 | M34: =M33+L34-K34 -> -114437 | P34: =P33+O34-N34 -> 280955 | S34: =S33+R34-Q34 -> 234930 | V34: =V33+U34-T34 -> 44089.2 | Y34: =Y33+X34-W34 -> 0 | AB34: =AB33+AA34-Z34 -> 80600 | AC34: 44145 | AE34: =AE33+AD34-AC34 -> 26928 | AH34: =AH33+AG34-AF34 -> 0 | AK34: =AK33+AJ34-AI34 -> 0 | AN34: =AN33+AM34-AL34 -> 0
B35: 46044 | D35: Payment | E35: Entalpia | G35: 942972 | H35: =sum(K35,N35,Q35,T35,W35,Z35,AC35,AF35,AI35,AL35) -> 26928 | I35: =sum(L35,O35,R35,U35,X35,AA35,AD35,AG35,AJ35,AM35) -> 0 | J35: =sum(M35,P35,S35,V35,Y35,AB35,AE35,AH35,AK35,AN35) -> 526137.2 | M35: =M34+L35-K35 -> -114437 | P35: =P34+O35-N35 -> 280955 | S35: =S34+R35-Q35 -> 234930 | V35: =V34+U35-T35 -> 44089.2 | Y35: =Y34+X35-W35 -> 0 | AB35: =AB34+AA35-Z35 -> 80600 | AC35: 26928 | AE35: =AE34+AD35-AC35 -> 0 | AH35: =AH34+AG35-AF35 -> 0 | AK35: =AK34+AJ35-AI35 -> 0 | AN35: =AN34+AM35-AL35 -> 0
B36: 46037 | D36: Payment | E36: Uniwestech | G36: 938035 | H36: =sum(K36,N36,Q36,T36,W36,Z36,AC36,AF36,AI36,AL36) -> 20000 | I36: =sum(L36,O36,R36,U36,X36,AA36,AD36,AG36,AJ36,AM36) -> 0 | J36: =sum(M36,P36,S36,V36,Y36,AB36,AE36,AH36,AK36,AN36) -> 506137.2 | M36: =M35+L36-K36 -> -114437 | P36: =P35+O36-N36 -> 280955 | S36: =S35+R36-Q36 -> 234930 | V36: =V35+U36-T36 -> 44089.2 | Y36: =Y35+X36-W36 -> 0 | Z36: 20000 | AB36: =AB35+AA36-Z36 -> 60600 | AE36: =AE35+AD36-AC36 -> 0 | AH36: =AH35+AG36-AF36 -> 0 | AK36: =AK35+AJ36-AI36 -> 0 | AN36: =AN35+AM36-AL36 -> 0
B37: 46038 | D37: Payment | E37: JYQL | G37: 938045 | H37: =sum(K37,N37,Q37,T37,W37,Z37,AC37,AF37,AI37,AL37) -> 27260 | I37: =sum(L37,O37,R37,U37,X37,AA37,AD37,AG37,AJ37,AM37) -> 0 | J37: =sum(M37,P37,S37,V37,Y37,AB37,AE37,AH37,AK37,AN37) -> 478877.2 | M37: =M36+L37-K37 -> -114437 | N37: 27260 | P37: =P36+O37-N37 -> 253695 | S37: =S36+R37-Q37 -> 234930 | V37: =V36+U37-T37 -> 44089.2 | Y37: =Y36+X37-W37 -> 0 | AB37: =AB36+AA37-Z37 -> 60600 | AE37: =AE36+AD37-AC37 -> 0 | AH37: =AH36+AG37-AF37 -> 0 | AK37: =AK36+AJ37-AI37 -> 0 | AN37: =AN36+AM37-AL37 -> 0
B38: 46038 | D38: Payment | E38: JYQL | G38: 942958 | H38: =sum(K38,N38,Q38,T38,W38,Z38,AC38,AF38,AI38,AL38) -> 12000 | I38: =sum(L38,O38,R38,U38,X38,AA38,AD38,AG38,AJ38,AM38) -> 0 | J38: =sum(M38,P38,S38,V38,Y38,AB38,AE38,AH38,AK38,AN38) -> 466877.2 | M38: =M37+L38-K38 -> -114437 | N38: 12000 | P38: =P37+O38-N38 -> 241695 | S38: =S37+R38-Q38 -> 234930 | V38: =V37+U38-T38 -> 44089.2 | Y38: =Y37+X38-W38 -> 0 | AB38: =AB37+AA38-Z38 -> 60600 | AE38: =AE37+AD38-AC38 -> 0 | AH38: =AH37+AG38-AF38 -> 0 | AK38: =AK37+AJ38-AI38 -> 0 | AN38: =AN37+AM38-AL38 -> 0
B39: 46038 | D39: Payment | E39: JYQL | G39: 942959 | H39: =sum(K39,N39,Q39,T39,W39,Z39,AC39,AF39,AI39,AL39) -> 10800 | I39: =sum(L39,O39,R39,U39,X39,AA39,AD39,AG39,AJ39,AM39) -> 0 | J39: =sum(M39,P39,S39,V39,Y39,AB39,AE39,AH39,AK39,AN39) -> 456077.2 | M39: =M38+L39-K39 -> -114437 | N39: 10800 | P39: =P38+O39-N39 -> 230895 | S39: =S38+R39-Q39 -> 234930 | V39: =V38+U39-T39 -> 44089.2 | Y39: =Y38+X39-W39 -> 0 | AB39: =AB38+AA39-Z39 -> 60600 | AE39: =AE38+AD39-AC39 -> 0 | AH39: =AH38+AG39-AF39 -> 0 | AK39: =AK38+AJ39-AI39 -> 0 | AN39: =AN38+AM39-AL39 -> 0
B40: 46044 | D40: Payment | E40: JYQL | G40: 942960 | H40: =sum(K40,N40,Q40,T40,W40,Z40,AC40,AF40,AI40,AL40) -> 8550 | I40: =sum(L40,O40,R40,U40,X40,AA40,AD40,AG40,AJ40,AM40) -> 0 | J40: =sum(M40,P40,S40,V40,Y40,AB40,AE40,AH40,AK40,AN40) -> 447527.2 | M40: =M39+L40-K40 -> -114437 | N40: 8550 | P40: =P39+O40-N40 -> 222345 | S40: =S39+R40-Q40 -> 234930 | V40: =V39+U40-T40 -> 44089.2 | Y40: =Y39+X40-W40 -> 0 | AB40: =AB39+AA40-Z40 -> 60600 | AE40: =AE39+AD40-AC40 -> 0 | AH40: =AH39+AG40-AF40 -> 0 | AK40: =AK39+AJ40-AI40 -> 0 | AN40: =AN39+AM40-AL40 -> 0
B41: 46045 | D41: Payment | E41: Winterpine | G41: 942955 | H41: =sum(K41,N41,Q41,T41,W41,Z41,AC41,AF41,AI41,AL41) -> 18858.4 | I41: =sum(L41,O41,R41,U41,X41,AA41,AD41,AG41,AJ41,AM41) -> 0 | J41: =sum(M41,P41,S41,V41,Y41,AB41,AE41,AH41,AK41,AN41) -> 428668.8 | M41: =M40+L41-K41 -> -114437 | P41: =P40+O41-N41 -> 222345 | S41: =S40+R41-Q41 -> 234930 | T41: 18858.4 | V41: =V40+U41-T41 -> 25230.8 | Y41: =Y40+X41-W41 -> 0 | AB41: =AB40+AA41-Z41 -> 60600 | AE41: =AE40+AD41-AC41 -> 0 | AH41: =AH40+AG41-AF41 -> 0 | AK41: =AK40+AJ41-AI41 -> 0 | AN41: =AN40+AM41-AL41 -> 0
...

Sheet 2026 issuances
A1: 46060
A2: Date of Issuance | B2: Check Date | C2: Deposit Date | D2: Check # | E2: Amount | F2: Payee | G2: Reference | H2: Remarks
A3: 45908 | B3: 46011 | C3: 46011 | D3: 938016 | E3: 20000 | F3: Centralworld Enterprises
C4: 46017 | E4: 18000 | F4: salaries
B5: 46017 | D5: 942969 | E5: 13800 | F5: 2BMA
A7: 45978 | B7: 46003 | C7: 45669 | D7: 938046 | E7: 11800 | F7: JYQL | G7: 034534 & 180294 JYQL (6350+5450) | H7: HOLD, deposit Jan 12, 2026
B8: 46035 | C8: 45670 | D8: 942956 | E8: 13800 | F8: 65045 JYQL | G8: 45945
B9: 46035 | C9: 45670 | D9: 942957 | E9: 16300 | F9: 91741 JYQL | G9: 45959
A10: 45845 | B10: 45924 | C10: 46010 | D10: 917636 | E10: 5310 | F10: Jambon / Cash | G10: DR#0108 | H10: HOLD, deposit Dec 19
A11: 45845 | B11: 45952 | C11: 46010 | D11: 917637 | E11: 18760 | F11: Jambon / Cash | G11: DR#0116 | H11: HOLD, deposit Dec 19
A12: 45845 | B12: 45961 | C12: 46010 | D12: 917646 | E12: 10020 | F12: Jambon / Cash | G12: DR#0123 | H12: HOLD, deposit Dec 19
B13: 46036 | C13: 45671 | D13: 942953 | E13: 32118 | F13: 204688 Winterpine (JS)
C14: 46037 | E14: 15600 | F14: Salaries
A15: 45940 | B15: 45966 | C15: 46037 | D15: 938035 | E15: 20000 | F15: UNIWESTECH | G15: for 8 cylender freon | H15: deposit Jan 15 2026
A16: 45978 | B16: 46000 | C16: 46038 | D16: 938045 | E16: 27260 | F16: JYQL | G16: 401581 JYQL | H16: HOLD, deposit Jan 16, 2026
B17: 46038 | C17: 46038 | D17: 942958 | E17: 12000 | F17: 72620 JYQL | G17: 45972
B18: 46038 | C18: 46038 | D18: 942959 | E18: 10800 | F18: 20202 JYQL | G18: 45973
A20: 45908 | B20: 46042 | C20: 46042 | D20: 938017 | E20: 20000 | F20: Centralworld Enterprises
B21: 46030 | C21: 46044 | D21: 942970 | E21: 44145 | F21: Entalpia | H21: 10 cyls 404, deposit date Jan 22
A22: 46036 | B22: 45672 | C22: 46044 | D22: 942972 | E22: 26928 | F22: Entalpia | G22: 4 cyls R314A | H22: Entalpia Europe (Philippines) Inc
B23: 46044 | C23: 46044 | D23: 942960 | E23: 8550 | F23: 50116 JYQL | G23: 45980
B24: 46041 | C24: 46045 | D24: 942955 | E24: 18858.4 | F24: 208141 Winterpine | G24: 45996
A25: 45905 | B25: 45965 | C25: 45314 | D25: 917650 | E25: 3650 | F25: Jambon / Cash | G25: DR#0126 additional, less overpayment DR#108 | H25: HOLD, deposit Jan 24, 2026
A26: 45905 | B26: 45970 | C26: 45314 | D26: 938001 | E26: 7470 | F26: Jambon / Cash | G26: DR#0130 | H26: HOLD, deposit Jan 24, 2026
A28: 45940 | B28: 45971 | C28: 46048 | D28: 938036 | E28: 25600 | F28: UNIWESTECH | G28: for 8 cylender freon | H28: deposit Jan 26, 2026
C29: 46052 | E29: 18000 | F29: Salaries
B31: 46045 | C31: 46058 | D31: 942965 | E31: 27450 | F31: 30652 JYQL | G31: 45989 | H31: moved to Feb 5 2026
B32: 46044 | C32: 46058 | D32: 942961 | E32: 18610 | F32: 65427 JYQL | G32: 45980 | H32: moved to Feb 5 2026
A33: 45981 | B33: 46008 | C33: 46047 | D33: 942952 | E33: 35000 | F33: UNIWESTECH | G33: replacement check # 917648 | H33: bounced, redep Feb 13, cleared Feb 6 2026
B34: 46059 | C34: 45694 | D34: 942962 | E34: 12850 | F34: 63426 JYQL | G34: 45994 | H34: paid thru bank transfer Feb 7 2026
A36: 46037 | B36: 46065 | C36: 46065 | D36: 942974 | E36: 23500 | F36: 65820 JYQL
A37: 46037 | B37: 46066 | C37: 46066 | D37: 942975 | E37: 10290 | F37: 94218 JYQL
A38: 46037 | B38: 46066 | C38: 46066 | D38: 942976 | E38: 9400 | F38: 70746JYQL
C39: 46066 | E39: 18000 | F39: Salaries
B41: 46069 | C41: 46069 | D41: 942999 | E41: 10290 | F41: 94218 JYQL | G41: DR# 94218
B43: 46075 | C43: 46075 | D43: 943000 | E43: 9400 | F43: 70746 JYQL | G43: DR# 70746
B44: 46078 | C44: 46078 | D44: 943001 | E44: 19240 | F44: 91780 JYQL | G44: DR# 91780 | H44: Good
A46: 45908 | B46: 46073 | C46: 46073 | D46: 938018 | E46: 20000 | F46: Centralworld Enterprises | H46: cleared Feb 27
A47: 46036 | B47: 46043 | C47: 46080 | D47: 942973 | E47: 16000 | F47: Uniwestech | G47: 2 tanks Gaz | H47: Uniwestech Philippines Inc
C48: 46081 | E48: 18000 | F48: Salaries
...

Sheet 2026 AR
A1: Aton Aire Trading Corporation
A2: 2026 Receivable | E2: =SUM(E3:E10) -> 0
A3: =TODAY() -> 46311 | D3: ISHABELLA | E3: =H11 -> 0
D4: JYQL | E4: =K11 -> 0
D5: JAMBON | E5: =N11 -> 0
D6: WINTERPINE | E6: =Q11 -> 0
D7: COOP | E7: =T11 -> 0
D8: UNIWESTECH | E8: =W11 -> 0
D9: HISYS | E9: =Z11 -> 0
D10: NBO
F11: =SUM(F15:F1048576) -> 0 | G11: =SUM(G15:G1048576) -> 0 | H11: =H14+G11-F11 -> 0 | I11: =SUM(I15:I1048576) -> 0 | J11: =SUM(J15:J1048576) -> 0 | K11: =K14+J11-I11 -> 0 | L11: =SUM(L15:L1048576) -> 0 | M11: =SUM(M15:M1048576) -> 0 | N11: =N14+M11-L11 -> 0 | O11: =SUM(O15:O1048576) -> 0 | P11: =SUM(P15:P1048576) -> 0 | Q11: =Q14+P11-O11 -> 0 | R11: =SUM(R15:R1048576) -> 0 | S11: =SUM(S15:S1048576) -> 0 | T11: =T14+S11-R11 -> 0 | U11: =SUM(U15:U1048576) -> 0 | V11: =SUM(V15:V1048576) -> 0 | W11: =W14+V11-U11 -> 0 | X11: =SUM(X15:X1048576) -> 0 | Y11: =SUM(Y15:Y1048576) -> 0 | Z11: =Z14+Y11-X11 -> 0 | AA11: =SUM(AA15:AA1048576) -> 0 | AB11: =SUM(AB15:AB1048576) -> 0 | AC11: =AC14+AB11-AA11 -> 0
F12: ISHABELLA | I12: JYQL AIRCON PARTS TRADING | L12: JAMBON/STAL | O12: WINTERPINE AIR CONDITIONING CORP | R12: COOP | U12: UNIWESTECH | X12: HISYS | AA12: LUFT
B13: Date | C13: Due Date | D13: Particulars | E13: References | F13: Debit | G13: Credit | H13: Balance | I13: Debit | J13: Credit | K13: Balance | L13: Debit | M13: Credit | N13: Balance | O13: Debit | P13: Credit | Q13: Balance | R13: Debit | S13: Credit | T13: Balance | U13: Debit | V13: Credit | W13: Balance | X13: Debit | Y13: Credit | Z13: Balance | AA13: Debit | AB13: Credit | AC13: Balance
Q14: 0 | T14: 0 | W14: 0 | Z14: 0 | AC14: 0
H15: =H14+G15-F15 -> 0 | K15: =K14+J15-I15 -> 0 | N15: =N14+M15-L15 -> 0 | Q15: =Q14+P15-O15 -> 0 | T15: =T14+S15-R15 -> 0 | W15: =W14+V15-U15 -> 0 | Z15: =Z14+Y15-X15 -> 0 | AC15: =AC14+AB15-AA15 -> 0
H16: =H15+G16-F16 -> 0 | K16: =K15+J16-I16 -> 0 | N16: =N15+M16-L16 -> 0 | Q16: =Q15+P16-O16 -> 0 | T16: =T15+S16-R16 -> 0 | W16: =W15+V16-U16 -> 0 | Z16: =Z15+Y16-X16 -> 0 | AC16: =AC15+AB16-AA16 -> 0
H17: =H16+G17-F17 -> 0 | K17: =K16+J17-I17 -> 0 | N17: =N16+M17-L17 -> 0 | Q17: =Q16+P17-O17 -> 0 | T17: =T16+S17-R17 -> 0 | W17: =W16+V17-U17 -> 0 | Z17: =Z16+Y17-X17 -> 0 | AC17: =AC16+AB17-AA17 -> 0
H18: =H17+G18-F18 -> 0 | K18: =K17+J18-I18 -> 0 | N18: =N17+M18-L18 -> 0 | Q18: =Q17+P18-O18 -> 0 | T18: =T17+S18-R18 -> 0 | W18: =W17+V18-U18 -> 0 | Z18: =Z17+Y18-X18 -> 0 | AC18: =AC17+AB18-AA18 -> 0
H19: =H18+G19-F19 -> 0 | K19: =K18+J19-I19 -> 0 | N19: =N18+M19-L19 -> 0 | Q19: =Q18+P19-O19 -> 0 | T19: =T18+S19-R19 -> 0 | W19: =W18+V19-U19 -> 0 | Z19: =Z18+Y19-X19 -> 0 | AC19: =AC18+AB19-AA19 -> 0
H20: =H18+G20-F20 -> 0 | K20: =K19+J20-I20 -> 0 | N20: =N19+M20-L20 -> 0 | Q20: =Q19+P20-O20 -> 0 | T20: =T19+S20-R20 -> 0 | W20: =W19+V20-U20 -> 0 | Z20: =Z19+Y20-X20 -> 0 | AC20: =AC19+AB20-AA20 -> 0
H21: =H19+G21-F21 -> 0 | K21: =K20+J21-I21 -> 0 | N21: =N20+M21-L21 -> 0 | Q21: =Q20+P21-O21 -> 0 | T21: =T20+S21-R21 -> 0 | W21: =W20+V21-U21 -> 0 | Z21: =Z20+Y21-X21 -> 0 | AC21: =AC20+AB21-AA21 -> 0
H22: =H20+G22-F22 -> 0 | K22: =K21+J22-I22 -> 0 | N22: =N21+M22-L22 -> 0 | Q22: =Q21+P22-O22 -> 0 | T22: =T21+S22-R22 -> 0 | W22: =W21+V22-U22 -> 0 | Z22: =Z21+Y22-X22 -> 0 | AC22: =AC21+AB22-AA22 -> 0
H23: =H21+G23-F23 -> 0 | K23: =K22+J23-I23 -> 0 | N23: =N22+M23-L23 -> 0 | Q23: =Q22+P23-O23 -> 0 | T23: =T22+S23-R23 -> 0 | W23: =W22+V23-U23 -> 0 | Z23: =Z22+Y23-X23 -> 0 | AC23: =AC22+AB23-AA23 -> 0
H24: =H22+G24-F24 -> 0 | K24: =K23+J24-I24 -> 0 | N24: =N23+M24-L24 -> 0 | Q24: =Q23+P24-O24 -> 0 | T24: =T23+S24-R24 -> 0 | W24: =W23+V24-U24 -> 0 | Z24: =Z23+Y24-X24 -> 0 | AC24: =AC23+AB24-AA24 -> 0
H25: =H24+G25-F25 -> 0 | K25: =K24+J25-I25 -> 0 | N25: =N24+M25-L25 -> 0 | Q25: =Q24+P25-O25 -> 0 | T25: =T24+S25-R25 -> 0 | W25: =W24+V25-U25 -> 0 | Z25: =Z24+Y25-X25 -> 0 | AC25: =AC24+AB25-AA25 -> 0
H26: =H25+G26-F26 -> 0 | K26: =K25+J26-I26 -> 0 | N26: =N25+M26-L26 -> 0 | Q26: =Q25+P26-O26 -> 0 | T26: =T25+S26-R26 -> 0 | W26: =W25+V26-U26 -> 0 | Z26: =Z25+Y26-X26 -> 0 | AC26: =AC25+AB26-AA26 -> 0
H27: =H26+G27-F27 -> 0 | K27: =K26+J27-I27 -> 0 | N27: =N26+M27-L27 -> 0 | Q27: =Q26+P27-O27 -> 0 | T27: =T26+S27-R27 -> 0 | W27: =W26+V27-U27 -> 0 | Z27: =Z26+Y27-X27 -> 0 | AC27: =AC26+AB27-AA27 -> 0
H28: =H27+G28-F28 -> 0 | K28: =K27+J28-I28 -> 0 | N28: =N27+M28-L28 -> 0 | Q28: =Q27+P28-O28 -> 0 | T28: =T27+S28-R28 -> 0 | W28: =W27+V28-U28 -> 0 | Z28: =Z27+Y28-X28 -> 0 | AC28: =AC27+AB28-AA28 -> 0
H29: =H28+G29-F29 -> 0 | K29: =K28+J29-I29 -> 0 | N29: =N28+M29-L29 -> 0 | Q29: =Q28+P29-O29 -> 0 | T29: =T28+S29-R29 -> 0 | W29: =W28+V29-U29 -> 0 | Z29: =Z28+Y29-X29 -> 0 | AC29: =AC28+AB29-AA29 -> 0
H30: =H29+G30-F30 -> 0 | K30: =K29+J30-I30 -> 0 | N30: =N29+M30-L30 -> 0 | Q30: =Q29+P30-O30 -> 0 | T30: =T29+S30-R30 -> 0 | W30: =W29+V30-U30 -> 0 | Z30: =Z29+Y30-X30 -> 0 | AC30: =AC29+AB30-AA30 -> 0
H31: =H30+G31-F31 -> 0 | K31: =K30+J31-I31 -> 0 | N31: =N30+M31-L31 -> 0 | Q31: =Q30+P31-O31 -> 0 | T31: =T30+S31-R31 -> 0 | W31: =W30+V31-U31 -> 0 | Z31: =Z30+Y31-X31 -> 0 | AC31: =AC30+AB31-AA31 -> 0
H32: =H31+G32-F32 -> 0 | K32: =K31+J32-I32 -> 0 | N32: =N31+M32-L32 -> 0 | Q32: =Q31+P32-O32 -> 0 | T32: =T31+S32-R32 -> 0 | W32: =W31+V32-U32 -> 0 | Z32: =Z31+Y32-X32 -> 0 | AC32: =AC31+AB32-AA32 -> 0
H33: =H32+G33-F33 -> 0 | K33: =K32+J33-I33 -> 0 | N33: =N32+M33-L33 -> 0 | Q33: =Q32+P33-O33 -> 0 | T33: =T32+S33-R33 -> 0 | W33: =W32+V33-U33 -> 0 | Z33: =Z32+Y33-X33 -> 0 | AC33: =AC32+AB33-AA33 -> 0
H34: =H33+G34-F34 -> 0 | K34: =K33+J34-I34 -> 0 | N34: =N33+M34-L34 -> 0 | Q34: =Q33+P34-O34 -> 0 | T34: =T33+S34-R34 -> 0 | W34: =W33+V34-U34 -> 0 | Z34: =Z33+Y34-X34 -> 0 | AC34: =AC33+AB34-AA34 -> 0
H35: =H34+G35-F35 -> 0 | K35: =K34+J35-I35 -> 0 | N35: =N34+M35-L35 -> 0 | Q35: =Q34+P35-O35 -> 0 | T35: =T34+S35-R35 -> 0 | W35: =W34+V35-U35 -> 0 | Z35: =Z34+Y35-X35 -> 0 | AC35: =AC34+AB35-AA35 -> 0
H36: =H35+G36-F36 -> 0 | K36: =K35+J36-I36 -> 0 | N36: =N35+M36-L36 -> 0 | Q36: =Q35+P36-O36 -> 0 | T36: =T35+S36-R36 -> 0 | W36: =W35+V36-U36 -> 0 | Z36: =Z35+Y36-X36 -> 0 | AC36: =AC35+AB36-AA36 -> 0
... H300: =H299+G300-F300 -> 0 | K300: =K299+J300-I300 -> 0 | N300: =N299+M300-L300 -> 0 | Q300: =Q299+P300-O300 -> 0 | T300: =T299+S300-R300 -> 0 | W300: =W299+V300-U300 -> 0 | Z300: =Z299+Y300-X300 -> 0 | AC300: =AC299+AB300-AA300 -> 0

Sheet Template
C2: 0 5 0 5 2 0 2 6
B5: JYQL AIRCON PARTS TRADING | C5: 22170
B6: TWENTY TWO THOUSAND ONE HUNDRED SEVENTY PESOS ONLY

Sheet 2026 Comm
A1: Aton Aire Trading Corporation | I1: Drench
A2: 2026 Commissions | C2: =C3-C4 -> 0 | D2: =D3-D4 -> 0 | E2: =E3-E4 -> 0 | F2: =F3-F4 -> 0 | G2: =G3-G4 -> 0 | H2: =H3-H4 -> 0 | I2: =I3-I4 -> 2000
C3: ='2026 DS'!K3 -> 7449.12 | D3: ='2026 IS'!D32 -> 8046.984 | E3: ='2026 IS'!E32 -> 3061.1 | F3: ='2026 IS'!F32 -> 6234.4 | G3: ='2026 IS'!G32 -> 6360.22 | H3: ='2026 IS'!H32 -> 11371.94 | I3: ='2026 IS'!I32 -> 11635.78
C4: =SUM(C6:C25) -> 7449.12 | D4: =SUM(D6:D25) -> 8046.984 | E4: =SUM(E6:E25) -> 3061.1 | F4: =SUM(F6:F25) -> 6234.4 | G4: =SUM(G6:G25) -> 6360.22 | H4: =SUM(H6:H25) -> 11371.94 | I4: =SUM(I6:I25) -> 9635.78 | J4: =SUM(J6:J25) -> 0 | ... O4: =SUM(O6:O25) -> 52159.544
A5: Names | B5: Gcash # | C5: January | D5: February | E5: March | F5: April | G5: May | H5: June | I5: July | J5: August | K5: September | L5: October | M5: November | N5: December | O5: Total
A6: Store | C6: =sumif('2026 DS'!$D$4:$D$42,$A$6,'2026 DS'!$K$4:$K$42) -> 0 | D6: =sumif('2026 DS'!$D$45:$D$102,$A6,'2026 DS'!$K$45:$K$102) -> 0 | E6: =sumif('2026 DS'!$D$104:$D$169,$A6,'2026 DS'!$K$104:$K$169) -> 0 | F6: =sumif('2026 DS'!$D$171:$D$238,$A6,'2026 DS'!$K$171:$K$238) -> 0 | G6: =sumif('2026 DS'!$D$240:$D$290,$A6,'2026 DS'!$K$240:$K$290) -> 44 | H6: =sumif('2026 DS'!$D$292:$D$357,A6,'2026 DS'!$K$292:$K$357) -> 0 | I6: =sumif('2026 DS'!$D$359:$D$435,A6,'2026 DS'!$K$359:$K$435) -> 0 | O6: =SUM(C6:N6) -> 44
A7: Rocky | C7: =sumif('2026 DS'!D$4:D$42,A7,'2026 DS'!K$4:K$42) -> 5397.52 | D7: =sumif('2026 DS'!$D$45:$D$102,$A7,'2026 DS'!$K$45:$K$102) -> 2392.984 | E7: =sumif('2026 DS'!$D$104:$D$169,$A7,'2026 DS'!$K$104:$K$169) -> 593 | F7: =sumif('2026 DS'!$D$171:$D$238,$A7,'2026 DS'!$K$171:$K$238) -> 3131.2 | G7: =sumif('2026 DS'!$D$240:$D$290,$A7,'2026 DS'!$K$240:$K$290) -> 3654.32 | H7: =sumif('2026 DS'!$D$292:$D$357,A7,'2026 DS'!$K$292:$K$357) -> 8659.44 | I7: =sumif('2026 DS'!$D$359:$D$435,A7,'2026 DS'!$K$359:$K$435) -> 3758.08 | O7: =SUM(C7:N7) -> 27586.544
A8: Arnold | C8: =sumif('2026 DS'!D$4:D$42,A8,'2026 DS'!K$4:K$42) -> 0 | D8: =sumif('2026 DS'!$D$45:$D$102,$A8,'2026 DS'!$K$45:$K$102) -> 3788 | E8: =sumif('2026 DS'!$D$104:$D$169,$A8,'2026 DS'!$K$104:$K$169) -> 0 | F8: =sumif('2026 DS'!$D$171:$D$238,$A8,'2026 DS'!$K$171:$K$238) -> 0 | G8: =sumif('2026 DS'!$D$240:$D$290,$A8,'2026 DS'!$K$240:$K$290) -> 0 | H8: =sumif('2026 DS'!$D$292:$D$357,A8,'2026 DS'!$K$292:$K$357) -> 0 | I8: =sumif('2026 DS'!$D$359:$D$435,A8,'2026 DS'!$K$359:$K$435) -> 0 | O8: =SUM(C8:N8) -> 3788
