Workbook
Name DashboardMonths: [1]Summary!$AE$131:$AE$142
Name DashboardMonths: [1]Summary!$AE$131:$AE$142
Name DashboardMonths: Summary!$AE$131:$AE$142
Name DashboardMonths: #REF!
Name InventoryCodes: [1]!LIST[CODE]
Name InventoryCodes: [1]!LIST[CODE]
Name InventoryCodes: #REF!
Name InventoryCodes: #REF!
Name Phase2_ApprovedAgents: '[1]Workbook Map'!$H$91:$H$103
Name Phase2_ApprovedAgents: '[1]Workbook Map'!$H$91:$H$103
Name Phase2_ApprovedAgents: 'Workbook Map'!$H$91:$H$103
Name Phase2_ClientCategories: '[1]Workbook Map'!$I$91:$I$93
Name Phase2_ClientCategories: '[1]Workbook Map'!$I$91:$I$93
Name Phase2_ClientCategories: 'Workbook Map'!$I$91:$I$93
Name Phase2_ProductCategories: '[1]Workbook Map'!$G$91:$G$94
Name Phase2_ProductCategories: '[1]Workbook Map'!$G$91:$G$94
Name Phase2_ProductCategories: 'Workbook Map'!$G$91:$G$94

Sheet Operating Guide
A1: OPERATING GUIDE — 2026
A2: Quick-start controls and approved entry locations for daily workbook operation
A4: Use only the entry locations listed below. Sales, cost, commission, reporting and dashboard outputs recalculate automatically. Inventory movement formulas are stable, but 364 products still have unsupported negative stock; do not create purchases or adjustments without source evidence or owner approval.
A7: WHERE TO WORK
A8: Workflow | B8: Sheet | C8: Entry point | D8: Required inputs | E8: Automatic results | F8: Primary check | G8: Stop condition | H8: Current state
A9: Enter sales | B9: Daily Sales | C9: sales[Month] to sales[Price] | D9: Month, date, agent, client, item, qty, price | E9: Sales, cost, capital, markup, commission | F9: Audit sales difference | G9: Any nonzero difference | H9: READY
A10: Add products | B10: Inventory | C10: LIST[ITEM] to LIST[UNIT COST] | D10: Description, code, category, unit cost | E10: Price and stock calculations | F10: Duplicate/missing codes | G10: Duplicate code or blank cost | H10: CONTROLLED
A11: Add clients | B11: Client List01 | C11: Table28 | D11: Client name, initials, agent | E11: Sales client lookups | F11: Unknown client / blank agent | G11: Any unresolved client | H11: READY
A12: Enter expenses | B12: Expenses | C12: Monthly expense columns | D12: Category, date, item, amount | E12: Summary expense and profit rows | F12: Summary annual expenses | G12: Unexpected annual change | H12: READY
A13: Enter purchases | B13: Purchase Log | C13: PurchaseLog | D13: ID, date, supplier, invoice, code, qty, cost | E13: Item/category/amount and stock purchased | F13: Validation Status = READY | G13: Duplicate ID or invalid code | H13: READY FOR ENTRY
A14: Review results | B14: INDEX / Audit | C14: KPI dashboard and controls | D14: No manual edits to formulas | E14: 2026 KPIs, charts and control statuses | F14: Audit PASS/FAIL controls | G14: Any FAIL without approval | H14: REVIEW
A16: LIVE CONTROL CHECK — REVIEW BEFORE AND AFTER ENTRY
A17: Control | B17: Current value | C17: Status | D17: Operator response | F17: HANDOVER LIMITATION
A18: Sales difference | B18: =Audit!D17 -> #REF! | C18: =Audit!E17 -> #REF! | D18: Must remain ₱0.00 | F18: Inventory exceptions are fully traced in Stock Exceptions, but remain open because Purchase Log contains no validated historical purchases. Continue normal sales and reporting operations only under the documented override; do not treat current running stock as fully reconciled.
A19: Cost difference | B19: =Audit!D18 -> #REF! | C19: =Audit!E18 -> #REF! | D19: Must remain ₱0.00
A20: Commission difference | B20: =Audit!D19 -> #REF! | C20: =Audit!E19 -> #REF! | D20: Must remain ₱0.00
A21: Movement exceptions | B21: =Audit!B20 -> #REF! | C21: =Audit!E20 -> #REF! | D21: Must remain zero
A22: Negative running stock | B22: =Audit!B24 -> #REF! | C22: =Audit!E24 -> #REF! | D22: Source support required
A23: Missing unit cost | B23: =Audit!B25 -> #REF! | C23: =Audit!E25 -> #REF! | D23: Complete product cost | F23: AFTER EVERY ENTRY BATCH
A24: Sales exceeding stock | B24: =Audit!B26 -> #REF! | C24: =Audit!E26 -> #REF! | D24: Source support required | F24: 1. Recalculate. 2. Confirm sales, cost and commission differences remain zero. 3. Review new validation or stock exceptions. 4. Save a new workbook version. 5. Stop immediately if a financial difference appears.

Sheet Summary
B1: DR SALES SUMMARY | C1: 3 | D1: 46298
B2: Progress | D2: 0.36944833 | F2: 0.46434267 | H2: 0.47125637 | J2: 0.573418 | L2: 0.64928867 | N2: 0.67444333 | P2: 0.570506 | R2: 0.369747 | T2: 0.433837 | V2: 0.023076667 | X2: 0 | Z2: 0 | AB2: Annual target/progress | AD2: BALANCE
B3: Mo. Sales | D3: 554172.5 | F3: 696514 | H3: 706884.55 | J3: 860127 | L3: 973933 | N3: 1011665 | P3: 855759 | R3: 554620.5 | T3: 650755.5 | V3: 34615 | X3: 0 | Z3: 0 | AB3: 6899046 | AC3: 0.38328034 | AD3: -11100954
B4: 46298 | C4: Day | D4: 46023 | F4: 46055 | H4: 46083 | J4: 46114 | L4: 46144 | N4: 46175 | P4: 46205 | R4: 46236 | T4: 46267 | V4: 46297 | X4: 46328 | Z4: 46358
D5: Daily | E5: Cummulative | F5: Daily | G5: Cummulative | H5: Daily | I5: Cummulative | J5: Daily | K5: Cummulative | L5: Daily | M5: Cummulative | N5: Daily | O5: Cummulative | P5: Daily | Q5: Cummulative | R5: Daily | S5: Cummulative | T5: Daily | U5: Cummulative | V5: Daily | W5: Cummulative | X5: Daily | Y5: Cummulative | Z5: Daily | AA5: Cummulative | AB5: 18000000
B6: Target | D6: 75000 | E6: 1500000 | F6: 75000 | G6: 1500000 | H6: 75000 | I6: 1500000 | J6: 75000 | K6: 1500000 | L6: 75000 | M6: 1500000 | N6: 75000 | O6: 1500000 | P6: 75000 | Q6: 1500000 | R6: 75000 | S6: 1500000 | T6: 75000 | U6: 1500000 | V6: 75000 | W6: 1500000 | X6: 75000 | Y6: 1500000 | Z6: 75000 | AA6: 1500000
B7: 45566 | C7: 1 | D7: 0 | E7: 0 | F7: 0 | G7: 0 | H7: 0 | I7: 0 | J7: 51239 | K7: 51239 | L7: 0 | M7: 0 | N7: 56723 | O7: 56723 | P7: 22046 | Q7: 22046 | R7: 23680 | S7: 23680 | T7: 18288 | U7: 18288 | V7: 34615 | W7: 34615 | X7: 0 | Y7: 0 | Z7: 0 | AA7: 0 | AE7: 1500000 | AF7: 75000 | AG7: 27605.129
B8: 45567 | C8: 2 | D8: 18062 | E8: 18062 | F8: 35345 | G8: 35345 | H8: 36375 | I8: 36375 | J8: 0 | K8: 51239 | L8: 31324 | M8: 31324 | N8: 44632 | O8: 101355 | P8: 30014 | Q8: 52060 | R8: 0 | S8: 23680 | T8: 31870 | U8: 50158 | V8: 0 | W8: 34615 | X8: 0 | Y8: 0 | Z8: 0 | AA8: 0 | AE8: 1500000 | AF8: 75000 | AG8: 27605.129
B9: 45568 | C9: 3 | D9: 23348 | E9: 41410 | F9: 27093 | G9: 62438 | H9: 31114 | I9: 67489 | J9: 0 | K9: 51239 | L9: 0 | M9: 31324 | N9: 39515 | O9: 140870 | P9: 38931 | Q9: 90991 | R9: 10568 | S9: 34248 | T9: 31088.5 | U9: 81246.5 | V9: 0 | W9: 34615 | X9: 0 | Y9: 0 | Z9: 0 | AA9: 0 | AC9: CATEGORY | AD9: ADD ON | AE9: 1500000 | AF9: 75000 | AG9: 27605.129
B10: 45569 | C10: 4 | D10: 0 | E10: 41410 | F10: 31455 | G10: 93893 | H10: 57986 | I10: 125475 | J10: 24657 | K10: 75896 | L10: 38209 | M10: 69533 | N10: 24707 | O10: 165577 | P10: 46195 | Q10: 137186 | R10: 30710 | S10: 64958 | T10: 42401 | U10: 123647.5 | V10: 0 | W10: 34615 | X10: 0 | Y10: 0 | Z10: 0 | AA10: 0 | AC10: GENERAL | AD10: 0.05 | AE10: 1500000 | AF10: 75000 | AG10: 27605.129
B11: 45570 | C11: 5 | D11: 27160 | E11: 68570 | F11: 5010 | G11: 98903 | H11: 27506 | I11: 152981 | J11: 0 | K11: 75896 | L11: 21276 | M11: 90809 | N11: 27135 | O11: 192712 | P11: 0 | Q11: 137186 | R11: 10707.5 | S11: 75665.5 | T11: 58371 | U11: 182018.5 | V11: 0 | W11: 34615 | X11: 0 | Y11: 0 | Z11: 0 | AA11: 0 | AC11: TOOLS | AD11: 0.05 | AE11: 1500000 | AF11: 75000 | AG11: 27605.129
B12: 45571 | C12: 6 | D12: 27471 | E12: 96041 | F12: 6300 | G12: 105203 | H12: 37701.55 | I12: 190682.55 | J12: 30785 | K12: 106681 | L12: 40219 | M12: 131028 | N12: 31718 | O12: 224430 | P12: 30413 | Q12: 167599 | R12: 45960 | S12: 121625.5 | T12: 0 | U12: 182018.5 | V12: 0 | W12: 34615 | X12: 0 | Y12: 0 | Z12: 0 | AA12: 0 | AC12: INSTALLATION MATERIALS | AD12: 0.03 | AE12: 1500000 | AF12: 75000 | AG12: 27605.129
B13: 45572 | C13: 7 | D13: 46280 | E13: 142321 | F13: 29488 | G13: 134691 | H13: 48158 | I13: 238840.55 | J13: 69658 | K13: 176339 | L13: 16814 | M13: 147842 | N13: 0 | O13: 224430 | P13: 42315 | Q13: 209914 | R13: 28094 | S13: 149719.5 | T13: 14198 | U13: 196216.5 | V13: 0 | W13: 34615 | X13: 0 | Y13: 0 | Z13: 0 | AA13: 0 | AC13: CAR AIRCON | AD13: 0.05 | AE13: 1500000 | AF13: 75000 | AG13: 27605.129
B14: 45573 | C14: 8 | D14: 8450 | E14: 150771 | F14: 0 | G14: 134691 | H14: 0 | I14: 238840.55 | J14: 23263 | K14: 199602 | L14: 24832 | M14: 172674 | N14: 19084 | O14: 243514 | P14: 32335 | Q14: 242249 | R14: 30986 | S14: 180705.5 | T14: 15763 | U14: 211979.5 | V14: 0 | W14: 34615 | X14: 0 | Y14: 0 | Z14: 0 | AA14: 0 | AE14: 1500000 | AF14: 75000 | AG14: 27605.129
B15: 45574 | C15: 9 | D15: 18931 | E15: 169702 | F15: 17255 | G15: 151946 | H15: 37221 | I15: 276061.55 | J15: 41275 | K15: 240877 | L15: 64342 | M15: 237016 | N15: 45256 | O15: 288770 | P15: 37365 | Q15: 279614 | R15: 0 | S15: 180705.5 | T15: 14255 | U15: 226234.5 | V15: 0 | W15: 34615 | X15: 0 | Y15: 0 | Z15: 0 | AA15: 0 | AE15: 1500000 | AF15: 75000 | AG15: 27605.129
B16: 45575 | C16: 10 | D16: 36175 | E16: 205877 | F16: 39549 | G16: 191495 | H16: 7630 | I16: 283691.55 | J16: 48177 | K16: 289054 | L16: 0 | M16: 237016 | N16: 28085 | O16: 316855 | P16: 38598 | Q16: 318212 | R16: 4600 | S16: 185305.5 | T16: 16450 | U16: 242684.5 | V16: 0 | W16: 34615 | X16: 0 | Y16: 0 | Z16: 0 | AA16: 0 | AE16: 1500000 | AF16: 75000 | AG16: 27605.129
B17: 45576 | C17: 11 | D17: 0 | E17: 205877 | F17: 44230 | G17: 235725 | H17: 17065 | I17: 300756.55 | J17: 28101 | K17: 317155 | L17: 56942 | M17: 293958 | N17: 24278 | O17: 341133 | P17: 36566 | Q17: 354778 | R17: 15898 | S17: 201203.5 | T17: 15380 | U17: 258064.5 | V17: 0 | W17: 34615 | X17: 0 | Y17: 0 | Z17: 0 | AA17: 0 | AE17: 1500000 | AF17: 75000 | AG17: 27605.129
B18: 45577 | C18: 12 | D18: 20225 | E18: 226102 | F18: 14930 | G18: 250655 | H18: 28850 | I18: 329606.55 | J18: 0 | K18: 317155 | L18: 32610 | M18: 326568 | N18: 37523 | O18: 378656 | P18: 0 | Q18: 354778 | R18: 16665 | S18: 217868.5 | T18: 29862 | U18: 287926.5 | V18: 0 | W18: 34615 | X18: 0 | Y18: 0 | Z18: 0 | AA18: 0 | AE18: 1500000 | AF18: 75000 | AG18: 27605.129
B19: 45578 | C19: 13 | D19: 11540 | E19: 237642 | F19: 31030 | G19: 281685 | H19: 40688 | I19: 370294.55 | J19: 15400 | K19: 332555 | L19: 0 | M19: 326568 | N19: 57994 | O19: 436650 | P19: 28229 | Q19: 383007 | R19: 33572 | S19: 251440.5 | T19: 0 | U19: 287926.5 | V19: 0 | W19: 34615 | X19: 0 | Y19: 0 | Z19: 0 | AA19: 0 | AE19: 1500000 | AF19: 75000 | AG19: 27605.129
B20: 45579 | C20: 14 | D20: 28621 | E20: 266263 | F20: 20320 | G20: 302005 | H20: 23767 | I20: 394061.55 | J20: 27855 | K20: 360410 | L20: 23260 | M20: 349828 | N20: 0 | O20: 436650 | P20: 12981 | Q20: 395988 | R20: 3510 | S20: 254950.5 | T20: 14021 | U20: 301947.5 | V20: 0 | W20: 34615 | X20: 0 | Y20: 0 | Z20: 0 | AA20: 0 | AE20: 1500000 | AF20: 75000 | AG20: 27605.129
B21: 45580 | C21: 15 | D21: 13336 | E21: 279599 | F21: 0 | G21: 302005 | H21: 0 | I21: 394061.55 | J21: 121659 | K21: 482069 | L21: 56305 | M21: 406133 | N21: 35586 | O21: 472236 | P21: 36189 | Q21: 432177 | R21: 26827 | S21: 281777.5 | T21: 15895 | U21: 317842.5 | V21: 0 | W21: 34615 | X21: 0 | Y21: 0 | Z21: 0 | AA21: 0 | AE21: 1500000 | AF21: 75000 | AG21: 27605.129
B22: 45581 | C22: 16 | D22: 18185 | E22: 297784 | F22: 27675 | G22: 329680 | H22: 21100 | I22: 415161.55 | J22: 13285 | K22: 495354 | L22: 28127 | M22: 434260 | N22: 33260 | O22: 505496 | P22: 23965 | Q22: 456142 | R22: 200 | S22: 281977.5 | T22: 30340 | U22: 348182.5 | V22: 0 | W22: 34615 | X22: 0 | Y22: 0 | Z22: 0 | AA22: 0 | AE22: 1500000 | AF22: 75000 | AG22: 27605.129
B23: 45582 | C23: 17 | D23: 18420 | E23: 316204 | F23: 21570 | G23: 351250 | H23: 17962 | I23: 433123.55 | J23: 20528 | K23: 515882 | L23: 0 | M23: 434260 | N23: 54565 | O23: 560061 | P23: 41128 | Q23: 497270 | R23: 9290 | S23: 291267.5 | T23: 11545 | U23: 359727.5 | V23: 0 | W23: 34615 | X23: 0 | Y23: 0 | Z23: 0 | AA23: 0 | AE23: 1500000 | AF23: 75000 | AG23: 27605.129
B24: 45583 | C24: 18 | D24: 0 | E24: 316204 | F24: 20232 | G24: 371482 | H24: 21290 | I24: 454413.55 | J24: 21273 | K24: 537155 | L24: 44081 | M24: 478341 | N24: 54396 | O24: 614457 | P24: 21621 | Q24: 518891 | R24: 19816 | S24: 311083.5 | T24: 4777 | U24: 364504.5 | V24: 0 | W24: 34615 | X24: 0 | Y24: 0 | Z24: 0 | AA24: 0 | AE24: 1500000 | AF24: 75000 | AG24: 27605.129
B25: 45584 | C25: 19 | D25: 9625 | E25: 325829 | F25: 27060 | G25: 398542 | H25: 29104 | I25: 483517.55 | J25: 350 | K25: 537505 | L25: 24697 | M25: 503038 | N25: 31954 | O25: 646411 | P25: 500 | Q25: 519391 | R25: 7970 | S25: 319053.5 | T25: 24774 | U25: 389278.5 | V25: 0 | W25: 34615 | X25: 0 | Y25: 0 | Z25: 0 | AA25: 0 | AE25: 1500000 | AF25: 75000 | AG25: 27605.129
... B37: 45596 | C37: 31 | D37: 17220 | E37: 554172.5 | F37: 0 | G37: 696514 | H37: 13120 | I37: 706884.55 | J37: 0 | K37: 860127 | L37: 0 | M37: 973933 | N37: 0 | O37: 1011665 | P37: 20960 | Q37: 855759 | R37: 18005 | S37: 554620.5 | T37: 0 | U37: 650755.5 | V37: 0 | W37: 34615 | X37: 0 | Y37: 0 | Z37: 0 | AA37: 0 | AE37: 1500000 | AF37: 75000 | AG37: 27605.129
B38: 0.03
B39: MONTH | C39: ANNUAL | D39: 1 | F39: 2 | H39: 3 | J39: 4 | L39: 5 | N39: 6 | P39: 7 | R39: 8 | T39: 9 | V39: 10 | X39: 46328 | Z39: 46358
B40: [1]T-SALES | C40: 6899046 | D40: 554172.5 | F40: 696514 | H40: 706884.55 | J40: 860127 | L40: 973933 | N40: 1011665 | P40: 855759 | R40: 554620.5 | T40: 650755.5 | V40: 34615 | X40: 0 | Z40: 0
B41: [2]T-CAPITAL | C41: 4343170 | D41: 372521.97 | F41: 519477.67 | H41: 490787.68 | J41: 477023.89 | L41: 423396.4 | N41: 564360.89 | P41: 619192.51 | R41: 398804.1 | T41: 451575.4 | V41: 26029.49 | X41: 0 | Z41: 0
B42: [3]T-COST | C42: 4151287.6 | D42: 355356.11 | F42: 496195.63 | H42: 468391.97 | J42: 455238.36 | L42: 405464.07 | N42: 540599.88 | P42: 591909.29 | R42: 381300.7 | T42: 431631.04 | V42: 25200.6 | X42: 0 | Z42: 0
B43: [4]T-AGENT | C43: 266326.26 | D43: 21344.085 | F43: 19634.272 | H43: 18376.849 | J43: 39320.199 | L43: 54781.184 | N43: 47228.378 | P43: 26748.582 | R43: 18690.388 | T43: 20009.425 | V43: 192.9 | X43: 0 | Z43: 0
B44: [5-1]T-MANAGER (1.0%) | C44: 68990.46 | D44: 5541.725 | F44: 6965.14 | H44: 7068.8455 | J44: 8601.27 | L44: 9739.33 | N44: 10116.65 | P44: 8557.59 | R44: 5546.205 | T44: 6507.555 | V44: 346.15 | X44: 0 | Z44: 0
B45: [5-2]STORE MANAGER (0.5%) | C45: 34495.23 | D45: 2770.8625 | F45: 3482.57 | H45: 3534.4228 | J45: 4300.635 | L45: 4869.665 | N45: 5058.325 | P45: 4278.795 | R45: 2773.1025 | T45: 3253.7775 | V45: 173.075 | X45: 0 | Z45: 0
B46: [5-3]ISHABELLA SALES (1%) | C46: 8831.47 | D46: 1109.45 | F46: 863.98 | H46: 895.87 | J46: 1100.16 | L46: 1277.01 | N46: 774.44 | P46: 1127.2 | R46: 758.43 | T46: 914.93 | V46: 10 | X46: 0 | Z46: 0
B47: [5-4]OWNER'S ALLOWANCE | C47: 85405.051 | D47: 8312.5875 | F47: 10447.71 | H47: 10603.268 | J47: 12901.905 | L47: 14608.995 | N47: 15174.975 | P47: 12836.385 | R47: 0 | T47: 0 | V47: 519.225 | X47: 0 | Z47: 0
B48: [7-1]T-EXPENSES | C48: 1381162.7 | D48: 141564 | F48: 168083.6 | H48: 149703.3 | J48: 160227.3 | L48: 150531.3 | N48: 157646.3 | P48: 152727.33 | R48: 142974.3 | T48: 157705.3 | V48: 0 | X48: 0 | Z48: 0
B49: [8] GROSS INCOME [1]-[2]-[4] | C49: 2289549.8 | D49: 160306.44 | F49: 157402.06 | H49: 197720.02 | J49: 343782.91 | L49: 495755.42 | N49: 400075.73 | P49: 209817.9 | R49: 137126.01 | T49: 179170.68 | V49: 8392.61 | X49: 0 | Z49: 0 | AC49: CAPITAL = | AD49: COST x 105%
B50: [9]NET INCOME | C50: 804901.37 | D50: 10429.856 | F50: -21129.249 | H50: 37413.455 | J50: 170653.7 | L50: 330615.12 | N50: 227254.46 | P50: 44254.189 | R50: -14167.595 | T50: 11704.045 | V50: 7873.385 | X50: 0 | Z50: 0 | AC50: - MANAGER INCT. = | AD50: 1% x 2
B51: [10] ADD ON CAPITAL [2]-[3] | C51: 106477.3 | D51: 8853.2738 | F51: 12834.327 | H51: 11792.439 | J51: 8883.6286 | L51: 3323.3341 | N51: 8586.0334 | P51: 14446.839 | R51: 17503.4 | T51: 19944.358 | V51: 309.665 | X51: 0 | Z51: 0
...

Sheet Sales Record
A1: DR SALES RECORD — 2026
A2: One consolidated record per delivery receipt, grouped by transaction date and client
A4: TOTAL DR | B4: 2153 | C4: TOTAL SALES | D4: 6899046 | E4: TOTAL COST | F4: 4151287.7 | G4: GROSS PROFIT | H4: 2747758.4 | I4: AGENT COMM. | J4: 266326.26 | K4: AVG. DR SALE | L4: 3204.3874
A6: DR Number | B6: Date | C6: Agent | D6: Client | E6: Line Items | F6: Total Qty | G6: Delivery | H6: Sales | I6: Total Cost | J6: Capital | K6: Markup | L6: Agent Commission | M6: Gross Profit | N6: Gross Margin
A7: 0102-01 | B7: 46024 | C7: Store | D7: DODOY | E7: 1 | F7: 1 | G7: 0 | H7: 1800 | I7: 1150 | J7: 1207.5 | K7: 592.5 | L7: 0 | M7: 650 | N7: 0.36111111
A8: 0102-02 | B8: 46024 | C8: Store | D8: EDWARD NAILGAS | E8: 5 | F8: 55 | G8: 0 | H8: 1667 | I8: 865.6 | J8: 896.018 | K8: 770.982 | L8: 0 | M8: 801.4 | N8: 0.48074385
A9: 0102-03 | B9: 46024 | C9: Ptr. Rod | D9: GIE | E9: 1 | F9: 1 | G9: 0 | H9: 1625 | I9: 800 | J9: 840 | K9: 785 | L9: 235.5 | M9: 825 | N9: 0.50769231
A10: 0102-04 | B10: 46024 | C10: Store | D10: JAY STA ROSA | E10: 1 | F10: 1 | G10: 0 | H10: 7800 | I10: 6732 | J10: 7068.6 | K10: 731.4 | L10: 0 | M10: 1068 | N10: 0.13692308
A11: 0102-05 | B11: 46024 | C11: Store | D11: JHUN M / MC MC | E11: 1 | F11: 1 | G11: 0 | H11: 300 | I11: 100 | J11: 105 | K11: 195 | L11: 0 | M11: 200 | N11: 0.66666667
A12: 0102-06 | B12: 46024 | C12: Store | D12: RHAYMAR CARBUNGCO | E12: 1 | F12: 1 | G12: 0 | H12: 2100 | I12: 1100 | J12: 1155 | K12: 945 | L12: 0 | M12: 1000 | N12: 0.47619048
A13: 0102-07 | B13: 46024 | C13: Bro. Vin | D13: SPTC | E13: 1 | F13: 2 | G13: 0 | H13: 900 | I13: 360 | J13: 378 | K13: 522 | L13: 156.6 | M13: 540 | N13: 0.6
A14: 0102-08 | B14: 46024 | C14: Store | D14: WALK IN | E14: 2 | F14: 2 | G14: 0 | H14: 1870 | I14: 990 | J14: 1039.5 | K14: 830.5 | L14: 0 | M14: 880 | N14: 0.47058824
A15: 0103-01 | B15: 46025 | D15: AirCooled / Yohanan Saul | E15: 2 | F15: 2 | G15: 0 | H15: 175 | I15: 105 | J15: 108.75 | K15: 66.25 | L15: 19.875 | M15: 70 | N15: 0.4
A16: 0103-02 | B16: 46025 | C16: Bro. Rhoge | D16: BERNABE DE VERA CONSTRUCTION | E16: 1 | F16: 30 | G16: 0 | H16: 1338 | I16: 1050 | J16: 1102.5 | K16: 235.5 | L16: 70.65 | M16: 288 | N16: 0.21524664
A17: 0103-03 | B17: 46025 | D17: BIB / BOB | E17: 2 | F17: 3 | G17: 0 | H17: 860 | I17: 452 | J17: 474.6 | K17: 385.4 | L17: 115.62 | M17: 408 | N17: 0.4744186
A18: 0103-04 | B18: 46025 | C18: Ptr. Rod | D18: EDLAN | E18: 2 | F18: 2 | G18: 0 | H18: 3975 | I18: 2550 | J18: 2677.5 | K18: 1297.5 | L18: 389.25 | M18: 1425 | N18: 0.35849057
A19: 0103-05 | B19: 46025 | C19: Store | D19: EDWARD NAILGAS | E19: 4 | F19: 5.8 | G19: 0 | H19: 3410 | I19: 1488.6 | J19: 1533.258 | K19: 1876.742 | L19: 0 | M19: 1921.4 | N19: 0.56346041
A20: 0103-06 | B20: 46025 | C20: Ptr. Rod | D20: GIE | E20: 16 | F20: 22 | G20: 0 | H20: 8205 | I20: 5005 | J20: 5248.65 | K20: 2956.35 | L20: 886.905 | M20: 3200 | N20: 0.39000609
A21: 0103-07 | B21: 46025 | C21: Store | D21: JOVI TECH | E21: 5 | F21: 11 | G21: 0 | H21: 855 | I21: 515 | J21: 534.23 | K21: 320.77 | L21: 0 | M21: 340 | N21: 0.39766082
A22: 0103-08 | B22: 46025 | C22: Store | D22: LAGUNA AIR BINAN | E22: 1 | F22: 1 | G22: 0 | H22: 2100 | I22: 1075 | J22: 1128.75 | K22: 971.25 | L22: 0 | M22: 1025 | N22: 0.48809524
A23: 0103-09 | B23: 46025 | C23: Bro. Mel | D23: ROSIPITO | E23: 2 | F23: 12 | G23: 0 | H23: 1050 | I23: 551 | J23: 578.55 | K23: 471.45 | L23: 141.435 | M23: 499 | N23: 0.4752381
A24: 0103-10 | B24: 46025 | C24: Store | D24: WALK IN | E24: 3 | F24: 3 | G24: 0 | H24: 1380 | I24: 410 | J24: 430.5 | K24: 949.5 | L24: 0 | M24: 970 | N24: 0.70289855
A25: 0105-01 | B25: 46027 | C25: Store | D25: CEMTRANS | E25: 1 | F25: 2 | G25: 0 | H25: 900 | I25: 360 | J25: 378 | K25: 522 | L25: 0 | M25: 540 | N25: 0.6
A26: 0105-02 | B26: 46027 | C26: Ptr. Rod | D26: CRISJAP | E26: 2 | F26: 2 | G26: 0 | H26: 2475 | I26: 1210 | J26: 1270.5 | K26: 1204.5 | L26: 361.35 | M26: 1265 | N26: 0.51111111
A27: 0105-03 | B27: 46027 | C27: Store | D27: DODOY | E27: 7 | F27: 67 | G27: 0 | H27: 4940 | I27: 2482 | J27: 2606.1 | K27: 2333.9 | L27: 0 | M27: 2458 | N27: 0.49757085
A28: 0105-04 | B28: 46027 | C28: Sis. Jackie | D28: DXB KING JEFF | E28: 1 | F28: 1 | G28: 0 | H28: 2300 | I28: 1500 | J28: 1575 | K28: 725 | L28: 217.5 | M28: 800 | N28: 0.34782609
A29: 0105-05 | B29: 46027 | C29: Ptr. Rod | D29: GIE | E29: 1 | F29: 1 | G29: 0 | H29: 1700 | I29: 1200 | J29: 1260 | K29: 440 | L29: 132 | M29: 500 | N29: 0.29411765
... A33: 0105-09 | B33: 46027 | C33: Store | D33: WALK IN | E33: 1 | F33: 1 | G33: 0 | H33: 585 | I33: 480 | J33: 504 | K33: 81 | L33: 0 | M33: 105 | N33: 0.17948718
A34: 0106-01 | B34: 46028 | D34: BIB / BOB | E34: 2 | F34: 2 | G34: 0 | H34: 3400 | I34: 2250 | J34: 2362.5 | K34: 1037.5 | L34: 311.25 | M34: 1150 | N34: 0.33823529
A35: 0106-02 | B35: 46028 | C35: Store | D35: CJ PANTHER/SEVILLA | E35: 2 | F35: 4 | G35: 0 | H35: 2055 | I35: 1565 | J35: 1643.25 | K35: 411.75 | L35: 0 | M35: 490 | N35: 0.23844282
A36: 0106-03 | B36: 46028 | C36: Store | D36: DEMY | E36: 1 | F36: 1 | G36: 0 | H36: 2000 | I36: 1100 | J36: 1155 | K36: 845 | L36: 0 | M36: 900 | N36: 0.45
A37: 0106-04 | B37: 46028 | C37: Sis. Jackie | D37: DXB KING JEFF | E37: 1 | F37: 1 | G37: 0 | H37: 2000 | I37: 1300 | J37: 1365 | K37: 635 | L37: 190.5 | M37: 700 | N37: 0.35
A38: 0106-05 | B38: 46028 | C38: Bro. Roxie | D38: ENTENG CAR AIRCON | E38: 2 | F38: 2 | G38: 0 | H38: 3800 | I38: 2200 | J38: 2310 | K38: 1490 | L38: 447 | M38: 1600 | N38: 0.42105263
A39: 0106-06 | B39: 46028 | C39: Store | D39: LAGUNA AIR PACITA | E39: 2 | F39: 2 | G39: 0 | H39: 9700 | I39: 7632 | J39: 8013.6 | K39: 1686.4 | L39: 0 | M39: 2068 | N39: 0.21319588
A40: 0106-07 | B40: 46028 | C40: Store | D40: WALK IN | E40: 14 | F40: 48.8 | G40: 0 | H40: 4516 | I40: 2825.8 | J40: 2941.214 | K40: 1574.786 | L40: 0 | M40: 1690.2 | N40: 0.37426926
A41: 0107-01 | B41: 46029 | C41: Ptr. Rod | D41: CRISJAP | E41: 2 | F41: 2 | G41: 0 | H41: 9900 | I41: 8132 | J41: 8538.6 | K41: 1361.4 | L41: 408.42 | M41: 1768 | N41: 0.17858586
A42: 0107-02 | B42: 46029 | C42: Store | D42: DODOY | E42: 2 | F42: 3 | G42: 0 | H42: 17700 | I42: 14964 | J42: 15712.2 | K42: 1987.8 | L42: 0 | M42: 2736 | N42: 0.15457627
A43: 0107-03 | B43: 46029 | D43: HELBERT ARIETE / MHM AUTOSHOP | E43: 2 | F43: 2 | G43: 0 | H43: 2230 | I43: 1230 | J43: 1291.5 | K43: 938.5 | L43: 281.55 | M43: 1000 | N43: 0.44843049
A44: 0107-04 | B44: 46029 | C44: Store | D44: JHUN M / MC MC | E44: 5 | F44: 5 | G44: 0 | H44: 5390 | I44: 3200 | J44: 3360 | K44: 2030 | L44: 0 | M44: 2190 | N44: 0.40630798
A45: 0107-05 | B45: 46029 | C45: Store | D45: LAGUNA AIR PACITA | E45: 1 | F45: 1 | G45: 0 | H45: 2000 | I45: 1400 | J45: 1470 | K45: 530 | L45: 0 | M45: 600 | N45: 0.3
...

Sheet Expense List
A1: EXPENSE LIST — 2026
A2: Live summary of expense items and monthly amounts from the Expenses sheet
A4: Category | B4: Expense Item | C4: January | D4: February | E4: March | F4: April | G4: May | H4: June | I4: July | J4: August | K4: September | L4: October | M4: November | N4: December | O4: YTD Total
A5: Fixed | B5: Globe | C5: 599 | D5: 599 | E5: 605 | F5: 605 | G5: 605 | H5: 605 | I5: 605 | J5: 605 | K5: 605 | L5: 0 | M5: 0 | N5: 0 | O5: 5433
A6: Fixed | B6: PLDT | C6: 1907 | D6: 1907 | E6: 1907 | F6: 1907 | G6: 1907 | H6: 1907 | I6: 1907 | J6: 1907 | K6: 1907 | L6: 0 | M6: 0 | N6: 0 | O6: 17163
A7: Fixed | B7: Rental | C7: 9000 | D7: 9000 | E7: 9000 | F7: 9000 | G7: 9000 | H7: 9000 | I7: 9000 | J7: 9000 | K7: 9000 | L7: 0 | M7: 0 | N7: 0 | O7: 81000
A8: Fixed | B8: Bookkeeping | C8: 5000 | D8: 5000 | E8: 5000 | F8: 5000 | G8: 5000 | H8: 5000 | I8: 5000 | J8: 5000 | K8: 5000 | L8: 0 | M8: 0 | N8: 0 | O8: 45000
A9: Fixed | B9: Avanza | C9: 17365 | D9: 17365 | E9: 17365 | F9: 17365 | G9: 17365 | H9: 17365 | I9: 17365 | J9: 17365 | K9: 17365 | L9: 0 | M9: 0 | N9: 0 | O9: 156285
A10: Fixed | B10: Insurance | C10: 2000 | D10: 2000 | E10: 2000 | F10: 2000 | G10: 2000 | H10: 2000 | I10: 2000 | J10: 2000 | K10: 2000 | L10: 0 | M10: 0 | N10: 0 | O10: 18000
A11: Fixed | B11: Meralco | C11: 6306 | D11: 7104 | E11: 8413 | F11: 9632 | G11: 11203 | H11: 11637 | I11: 8815.03 | J11: 5766 | K11: 8135 | L11: 0 | M11: 0 | N11: 0 | O11: 77011.03
A12: Fixed | B12: Water | C12: 505 | D12: 502 | E12: 502 | F12: 497 | G12: 502 | H12: 497 | I12: 503 | J12: 503 | K12: 551 | L12: 0 | M12: 0 | N12: 0 | O12: 4562
A13: 0 | B13: Laptop | C13: 1500 | D13: 1500 | E13: 1500 | F13: 1500 | G13: 1500 | H13: 1500 | I13: 1500 | J13: 1500 | K13: 1500 | L13: 0 | M13: , | N13: 0 | O13: 13500
A14: 0 | B14: BIR | C14: 470 | D14: 470 | E14: 470 | F14: 470 | G14: 470 | H14: 470 | I14: 470 | J14: 470 | K14: 470 | L14: 0 | M14: 0 | N14: 0 | O14: 4230
A15: 0 | B15: Salary 15th | C15: 30951 | D15: 28750 | E15: 29850 | F15: 26963 | G15: 27743 | H15: 28785 | I15: 28935 | J15: 29177 | K15: 35935 | L15: 0 | M15: 0 | N15: 0 | O15: 267089
A16: 0 | B16: Salary 30th | C16: 31630 | D16: 30400 | E16: 30962 | F16: 28343 | G16: 28985 | H16: 29692 | I16: 30435 | J16: 28985 | K16: 35242 | L16: 0 | M16: 0 | N16: 0 | O16: 274674
A17: 0 | B17: Mandatories | C17: 14130 | D17: 14130 | E17: 14130 | F17: 12025 | G17: 12025 | H17: 12025 | I17: 12025 | J17: 12025 | K17: 12025 | L17: 0 | M17: 0 | N17: 0 | O17: 114540
A18: 0 | B18: Gas Avanza | C18: 3000 | D18: 3000 | E18: 3000 | F18: 3000 | G18: 3000 | H18: 3000 | I18: 3000 | J18: 3000 | K18: 3000 | L18: 0 | M18: 0 | N18: 0 | O18: 27000
A19: 0 | B19: Food and water | C19: 3842 | D19: 3683 | E19: 4149 | F19: 3907 | G19: 3668 | H19: 4720 | I19: 4370 | J19: 3940 | K19: 3742 | L19: 0 | M19: 0 | N19: 0 | O19: 36021
A20: 0 | B20: lalamove/ Delivery | C20: 6340 | D20: 4058 | E20: 2595 | F20: 7480 | G20: 7565 | H20: 10190 | I20: 5330 | J20: 2900 | K20: 2775 | L20: 0 | M20: 0 | N20: 0 | O20: 49233
A21: 0 | B21: Grocery | C21: 3974 | D21: 1749 | E21: 2062 | F21: 1415 | G21: 1800 | H21: 2230 | I21: 1764 | J21: 919 | K21: 920 | L21: 0 | M21: 0 | N21: 0 | O21: 16833
A22: 0 | B22: Ishabella ADMIN | C22: 2500 | D22: 2500 | E22: 2500 | F22: 2500 | G22: 2500 | H22: 2500 | I22: 2500 | J22: 2500 | K22: 2500 | L22: 0 | M22: 0 | N22: 0 | O22: 22500
A23: 0 | B23: return item | C23: 545 | D23: 0 | E23: 260 | F23: 570 | G23: 260 | H23: 1090 | I23: 2070 | J23: 880 | K23: 0 | L23: 0 | M23: 0 | N23: 0 | O23: 5675
A24: 0 | B24: Acct. Firm | C24: 0 | D24: 0 | E24: 0 | F24: 7500 | G24: 0 | H24: 0 | I24: 0 | J24: 0 | K24: 0 | L24: 0 | M24: 0 | N24: 0 | O24: 7500
A25: 0 | B25: DR Reciept | C25: 0 | D25: 7500 | E25: 0 | F25: 0 | G25: 0 | H25: 0 | I25: 0 | J25: 0 | K25: 0 | L25: 0 | M25: 0 | N25: 0 | O25: 7500
... A29: 0 | B29: paypal | C29: 0 | D29: 0 | E29: 0 | F29: 0 | G29: 0 | H29: 0 | I29: 0 | J29: 1099 | K29: 0 | L29: 0 | M29: 0 | N29: 0 | O29: 1099
A30: Annual Expenses | B30: 161200 | C30: 13433.333 | D30: 13433.3 | E30: 13433.3 | F30: 13433.3 | G30: 13433.3 | H30: 13433.3 | I30: 13433.3 | J30: 13433.3 | K30: 13433.3 | L30: 0 | M30: 0 | N30: 0 | O30: 120899.73
A31: 13th Month | B31: 77000 | C31: 6416.6667 | D31: 6416.6667 | E31: 6416.6667 | F31: 6416.6667 | G31: 6416.6667 | H31: 6416.6667 | I31: 6416.6667 | J31: 6416.6667 | K31: 6416.6667 | L31: 0 | M31: 0 | N31: 0 | O31: 57750
A32: Business Permit | B32: 72200 | C32: 6016.6667 | D32: 6016.6667 | E32: 6016.6667 | F32: 6016.6667 | G32: 6016.6667 | H32: 6016.6667 | I32: 6016.6667 | J32: 6016.6667 | K32: 6016.6667 | L32: 0 | M32: 0 | N32: 0 | O32: 54150
A33: Give away / Calendar | B33: 12000 | C33: 1000 | D33: 1000 | E33: 1000 | F33: 1000 | G33: 1000 | H33: 1000 | I33: 1000 | J33: 1000 | K33: 1000 | L33: 0 | M33: 0 | N33: 0 | O33: 9000

Sheet Report
P15: Car Aircon parts | Q15: =D65 -> #REF! | R15: =D67 -> #REF! | U15: =D68 -> #REF!
P16: TOOLS | Q16: =H65 -> #REF! | R16: =H67 -> #REF! | U16: =H68 -> #REF!
P17: GENERAL | Q17: =D76 -> #REF! | R17: =D78 -> #REF! | U17: =D79 -> #REF!
P18: INSTALLATION MATERIALS | Q18: =H76 -> #REF! | R18: =H83 -> 513430 | U18: =H79 -> #REF!
Q19: =SUM(Q15:Q18) -> #REF!
A31: I. | B31: Total Annual
B32: Sales | F32: Expenses | G32: = | H32: =SUM(H33:H37) -> #REF!
B33: Gross Sales | C33: = | D33: =#REF! -> #REF! | F33: Agent Comm | G33: = | H33: =#REF! -> #REF!
B34: Cost of material | C34: = | D34: =#REF! -> #REF! | F34: Manager Incentive | G34: = | H34: =#REF! -> #REF!
B35: Declared Capital | C35: = | D35: =#REF! -> #REF! | F35: Owners Allowance | G35: = | H35: =#REF! -> #REF!
B36: Add on Capital | C36: = | D36: =#REF! -> #REF! | F36: Store Opex | G36: = | H36: =#REF! -> #REF!
F37: Store Manager Incentive | G37: = | H37: =#REF! -> #REF!
B39: Capitalization & Assets | D39: =SUM(D40:D44) -> 433300 | F39: Income
B40: Capitalization | C40: = | D40: =298000-18000 -> 280000 | F40: Net Income | G40: = | H40: =#REF! -> #REF!
B41: Motorcycle | C41: = | D41: 76000 | F41: Bottom Line | G41: = | H41: =#REF! -> #REF!
B42: CCTV | C42: = | D42: 15600 | F42: After Capitalization@1/3 | G42: = | H42: =H41-(D39*1/3) -> #REF!
B43: Receipts | C43: = | D43: 12800
B44: Store Improvement | C44: = | D44: 48900
B46: Sharing@50% | D46: =H42/2 -> #REF!
B47: Rod@60% | C47: = | D47: =$D$46*0.6 -> #REF!
B48: Vin@30% | C48: = | D48: =$D$46*0.3 -> #REF!
B49: Fred@10% | C49: = | D49: =$D$46*0.1 -> #REF!
A51: II. | B51: Collectibles | D51: =SUM(D52:D61) -> 897309
B52: Envirocool | C52: = | D52: 630839 | F52: For client visit, payment negotiation
B53: Janus | C53: = | D53: 0 | F53: For collection
B54: Anna | C54: = | D54: 0 | F54: For collection - January 22
B55: James | C55: = | D55: 0 | F55: OK
B56: ALB | C56: = | D56: 199090 | F56: For update
B57: ABG | C57: = | D57: 3115 | F57: OK
B58: Bobby | C58: = | D58: 5655 | F58: OK
B59: Ghie | C59: = | D59: 9350 | F59: OK
B60: Edlan | C60: = | D60: 25560 | F60: OK
B61: Benjie | C61: = | D61: =18400+5300 -> 23700 | F61: OK
A63: III. | B63: Categories Monthly
B64: Car Aircon parts | F64: TOOLS
B65: Sales | C65: = | D65: =SUMIFS(#REF!,#REF!,"CAR AIRCON") -> #REF! | F65: Sales | G65: = | H65: =SUMIFS(#REF!,#REF!,"TOOLS") -> #REF!
B66: Capital | C66: = | D66: =SUMIFS(#REF!,#REF!,"CAR AIRCON") -> #REF! | F66: Capital | G66: = | H66: =SUMIFS(#REF!,#REF!,"TOOLS") -> #REF!
B67: Mark up | C67: = | D67: =D65-D66 -> #REF! | F67: Mark up | G67: = | H67: =H65-H66 -> #REF!
B68: Mark up % | C68: = | D68: =IF(D65=0,0,D67/D65) -> #REF! | F68: Mark up % | H68: =IF(H65=0,0,H67/H65) -> #REF!
B69: - Max | C69: = | D69: 456300 | F69: - Max | G69: = | H69: 140223
...

Sheet Client Record
B1: INDEX
B5: Sum of Sales | C5: Column Labels
B6: Row Labels | C6: 1 | D6: 2 | E6: 3 | F6: 4 | G6: 5 | H6: 6 | I6: 7 | J6: 8 | K6: 9 | L6: 10 | M6: 11 | N6: 12 | P6: (blank)
B7: AGAPOR AIRCONDITIONING | D7: 900
B8: ALB | F8: 83899
B9: ANAKIN | D9: 7800 | E9: 8550 | F9: 8500 | G9: 8500
B10: ARNEL CAHIGAS | F10: 491 | G10: 780 | H10: 1040 | J10: 430
B11: ARVIN PASCO | G11: 1010 | H11: 464
B12: AXM RESTOWORKZ | C12: 900 | E12: 120 | F12: 2200 | H12: 1300 | I12: 1630
B13: BEMBOL | G13: 9770 | H13: 3855 | I13: 300 | J13: 145 | K13: 2000
B14: BERNABE DE VERA CONSTRUCTION | C14: 1338 | D14: 7750 | F14: 2140 | G14: 1040 | H14: 1555 | J14: 200
B15: BONG CANTILLAN | D15: 23295 | E15: 38700 | F15: 8070 | G15: 34234 | H15: 83760 | I15: 30660 | J15: 11875
B16: BRYAN CAR AIRCON | F16: 8492 | I16: 8800
B17: BUBOY CORONEL | C17: 9225 | D17: 7195 | E17: 4995 | F17: 15582 | G17: 49151 | H17: 5116 | I17: 4776
B18: CAPILI | C18: 5975 | D18: 2100 | E18: 3485 | F18: 1970 | I18: 2000
B19: CHIE ESTRELLA | F19: 8460 | G19: 3340 | J19: 6920
B20: CHROME EDGE | C20: 12815 | D20: 1650 | E20: 5900 | F20: 10300 | G20: 2450 | H20: 20550 | I20: 5100 | J20: 15836
B21: CJ PANTHER/SEVILLA | C21: 2055 | D21: 4626 | E21: 6315 | F21: 6001 | G21: 15395 | H21: 33455 | I21: 2370 | J21: 8750
B22: COOL LEAN | E22: 4400 | H22: 3534 | I22: 7495
B23: COOL TIME / JM DIAMAT | C23: 5650 | D23: 5250 | E23: 4400 | F23: 2800 | G23: 17100 | H23: 5500 | I23: 5550 | J23: 1200
B24: CRISJAP | C24: 30015 | D24: 29306 | E24: 43898 | F24: 42229 | G24: 64198 | H24: 26982 | I24: 56912 | J24: 21563
B25: DEMY | C25: 6940 | D25: 8450 | E25: 531 | F25: 100 | G25: 6786 | I25: 1900
B26: DXB KING JEFF | C26: 13320 | D26: 22436 | E26: 12115 | F26: 12545 | G26: 25092 | H26: 23005 | I26: 16133 | J26: 24682 | K26: 1600
B27: EDLAN | C27: 35400 | D27: 5800 | E27: 4928 | F27: 17580 | G27: 34496 | H27: 16715 | I27: 15640 | J27: 22934
B28: ENTENG CAR AIRCON | C28: 10410 | D28: 21930 | E28: 12575 | F28: 9424 | G28: 18400 | H28: 15252 | I28: 5956 | J28: 6722
B29: EUGENE | C29: 8700 | D29: 34398 | E29: 46700 | F29: 34370 | G29: 38482 | H29: 35380 | I29: 38680 | J29: 19230
B30: EVANGELISTA HOSPITAL | D30: 2290 | G30: 13601 | H30: 16506 | I30: 7471
B31: EXPLORER | J31: 700
B32: FLEXTRAC | H32: 3710 | I32: 1800
B33: GEORGE AUTOCARE | D33: 8100 | H33: 8900 | J33: 9000
B34: GIE | C34: 39555 | D34: 49192 | E34: 35276 | F34: 45469 | G34: 27222 | H34: 33747 | I34: 36018 | J34: 27346
B35: JAIMAX AUTOMOTIVE/COOLMAX | I35: 180
B36: JANSON | D36: 1900
B37: JAY ALVIN OCAMPO | D37: 3700 | G37: 4275
B38: JAY STA ROSA | C38: 7800 | D38: 7800
B39: JDS | E39: 19960 | F39: 23360 | G39: 860 | H39: 24720 | I39: 8350 | J39: 33055
B40: JEFFREY DALIT | C40: 2806 | E40: 5330 | F40: 568 | G40: 2808 | I40: 2988
B41: JHONVER AUTO AIRCON | F41: 1900 | I41: 5100 | J41: 7250
B42: JHUN M / MC MC | C42: 43955 | D42: 39496 | E42: 37625 | F42: 46746 | G42: 64300 | H42: 42152 | I42: 52865 | J42: 22841.5 | K42: 2200
B43: JHUN SPORTSMAN | D43: 6550 | E43: 3700 | F43: 7700 | G43: 2000 | H43: 5100 | I43: 3970 | J43: 3600 | K43: 2000
...

Sheet Workbook Map
A1: WORKBOOK REFURBISHMENT MAP
A2: Phase 1 — architecture, dependencies, current business rules and confirmation register
A3: Documentation only: no operational formulas or source data were changed. Original empty Cash sheet was reused.
A5: WORKBOOK INVENTORY — ORIGINAL 20 SHEETS
A6: # | B6: Original Sheet | C6: Classification | D6: Purpose | E6: Objects and data flow | F6: Status / notes
A7: 1 | B7: Report | C7: Report / legacy | D7: Annual management report with sales, costs, expenses, income and a monthly chart. | E7: Objects: Chart 1; formula report Upstream: Summary Downstream: Management output | F7: REVIEW — Hidden; stale 2021 chart title and broken report references.
A8: 2 | B8: Client Record | C8: Pivot / report | D8: Client-by-month sales matrix used to review purchasing history. | E8: Objects: PivotTable1 Upstream: Daily Sales Downstream: Client review | F8: SUPPORT — Hidden; one stale pivot item displays #REF!.
A9: 3 | B9: INDEX | C9: Dashboard / report | D9: Primary management dashboard for targets, running sales, bottom line and category charts. | E9: Objects: 8 charts; KPI formulas Upstream: Summary; Sales Summary Downstream: Management decisions | F9: CORE — Current visual front end; some chart labels and titles are stale.
A10: 4 | B10: Cash | C10: Empty / obsolete | D10: Original sheet was empty and hidden; repurposed in Phase 1 as Workbook Map. | E10: Objects: None Upstream: None Downstream: None | F10: REPURPOSED — No operational data was removed.
A11: 5 | B11: Summary | C11: Calculation / pivot / report | D11: Central monthly and annual financial model: sales, capital, cost, incentives, expenses, profit and bottom line. | E11: Objects: ADD_ON table; PivotTable1; 2 charts Upstream: Sales Summary; Expenses; Sales; INDEX Downstream: INDEX; Report | F11: CORE — Financial control center; contains inconsistent copied formulas that need confirmation.
A12: 6 | B12: Sales Summary | C12: Pivot / calculation | D12: Five PivotTables summarizing sales, capital, costs, categories and agents by month. | E12: Objects: PivotTables 1–5 Upstream: Daily Sales Downstream: Summary; INDEX | F12: CORE — Main aggregation layer between transactions and reports.
A13: 7 | B13: Inventory | C13: Master input / calculation | D13: Product master, codes, category, unit cost, selling price, stock start and running quantity. | E13: Objects: LIST table: 2,220 products Upstream: Code; Purchase Log; Daily Sales Downstream: Daily Sales; management controls | F13: CORE — Movement formulas rebuilt; 364 source-supported stock deficits remain open.
A14: 8 | B14: Daily Sales | C14: Transaction input / calculation | D14: Detailed sales-entry ledger with clients, products, quantity, price, cost, capital, markup and commission. | E14: Objects: sales table: 8,100 rows Upstream: Client List01; Inventory; ADD_ON Downstream: Sales Summary; client and stock pivots | F14: CORE — Transaction product/client keys and calculation engine repaired. 4,742 positive-sale rows calculate with stable table references; Sales ₱5,682,935.05, Total Cost ₱4,012,118.84, Agent Commission ₱150,211.23.
A15: 9 | B15: Expenses | C15: Input / calculation | D15: Monthly operating-expense schedule by category and item with annual totals. | E15: Objects: Monthly expense grid Upstream: Manual entries Downstream: Summary | F15: CORE — Totals are intact; structure is manual and month columns are irregular.
A16: 10 | B16: Client List01 | C16: Master input | D16: Client master with contact, company, address, category and assigned agent. | E16: Objects: Table28: 382 rows Upstream: Manual entries Downstream: Daily Sales; client pivots | F16: CORE — Initial column contains broken references; client name is the practical key.
A17: 11 | B17: Input Slicer | C17: Pivot support | D17: Distinct product and client lists used as PivotTable/slicer support. | E17: Objects: PivotTables 1–2 Upstream: Daily Sales / masters Downstream: Filtering support | F17: SUPPORT — Helper sheet; not intended for direct editing.
A18: 12 | B18: Sales | C18: Pivot / calculation support | D18: Wide historical pivot workspace supporting monthly and analytical sales outputs. | E18: Objects: PivotTable1 only; 1,102 columns × 92 rows Upstream: Daily Sales Downstream: Summary daily grid | F18: SUPPORT — Redundant lower pivots retired; live Summary anchor preserved.
... A26: 20 | B26: FREDSAN | C26: Support / uncertain | D26: Small two-column helper calculation; operational purpose is not evident from labels. | E26: Objects: 2 formulas Upstream: Unknown Downstream: Unknown | F26: CONFIRM — Confirm whether this sheet is active, legacy or experimental.
A29: CORE DEPENDENCY MAP
A30: Source | B30: Destination | C30: Data / logic transferred | D30: Mechanism | E30: State | F30: Risk / operating note
A31: Client List01 | B31: Daily Sales | C31: Client name lookup assigns agent and related client information. | D31: VLOOKUP to Table28 | E31: ACTIVE | F31: Client name spelling must match exactly.
A32: Inventory | B32: Daily Sales | C32: Product description/code lookup supplies item, category, store price and unit cost. | D32: 9,813 direct formula references | E32: PARTLY BROKEN | F32: Some rows use deleted or external lookup ranges.
A33: Summary.ADD_ON | B33: Daily Sales | C33: Category percentage converts Total Cost into declared Capital. | D33: GENERAL 5%; TOOLS 5%; INSTALLATION MATERIALS 3%; CAR AIRCON 5% | E33: ACTIVE | F33: Confirm whether rates are tax/add-on policy or temporary assumptions.
A34: Daily Sales | B34: Sales Summary | C34: Transaction table feeds monthly PivotTables for sales, capital, cost, category and agent totals. | D34: Pivot cache dependency | E34: ACTIVE | F34: Pivot refresh timing is operationally important.
A35: Daily Sales | B35: Daily Inventory | C35: Transaction quantities are summarized by product code. | D35: PivotTable1 | E35: ACTIVE | F35: Inventory Qty Sold depends on this pivot being refreshed.
A36: Daily Inventory | B36: Inventory | C36: Qty Sold is retrieved by product code into the stock equation. | D36: 2,209 direct formula references | E36: ACTIVE | F36: Returns zero if a code is absent.
A37: Purchased | B37: Inventory | C37: Purchased quantity should be retrieved by product code into stock movement. | D37: New Purchase Log table lookup/aggregation by product code | E37: RETIRED / REPLACEMENT PLANNED | F37: Owner confirmed the deleted Purchased sheet will not be restored; create a controlled Purchase Log from scratch before rebuilding Inventory[Purchased].
A38: Inventory | B38: STORE PRICE | C38: Product data, cost, capital, store price and stock feed discount pricing. | D38: 1,648 direct formula references | E38: RETIRED | F38: RETIRED — STORE PRICE sheet permanently deleted; this dependency will not be rebuilt.
A39: Expenses | B39: Summary | C39: Monthly expense totals feed the financial model. | D39: 12 direct month links | E39: ACTIVE | F39: August onward remain zero until entered.
A40: Sales Summary | B40: Summary | C40: Monthly sales capital and cost aggregates feed financial calculations. | D40: 39 direct references / GETPIVOTDATA | E40: ACTIVE WITH ISSUE | F40: Cost uses Unit Cost for Jan–Oct but Total Cost for Nov–Dec.
A41: Summary | B41: INDEX | C41: Targets, sales, progress and bottom line feed the dashboard. | D41: 52 direct formula references | E41: ACTIVE | F41: Dashboard accuracy depends entirely on Summary.
... A43: Summary | B43: Report | C43: Annual financial totals feed the hidden legacy report. | D43: 9 direct formula references | E43: ACTIVE WITH ERRORS | F43: Report also references deleted internal cells.
A46: CURRENT BUSINESS-RULE REGISTER — DOCUMENTED, NOT YET CORRECTED
A47: ID | B47: Rule | C47: Current workbook logic | D47: Primary location | E47: State / interpretation | F47: Confirmation required
A48: R01 | B48: Sales | C48: Quantity × Price + Delivery | D48: Daily Sales[Sales] | E48: ACTIVE — Delivery is added to revenue. | F48: Confirm whether Delivery is always billable revenue.
A49: R02 | B49: Unit cost | C49: Lookup product Unit Cost from Inventory | D49: Daily Sales[Unit Cost] | E49: ACTIVE — Cost per unit comes from product master. | F49: Some sales with missing product code resolve to zero.
A50: R03 | B50: Total cost | C50: Unit Cost × Quantity | D50: Daily Sales[Total Cost] | E50: ACTIVE — Extended transaction cost. | F50: Summary currently does not consistently use this measure.
A51: R04 | B51: Declared capital | C51: Total Cost × (1 + category add-on) | D51: Daily Sales[Capital] / Summary.ADD_ON | E51: ACTIVE — Add-on: General 5%, Tools 5%, Installation Materials 3%, Car Aircon 5%. | F51: Confirm meaning and ownership of the add-on percentage.
A52: R05 | B52: Transaction markup | C52: Sales − Capital − Delivery | D52: Daily Sales[Mark up] | E52: ACTIVE — Margin after declared capital and delivery. | F52: Confirm whether delivery should be removed after already being included in Sales.
A53: R06 | B53: Agent commission | C53: Store = 0; otherwise 30% of transaction markup | D53: Daily Sales[Agent Comm.] | E53: ACTIVE — Commission is margin-based, not sales-based. | F53: Confirm that every non-Store agent receives the same 30%.
...

Sheet Audit
A1: MODEL AUDIT & PHASE 0 BASELINE
A2: Baseline captured 2026-08-01 22:00 GMT+08 | Operational formulas and source data unchanged
A4: STORY IN BRIEF
A5: The transaction ledger still totals ₱5.683m and reconciles exactly to Summary for sales, total cost, and agent commission. The baseline scan found 21,156 visible errors, led by STORE PRICE, Daily Sales, and Inventory. Inventory has 23 movement-equation exceptions, one negative-stock item, and 412 positive-sales rows without a product code. The workbook text expected 4,942 active transactions; the measurable positive-sales count is 4,742, so the active-row definition needs confirmation before Phase 3.
A7: BASELINE KPI | B7: Value | C7: Source / definition | D7: Status
A8: Original sheets | B8: 20 | C8: Pre-Phase 0 workbook inventory | D8: BASELINE
A9: Positive-sales transactions | B9: 4742 | C9: Daily Sales rows where Sales > 0 | D9: REVIEW
A10: Transaction sales | B10: 5682935 | C10: SUM(sales[Sales]) | D10: PASS
A11: Transaction total cost | B11: 2952627.4 | C11: SUM(sales[Total Cost]) | D11: PASS
A12: Transaction agent commission | B12: 256529.59 | C12: SUM(sales[Agent Comm.]) | D12: PASS
A13: Inventory master rows | B13: 2209 | C13: Inventory rows with an item description | D13: BASELINE
A14: Visible formula errors | B14: 21156 | C14: Full 20-sheet baseline scan | D14: FAIL
A16: LIVE CONTROL | B16: Workbook source | C16: Control target | D16: Difference / count | E16: Status | F16: Owner action | G16: Phase | H16: Priority
A17: Sales-to-Summary reconciliation | B17: =SUM(#REF!) -> #REF! | C17: =#REF! -> #REF! | D17: =B17-C17 -> #REF! | E17: =IF(ABS(D17)<0.01,"PASS","FAIL") -> #REF! | F17: No action while difference is zero | G17: 6 | H17: HIGH
A18: Cost reconciliation | B18: =_xlfn.AGGREGATE(9,6,#REF!) -> #REF! | C18: =#REF! -> #REF! | D18: =B18-C18 -> #REF! | E18: =IF(ABS(D18)<0.01,"PASS","FAIL") -> #REF! | F18: No action while difference is zero | G18: 6 | H18: HIGH
A19: Commission reconciliation | B19: =_xlfn.AGGREGATE(9,6,#REF!) -> #REF! | C19: =#REF! -> #REF! | D19: =B19-C19 -> #REF! | E19: =IF(ABS(D19)<0.01,"PASS","FAIL") -> #REF! | F19: No action while difference is zero | G19: 6 | H19: HIGH
A20: Inventory equation exceptions | B20: {=SUMPRODUCT(--(ABS(#REF!-(#REF!+#REF!+#REF!-#REF!))>0.0001))} -> #REF! | D20: =B20 -> #REF! | E20: =IF(B20=0,"PASS","FAIL") -> #REF! | F20: Repair Running / movement formulas | G20: 4 | H20: HIGH
A21: Duplicate product-code rows | B21: {=SUMPRODUCT((#REF!<>"")*(COUNTIF(#REF!,#REF!)>1))} -> #REF! | D21: =B21 -> #REF! | E21: =IF(D21=0,"PASS","FAIL") -> #REF! | F21: Keep at zero | G21: 2 | H21: HIGH
A22: Missing client on positive-sales rows | B22: =COUNTIFS(#REF!,">0",#REF!,"") -> #REF! | D22: =B22 -> #REF! | E22: =IF(D22=0,"PASS","FAIL") -> #REF! | F22: Complete client reference | G22: 3 | H22: HIGH
A23: Missing item code on positive-sales rows | B23: =COUNTIFS(#REF!,">0",#REF!,"") -> #REF! | D23: =B23 -> #REF! | E23: =IF(D23=0,"PASS","FAIL") -> #REF! | F23: Repair product lookup / code | G23: 3 | H23: HIGH
A24: Negative running stock | B24: =COUNTIF(#REF!,"<0") -> #REF! | D24: =B24 -> #REF! | E24: =IF(B24=0,"PASS","FAIL") -> #REF! | F24: Trace purchases, sales and adjustments | G24: 4 | H24: HIGH
A25: Missing unit cost | B25: =COUNTIFS(#REF!,"<>",#REF!,0) -> #REF! | D25: =B25 -> #REF! | E25: =IF(D25=0,"PASS","FAIL") -> #REF! | F25: Complete product master cost | G25: 2 | H25: HIGH
A26: Sales exceeding available stock | B26: {=SUMPRODUCT(--(#REF!>(#REF!+#REF!+#REF!)))} -> #REF! | D26: =B26 -> #REF! | E26: =IF(B26=0,"PASS","FAIL") -> #REF! | F26: Trace stock movement | G26: 4 | H26: HIGH
A28: PRIORITY ISSUE LOG | B28: Sheet | C28: Range / object | D28: Severity | E28: Category | F28: Baseline finding | G28: Next phase | H28: Status
A29: 1 | B29: STORE PRICE | C29: LIST53 | D29: CRITICAL | E29: Formula | F29: Worksheet permanently deleted by owner instruction; Phase 0 figures retained as historical baseline | G29: 5 | H29: DELETED
A30: 2 | B30: Daily Sales | C30: sales | D30: CRITICAL | E30: Formula | F30: 6,493 #REF! errors; 412 positive-sales rows lack item code | G30: 3 | H30: OPEN
A31: 3 | B31: Inventory | C31: LIST | D31: CRITICAL | E31: Formula / stock | F31: 2,300 errors; 23 movement exceptions; 1 negative stock | G31: 4 | H31: OPEN
A32: 4 | B32: Summary | C32: B40:AA62 | D32: WARNING | E32: Financial logic | F32: 20 visible errors; break-even rules remain open | G32: 6 | H32: OPEN
A33: 5 | B33: Sales Summary | C33: PivotTables | D33: WARNING | E33: Pivot | F33: 17 visible errors including stale #REF! items | G33: 7 | H33: OPEN
A34: 6 | B34: INDEX | C34: Charts / KPI links | D34: WARNING | E34: Report | F34: 7 visible errors; dashboard depends on Summary | G34: 8 | H34: OPEN
A35: 7 | B35: Workbook Map | C35: U08:U12 | D35: WARNING | E35: Business rules | F35: Five owner decisions remain open | G35: 46028 | H35: CONFIRM
A36: 8 | B36: Phase 0 | C36: External file copy | D36: INFO | E36: Archival | F36: Workbook baseline captured; external archival copy cannot be created from the live sheet session | G36: 0 | H36: MANUAL COPY
A38: 20-SHEET ERROR BASELINE | B38: Visibility | C38: Used range | D38: Formula cells | E38: Reference errors | F38: #DIV/0! / other | G38: Total errors | H38: Phase
A39: Report | B39: Hidden | C39: A15:U92 | D39: 114 | E39: 28 | F39: 0 | G39: 28 | H39: 7
A40: Client Record | B40: Hidden | C40: B1:P184 | D40: 0 | E40: 1 | F40: 0 | G40: 1 | H40: 7
A41: Workbook Map | B41: Visible | C41: A1:I103 | D41: 0 | E41: 0 | F41: 0 | G41: 0 | H41: 0
A42: INDEX | B42: Visible | C42: B2:AV122 | D42: 227 | E42: 7 | F42: 0 | G42: 7 | H42: 8
A43: Summary | B43: Visible | C43: B1:AG174 | D43: 1414 | E43: 8 | F43: 12 | G43: 20 | H43: 6
A44: Sales Summary | B44: Visible | C44: B1:AG88 | D44: 4 | E44: 16 | F44: 1 | G44: 17 | H44: 7
A45: Inventory | B45: Visible | C45: A1:AA2213 | D45: 34334 | E45: 2299 | F45: 1 | G45: 2300 | H45: 4
...

Sheet Client List
A1: CLIENT MASTER & AGENT ASSIGNMENTS — 2026
A2: Aligned to the supplied customer codes; unmatched active names are flagged for review.
A4: TOTAL ACCOUNTS | B4: 195 | C4: MATCHED | D4: 193 | E4: UNMATCHED | F4: 2 | G4: ACTIVE | H4: 195
A6: Code | B6: Customer | C6: Terms | D6: Credit Limit | E6: Status | F6: Action | G6: Assigned Agent | H6: Assignment Status | I6: Agents Found | J6: DR Count | K6: Latest Sale | L6: Total Sales | M6: Agent Commission
A7: CUS-PILI-00001 | B7: 1984 CONSTRUCTIONS SERVICES | C7: — | D7: 0 | E7: Active | F7: Edit / Deactivate | G7: Store | H7: ASSIGNED | I7: Store | J7: 1 | K7: 46126 | L7: 2500 | M7: 0
A8: CUS-PILI-00002 | B8: 2RK AIRCON SERVICES | C8: — | D8: 0 | E8: Active | F8: Edit / Deactivate | G8: Store | H8: ASSIGNED | I8: Store | J8: 1 | K8: 46213 | L8: 470 | M8: 0
A9: CUS-PILI-00003 | B9: 3JE | C9: — | D9: 0 | E9: Active | F9: Edit / Deactivate | G9: Store | H9: ASSIGNED | I9: Store | J9: 1 | K9: 46127 | L9: 900 | M9: 0
A10: CUS-PILI-00004 | B10: 4ER | C10: — | D10: 0 | E10: Active | F10: Edit / Deactivate | G10: Store | H10: ASSIGNED | I10: Store | J10: 2 | K10: 46218 | L10: 5034 | M10: 0
A11: CUS-PILI-00005 | B11: 52ND WIND INC | C11: — | D11: 0 | E11: Active | F11: Edit / Deactivate | G11: Store | H11: ASSIGNED | I11: Store | J11: 3 | K11: 46265 | L11: 12855 | M11: 0
A12: CUS-PILI-00006 | B12: 6 JAM AUTOCARE CENTER/ ADAM ANDEO | C12: — | D12: 0 | E12: Active | F12: Edit / Deactivate | G12: Store | H12: ASSIGNED | I12: Store | J12: 3 | K12: 46240 | L12: 5000 | M12: 532.95
A13: CUS-PILI-00007 | B13: 7 MAJESTIC AC | C13: — | D13: 0 | E13: Active | F13: Edit / Deactivate | G13: Store | H13: ASSIGNED | I13: Store | J13: 1 | K13: 46108 | L13: 2700 | M13: 0
A14: CUS-PILI-00009 | B14: ABEL | C14: — | D14: 0 | E14: Active | F14: Edit / Deactivate | G14: Store | H14: ASSIGNED | I14: Store | J14: 17 | K14: 46265 | L14: 23800 | M14: 0
A15: CUS-PILI-00015 | B15: AGAPOR AIRCONDITIONING | C15: — | D15: 0 | E15: Active | F15: Edit / Deactivate | G15: Bro. Jr | H15: ASSIGNED | I15: Bro. Jr | J15: 1 | K15: 46076 | L15: 900 | M15: 115.5
A16: CUS-PILI-00018 | B16: AIRCOLD SERVE | C16: — | D16: 0 | E16: Active | F16: Edit / Deactivate | G16: Store | H16: ASSIGNED | I16: Store | J16: 1 | K16: 46259 | L16: 3810 | M16: 0
A17: CUS-PILI-00019 | B17: AIRCON BOY | C17: — | D17: 0 | E17: Active | F17: Edit / Deactivate | G17: Store | H17: ASSIGNED | I17: Store | J17: 2 | K17: 46079 | L17: 899 | M17: 0
A18: CUS-PILI-00022 | B18: AirCooled | C18: — | D18: 0 | E18: Active | F18: Edit / Deactivate | G18: Store | H18: ASSIGNED | I18: Store | J18: 23 | K18: 46291 | L18: 38442 | M18: 3370.2533
... A38: CUS-PILI-00057 | B38: BLUE CHIP GAMING | C38: — | D38: 0 | E38: Active | F38: Edit / Deactivate | G38: Store | H38: ASSIGNED | I38: Store | J38: 1 | K38: 46046 | L38: 635 | M38: 0
B39: BOBBY ARCABOS | C39: — | D39: 0 | E39: Active | F39: Edit / Deactivate | G39: Store | H39: ASSIGNED | I39: Store | J39: 2 | K39: 46226 | L39: 71100 | M39: 2871
A40: CUS-PILI-00059 | B40: BONG CANTILLAN | C40: — | D40: 0 | E40: Active | F40: Edit / Deactivate | G40: Store | H40: ASSIGNED | I40: Store | J40: 16 | K40: 46238 | L40: 230594 | M40: 0
A41: CUS-PILI-00061 | B41: BRIGHT AIRE | C41: — | D41: 0 | E41: Active | F41: Edit / Deactivate | G41: Store | H41: ASSIGNED | I41: Store | J41: 1 | K41: 46183 | L41: 50 | M41: 0
A42: CUS-PILI-00062 | B42: BRYAN CAR AIRCON | C42: — | D42: 0 | E42: Active | F42: Edit / Deactivate | G42: Store | H42: ASSIGNED | I42: Store | J42: 3 | K42: 46209 | L42: 17292 | M42: 0
A43: CUS-PILI-00063 | B43: BUBOY CORONEL | C43: — | D43: 0 | E43: Active | F43: Edit / Deactivate | G43: Store | H43: ASSIGNED | I43: Store | J43: 13 | K43: 46269 | L43: 102995 | M43: 0
A44: CUS-PILI-00064 | B44: CAA MECHANICAL ENGINEERING SERVICES | C44: — | D44: 0 | E44: Active | F44: Edit / Deactivate | G44: Store | H44: ASSIGNED | I44: Store | J44: 1 | K44: 46172 | L44: 3000 | M44: 0
A45: CUS-PILI-00065 | B45: CAPILI | C45: — | D45: 0 | E45: Active | F45: Edit / Deactivate | G45: Ptr. Rod | H45: ASSIGNED | I45: Ptr. Rod | J45: 7 | K45: 46211 | L45: 15530 | M45: 1515.3
A46: CUS-PILI-00066 | B46: CAR AIRCON HOME SERVICE | C46: — | D46: 0 | E46: Active | F46: Edit / Deactivate | G46: Store | H46: ASSIGNED | I46: Store | J46: 1 | K46: 46185 | L46: 1220 | M46: 0
A47: CUS-PILI-00067 | B47: CEMTRANS | C47: — | D47: 0 | E47: Active | F47: Edit / Deactivate | G47: Store | H47: ASSIGNED | I47: Store | J47: 2 | K47: 46062 | L47: 1350 | M47: 0
A48: CUS-PILI-00068 | B48: CGM | C48: — | D48: 0 | E48: Active | F48: Edit / Deactivate | G48: Store | H48: ASSIGNED | I48: Store | J48: 1 | K48: 46258 | L48: 2336 | M48: 0
A49: CUS-PILI-00069 | B49: CHIE ESTRELLA | C49: — | D49: 0 | E49: Active | F49: Edit / Deactivate | G49: Store | H49: ASSIGNED | I49: Store | J49: 5 | K49: 46288 | L49: 19950 | M49: 0
A50: CUS-PILI-00071 | B50: CHRISTIAN ESTANISLAO | C50: — | D50: 0 | E50: Active | F50: Edit / Deactivate | G50: Store | H50: ASSIGNED | I50: Store | J50: 1 | K50: 46193 | L50: 600 | M50: 0
A51: CUS-PILI-00072 | B51: CHROME EDGE | C51: — | D51: 0 | E51: Active | F51: Edit / Deactivate | G51: Store | H51: ASSIGNED | I51: Store | J51: 33 | K51: 46295 | L51: 81601 | M51: 0
... A159: CUS-PILI-00255 | B159: PHOMAR CONSTRUCTION SERVICES INC | C159: — | D159: 0 | E159: Active | F159: Edit / Deactivate | G159: STORE | H159: ASSIGNED | I159: STORE | J159: 1 | K159: 46269 | L159: 360 | M159: 0
B160: PRIME TEC | C160: — | D160: 0 | E160: Active | F160: Edit / Deactivate | G160: Store | H160: ASSIGNED | I160: Store | J160: 1 | K160: 46203 | L160: 3000 | M160: 238.5
A161: CUS-PILI-00260 | B161: PRO TECH | C161: — | D161: 0 | E161: Active | F161: Edit / Deactivate | G161: Store | H161: ASSIGNED | I161: Store | J161: 1 | K161: 46192 | L161: 375 | M161: 0
A162: CUS-PILI-00261 | B162: PRSC | C162: — | D162: 0 | E162: Active | F162: Edit / Deactivate | G162: Store | H162: ASSIGNED | I162: Store | J162: 1 | K162: 46223 | L162: 5060 | M162: 0
A163: CUS-PILI-00263 | B163: PSYCHRO | C163: — | D163: 0 | E163: Active | F163: Edit / Deactivate | G163: Store | H163: ASSIGNED | I163: Store | J163: 7 | K163: 46260 | L163: 9367 | M163: 0
A164: CUS-PILI-00264 | B164: PSYCOOL | C164: — | D164: 0 | E164: Active | F164: Edit / Deactivate | G164: Store | H164: ASSIGNED | I164: Store | J164: 1 | K164: 46210 | L164: 350 | M164: 0
A165: CUS-PILI-00265 | B165: PUREGOLD | C165: — | D165: 0 | E165: Active | F165: Edit / Deactivate | G165: Store | H165: ASSIGNED | I165: Store | J165: 1 | K165: 46151 | L165: 660 | M165: 0
A166: CUS-PILI-00269 | B166: R&M CONSTRUCTION INC | C166: — | D166: 0 | E166: Active | F166: Edit / Deactivate | G166: Store | H166: ASSIGNED | I166: Store | J166: 1 | K166: 46254 | L166: 4768 | M166: 0
A167: CUS-PILI-00272 | B167: RAFFY LP | C167: — | D167: 0 | E167: Active | F167: Edit / Deactivate | G167: Ptr. Rod | H167: ASSIGNED | I167: Ptr. Rod | J167: 8 | K167: 46286 | L167: 18203 | M167: 1917.15
A168: CUS-PILI-00274 | B168: RAM COOL | C168: — | D168: 0 | E168: Active | F168: Edit / Deactivate | G168: Store | H168: ASSIGNED | I168: Store | J168: 3 | K168: 46153 | L168: 1015 | M168: 0
...
