Workbook
Name Agent_Base_Rate: 'Executive Summary'!$C$39
Name Agent_High_Rate: 'Executive Summary'!$C$41
Name Agent_High_Sales_Threshold: 'Executive Summary'!$C$40
Name Agent_Online_Rate: 'Executive Summary'!$C$42
Name Agent_Savings_Rate: 'Executive Summary'!$C$43
Name Back_Office_Rate: 'Executive Summary'!$C$51
Name Back_Office_Threshold: 'Executive Summary'!$C$50
Name Ikot_Commission_Rate: 'Executive Summary'!$C$49
Name Manager_Base_Rate: 'Executive Summary'!$C$45
Name Manager_Category_Rates: '%Comm'!$B$31:$C$42
Name Manager_High_Rate: 'Executive Summary'!$C$46
Name Manager_Sales_Threshold: 'Executive Summary'!$C$44
Name Offering_Multiplier: 'Executive Summary'!$C$53
Name Sales_Staff_Rate: 'Executive Summary'!$C$48
Name Sales_Staff_Threshold: 'Executive Summary'!$C$47
Name Tithes_Rate: 'Executive Summary'!$C$52

Sheet Executive Summary
A1: EXECUTIVE SUMMARY | G1: 📑 NAVIGATION
G2: ➤ Executive Summary
A3: Selected Month: | B3: August | G3: ➤ Commission Summary
A5: KEY FINANCIAL METRICS | D5: COMMISSION SUMMARY | G5: ➤ Instructions
A6: Total Sales (Gross) | B6: ='Back Office Commission'!D27 -> 5363118.7 | D6: Agent Commission | E6: ='Commission Summary'!C33 -> 152734.16
A7: Store Sales | B7: ='Back Office Commission'!D21 -> 2848080.1 | D7: Back Office Commission | E7: ='Commission Summary'!C34 -> 65978.196 | G7: ➤ Monthly Commission
A8: Monthly Expenses | B8: ='Back Office Commission'!D23 -> 753463.83
A9: Net Income | B9: ='Back Office Commission'!D24 -> 438780.36 | D9: TOTAL COMMISSION PAYOUT | E9: =ROUND('Commission Summary'!J17,2)+ROUND('Commission Summary'!C34,2) -> 206115.16 | G9: ➤ Back Office Commission
A10: Bottomline Before BO Commission | B10: ='Back Office Commission'!D28 -> 438780.36
A11: True Bottomline | B11: ='Back Office Commission'!D29 -> 372802.16 | G11: ➤ AgentYearlySales
G13: ➤ ItemReportsCategory
A14: BACK OFFICE BREAKDOWN | D14: AGENT SALES
A15: Manager (Bert) | B15: ='Back Office Commission'!C7 -> 33645.193 | D15: Agent Monthly Sales | E15: ='Commission Summary'!C17 -> 2481318.6 | G15: ➤ %Comm
A16: Sales Staff (Riza) | B16: ='Back Office Commission'!C8 -> 14433.67 | D16: Agent Net Sales | E16: ='Commission Summary'!D17 -> 539544.19
A17: Raymart (Ikot) | B17: ='Back Office Commission'!C10 -> 2542.02 | G17: ➤ Store Expenses
A18: Back Office Staff | B18: =SUM('Back Office Commission'!C11:C15) -> 10969.509
G19: ➤ Ikot Sales
A20: KEY RATIOS | B20: =B3&" performance" -> August performance | C20: Target Range | D20: Status | E20: Definition
A21: Expense Ratio (Expenses/Gross) | B21: =IFERROR('Back Office Commission'!D23/'Back Office Commission'!D27,0) -> 0.14048987 | C21: 10% - 20% | D21: =IF(AND(B21>=0.1,B21<=0.2),"✅ Good",IF(B21<0.1,"⚠️ Low","🔴 High")) -> ✅ Good | E21: Monthly Expenses ÷ Total Gross Sales. Measures operational cost efficiency. | G21: ➤ Payslip 1 - 4
A22: Net Income Margin | B22: =IFERROR('Back Office Commission'!D24/'Back Office Commission'!D27,0) -> 0.081814405 | C22: 5% - 10% | D22: =IF(AND(B22>=0.05,B22<=0.1),"✅ Good",IF(B22<0.05,"⚠️ Low","🔴 High")) -> ✅ Good | E22: Net Income ÷ Total Gross Sales. Shows profitability after all costs. | G22: ➤ Payslip 5 - 8
A23: Commission as % of Gross Sales | B23: =IFERROR('Commission Summary'!C35/'Back Office Commission'!D27,0) -> 0.040780817 | C23: 2% - 5% | D23: =IF(AND(B23>=0.02,B23<=0.05),"✅ Good",IF(B23<0.02,"⚠️ Low","🔴 High")) -> ✅ Good | E23: Total Commissions ÷ Total Gross Sales. Measures sales cost efficiency. | G23: ➤ Payslip 9 - 10
G25: ➤ Agent Expenses
A26: ASSESSMENT GUIDE
A27: Meaning | B27: Symbol | C27: Status | G27: ➤ Agent Savings
A28: Ratio is within healthy range | B28: ✅ | C28: Within Target
A29: Needs attention - below recommended level | B29: ⚠️ | C29: Below Target
A30: Needs review - may indicate inefficiency | B30: 🔴 | C30: Above Target
A32: =IF(COUNTIFS(CategoryMonthlyRecords[Period],">="&DATE(2026,'Back Office Commission'!$K$3,1),CategoryMonthlyRecords[Period],"<"&EDATE(DATE(2026,'Back Office Commission'!$K$3,1),1))>0,"📋 Month drivers aligned: "&B3,"⚠️ No category records for selected month "&B3) -> 📋 Month drivers aligned: August
A34: COMMISSION COMMAND CENTER
A35: ="Single source of truth for commission rules and live "&B3&" qualification checks. Edit yellow cells only." -> Single source of truth for commission rules and live August qualification checks. Edit yellow cells only.
A37: EDITABLE COMMISSION CONTROLS
A38: Category | B38: Control | C38: Edit Value | D38: Trigger / Applies When | E38: Calculation Basis | F38: Used By | G38: Named Reference
A39: Sales Agents | B39: Direct base rate | C39: 0.2 | D39: Paid gross sales is at or below the direct-agent threshold | E39: Net Sales (commission basis) × applicable rate | F39: Monthly Commission | G39: Agent_Base_Rate
A40: Sales Agents | B40: Direct high-sales threshold | C40: 200000 | D40: Direct paid gross sales must be greater than this amount | E40: Selects the base or high direct-agent rate | F40: Monthly Commission | G40: Agent_High_Sales_Threshold
A41: Sales Agents | B41: Direct high rate | C41: 0.3 | D41: Paid gross sales is greater than the direct-agent threshold | E41: Net Sales (commission basis) × applicable rate | F41: Monthly Commission | G41: Agent_High_Rate
A42: Sales Agents | B42: Online rate | C42: 0.2 | D42: Agent mode is online | E42: Net Sales (commission basis) × online rate | F42: Monthly Commission | G42: Agent_Online_Rate
A43: Sales Agents | B43: Savings rate | C43: 0.05 | D43: Applied after agent-specific expenses | E43: (Commission − Agent Expense) × savings rate | F43: Commission Summary | G43: Agent_Savings_Rate
A44: Manager (Bert) | B44: Category rate source | C44: %Comm!B31:C42 | D44: Match each category for the selected month | E44: (Category Gross − allocated expense) × category rate | F44: Back Office Commission | G44: Manager_Category_Rates
A45: Manager (Bert) | B45: Expense allocation | C45: Gross sales ratio | D45: Allocation pool: Monthly Expenses + Total Agent Commission | E45: Pool × Rate-Tier Gross Sales ÷ Total Gross Sales | F45: Back Office Commission
A46: Manager (Bert) | B46: Month driver | C46: Executive Summary!B3 | D46: Uses selected-month category sales and expenses | E46: Sum of category-level net commissions | F46: Back Office Commission
...

Sheet Sales Performance
A1: SALES PERFORMANCE & GROWTH DRIVERS
A2: Live scorecard for revenue momentum, category mix, agent productivity, margin, and collections
A3: Selected Month | B3: ='Executive Summary'!B3 -> August | C3: Period | D3: =DATE(2026,MATCH(B3,{"January","February","March","April","May","June","July","August","September","October","November","December"},0),1) -> 46235
A5: Gross Sales | C5: Net Sales | E5: Net Sales Yield | G5: MoM Gross Growth | I5: Expense Ratio | K5: Ikot Collection Rate
A6: =SUMIFS(CategoryMonthlyRecords[Gross Sales],CategoryMonthlyRecords[Period],$D$3) -> 5363118.7 | C6: =SUMIFS(CategoryMonthlyRecords[Net Sales],CategoryMonthlyRecords[Period],$D$3) -> 1192244.2 | E6: =IFERROR(C6/A6,0) -> 0.22230427 | G6: =IFERROR(A6/SUMIFS(CategoryMonthlyRecords[Gross Sales],CategoryMonthlyRecords[Period],EDATE($D$3,-1))-1,0) -> 0.059309786 | I6: =IFERROR('Executive Summary'!B8/A6,0) -> 0.14048987 | K6: =IFERROR(INDEX('Ikot Summary'!$G$11:$G$22,MATCH($B$3,'Ikot Summary'!$A$11:$A$22,0)),0) -> 0.91379998
A8: STORY IN BRIEF
A9: {="In "&B3&", gross sales were "&TEXT(A6,"₱0.00,,")&"M, "&IF(G6>=0,"up ","down ")&TEXT(ABS(G6),"0.0%")&" versus the prior month. Net sales were "&TEXT(C6,"₱0.00,,")&"M ("&TEXT(E6,"0.0%")&" of gross). The top two categories contributed "&TEXT(IFERROR(SUM(LARGE(B16:B27,{1,2}))/A6,0),"0.0%")&", and the leading agent produced "&TEXT(IFERROR(MAX(C32:C41)/SUM(C32:C41),0),"0.0%")&" of agent paid sales. Prioritize collection follow-up, reactivate zero-sales agents, and protect margin in the highest-volume categories."} -> In August, gross sales were ₱5.36M, up 5.9% versus the prior month. Net sales were ₱1.19M (22.2% of gross). The top two categories contributed 62.9%, and the leading agent produced 54.6% of agent paid sales. Prioritize collection follow-up, reactivate zero-sales agents, and protect margin in the highest-volume categories.
A13: CATEGORY PERFORMANCE | H13: GROSS SALES BY CATEGORY
A15: Category | B15: Gross Sales | C15: Sales Mix | D15: Net Sales | E15: Net Yield | F15: Growth Priority
A16: BATTERY | B16: =SUMIFS(CategoryMonthlyRecords[Gross Sales],CategoryMonthlyRecords[Period],$D$3,CategoryMonthlyRecords[Category],$A16) -> 1571000 | C16: =IFERROR(B16/$A$6,0) -> 0.29292658 | D16: =SUMIFS(CategoryMonthlyRecords[Net Sales],CategoryMonthlyRecords[Period],$D$3,CategoryMonthlyRecords[Category],$A16) -> 254356.4 | E16: =IFERROR(D16/B16,0) -> 0.16190732 | F16: =IF(B16=0,"No sales",IF(E16<10%,"Margin risk",IF(C16>=20%,"Protect & grow","Build pipeline"))) -> Protect & grow
A17: CAR AIRCON | B17: =SUMIFS(CategoryMonthlyRecords[Gross Sales],CategoryMonthlyRecords[Period],$D$3,CategoryMonthlyRecords[Category],$A17) -> 447523.27 | C17: =IFERROR(B17/$A$6,0) -> 0.083444596 | D17: =SUMIFS(CategoryMonthlyRecords[Net Sales],CategoryMonthlyRecords[Period],$D$3,CategoryMonthlyRecords[Category],$A17) -> 103451.63 | E17: =IFERROR(D17/B17,0) -> 0.2311648 | F17: =IF(B17=0,"No sales",IF(E17<10%,"Margin risk",IF(C17>=20%,"Protect & grow","Build pipeline"))) -> Build pipeline
A18: INSTALLATION MATERIALS | B18: =SUMIFS(CategoryMonthlyRecords[Gross Sales],CategoryMonthlyRecords[Period],$D$3,CategoryMonthlyRecords[Category],$A18) -> 1801410.4 | C18: =IFERROR(B18/$A$6,0) -> 0.3358886 | D18: =SUMIFS(CategoryMonthlyRecords[Net Sales],CategoryMonthlyRecords[Period],$D$3,CategoryMonthlyRecords[Category],$A18) -> 341325.57 | E18: =IFERROR(D18/B18,0) -> 0.18947685 | F18: =IF(B18=0,"No sales",IF(E18<10%,"Margin risk",IF(C18>=20%,"Protect & grow","Build pipeline"))) -> Protect & grow
A19: REFRIGERANTS | B19: =SUMIFS(CategoryMonthlyRecords[Gross Sales],CategoryMonthlyRecords[Period],$D$3,CategoryMonthlyRecords[Category],$A19) -> 320496.52 | C19: =IFERROR(B19/$A$6,0) -> 0.059759357 | D19: =SUMIFS(CategoryMonthlyRecords[Net Sales],CategoryMonthlyRecords[Period],$D$3,CategoryMonthlyRecords[Category],$A19) -> 110780.37 | E19: =IFERROR(D19/B19,0) -> 0.34565235 | F19: =IF(B19=0,"No sales",IF(E19<10%,"Margin risk",IF(C19>=20%,"Protect & grow","Build pipeline"))) -> Build pipeline
A20: PV PANELS | B20: =SUMIFS(CategoryMonthlyRecords[Gross Sales],CategoryMonthlyRecords[Period],$D$3,CategoryMonthlyRecords[Category],$A20) -> 0 | C20: =IFERROR(B20/$A$6,0) -> 0 | D20: =SUMIFS(CategoryMonthlyRecords[Net Sales],CategoryMonthlyRecords[Period],$D$3,CategoryMonthlyRecords[Category],$A20) -> 0 | E20: =IFERROR(D20/B20,0) -> 0 | F20: =IF(B20=0,"No sales",IF(E20<10%,"Margin risk",IF(C20>=20%,"Protect & grow","Build pipeline"))) -> No sales
A21: GENERAL | B21: =SUMIFS(CategoryMonthlyRecords[Gross Sales],CategoryMonthlyRecords[Period],$D$3,CategoryMonthlyRecords[Category],$A21) -> 64772.01 | C21: =IFERROR(B21/$A$6,0) -> 0.012077303 | D21: =SUMIFS(CategoryMonthlyRecords[Net Sales],CategoryMonthlyRecords[Period],$D$3,CategoryMonthlyRecords[Category],$A21) -> 18650.833 | E21: =IFERROR(D21/B21,0) -> 0.28794587 | F21: =IF(B21=0,"No sales",IF(E21<10%,"Margin risk",IF(C21>=20%,"Protect & grow","Build pipeline"))) -> Build pipeline
A22: AIRCON UNIT | B22: =SUMIFS(CategoryMonthlyRecords[Gross Sales],CategoryMonthlyRecords[Period],$D$3,CategoryMonthlyRecords[Category],$A22) -> 1058025 | C22: =IFERROR(B22/$A$6,0) -> 0.19727794 | D22: =SUMIFS(CategoryMonthlyRecords[Net Sales],CategoryMonthlyRecords[Period],$D$3,CategoryMonthlyRecords[Category],$A22) -> 342596 | E22: =IFERROR(D22/B22,0) -> 0.32380709 | F22: =IF(B22=0,"No sales",IF(E22<10%,"Margin risk",IF(C22>=20%,"Protect & grow","Build pipeline"))) -> Build pipeline
A23: TOOLS | B23: =SUMIFS(CategoryMonthlyRecords[Gross Sales],CategoryMonthlyRecords[Period],$D$3,CategoryMonthlyRecords[Category],$A23) -> 18235.76 | C23: =IFERROR(B23/$A$6,0) -> 0.0034002156 | D23: =SUMIFS(CategoryMonthlyRecords[Net Sales],CategoryMonthlyRecords[Period],$D$3,CategoryMonthlyRecords[Category],$A23) -> 4128.3059 | E23: =IFERROR(D23/B23,0) -> 0.22638519 | F23: =IF(B23=0,"No sales",IF(E23<10%,"Margin risk",IF(C23>=20%,"Protect & grow","Build pipeline"))) -> Build pipeline
A24: ELECTRICAL | B24: =SUMIFS(CategoryMonthlyRecords[Gross Sales],CategoryMonthlyRecords[Period],$D$3,CategoryMonthlyRecords[Category],$A24) -> 59985.68 | C24: =IFERROR(B24/$A$6,0) -> 0.01118485 | D24: =SUMIFS(CategoryMonthlyRecords[Net Sales],CategoryMonthlyRecords[Period],$D$3,CategoryMonthlyRecords[Category],$A24) -> 13161.94 | E24: =IFERROR(D24/B24,0) -> 0.21941803 | F24: =IF(B24=0,"No sales",IF(E24<10%,"Margin risk",IF(C24>=20%,"Protect & grow","Build pipeline"))) -> Build pipeline
A25: AIRCON PARTS | B25: =SUMIFS(CategoryMonthlyRecords[Gross Sales],CategoryMonthlyRecords[Period],$D$3,CategoryMonthlyRecords[Category],$A25) -> 20000 | C25: =IFERROR(B25/$A$6,0) -> 0.0037291735 | D25: =SUMIFS(CategoryMonthlyRecords[Net Sales],CategoryMonthlyRecords[Period],$D$3,CategoryMonthlyRecords[Category],$A25) -> 3387.622 | E25: =IFERROR(D25/B25,0) -> 0.1693811 | F25: =IF(B25=0,"No sales",IF(E25<10%,"Margin risk",IF(C25>=20%,"Protect & grow","Build pipeline"))) -> Build pipeline
A26: INVERTER | B26: =SUMIFS(CategoryMonthlyRecords[Gross Sales],CategoryMonthlyRecords[Period],$D$3,CategoryMonthlyRecords[Category],$A26) -> 0 | C26: =IFERROR(B26/$A$6,0) -> 0 | D26: =SUMIFS(CategoryMonthlyRecords[Net Sales],CategoryMonthlyRecords[Period],$D$3,CategoryMonthlyRecords[Category],$A26) -> 0 | E26: =IFERROR(D26/B26,0) -> 0 | F26: =IF(B26=0,"No sales",IF(E26<10%,"Margin risk",IF(C26>=20%,"Protect & grow","Build pipeline"))) -> No sales
A27: CONSTRUCTION | B27: =SUMIFS(CategoryMonthlyRecords[Gross Sales],CategoryMonthlyRecords[Period],$D$3,CategoryMonthlyRecords[Category],$A27) -> 1670 | C27: =IFERROR(B27/$A$6,0) -> 0.00031138599 | D27: =SUMIFS(CategoryMonthlyRecords[Net Sales],CategoryMonthlyRecords[Period],$D$3,CategoryMonthlyRecords[Category],$A27) -> 405.52101 | E27: =IFERROR(D27/B27,0) -> 0.24282695 | F27: =IF(B27=0,"No sales",IF(E27<10%,"Margin risk",IF(C27>=20%,"Protect & grow","Build pipeline"))) -> Build pipeline
A29: AGENT PRODUCTIVITY | H29: PAID SALES BY AGENT
A31: Agent | B31: Mode | C31: Paid Sales | D31: Net Sales | E31: Net Yield | F31: Coaching Priority
A32: ='Commission Summary'!A7 -> ARNOLD ORTIZ | B32: ='Commission Summary'!B7 -> direct | C32: ='Commission Summary'!C7 -> 113401 | D32: ='Commission Summary'!D7 -> 26067.4 | E32: =IFERROR(D32/C32,0) -> 0.22986923 | F32: =IF(C32=0,"Inactive",IF(E32<10%,"Low margin",IF(C32>=AVERAGEIF($C$32:$C$41,">0"),"Scale","Develop"))) -> Develop
A33: ='Commission Summary'!A8 -> JENNIFER DUM-OGAN - ONLINE | B33: ='Commission Summary'!B8 -> online | C33: ='Commission Summary'!C8 -> 23556.88 | D33: ='Commission Summary'!D8 -> 7491.37 | E33: =IFERROR(D33/C33,0) -> 0.31801198 | F33: =IF(C33=0,"Inactive",IF(E33<10%,"Low margin",IF(C33>=AVERAGEIF($C$32:$C$41,">0"),"Scale","Develop"))) -> Develop
A34: ='Commission Summary'!A9 -> JOVY VILLANUEVA | B34: ='Commission Summary'!B9 -> direct | C34: ='Commission Summary'!C9 -> 33922 | D34: ='Commission Summary'!D9 -> 6104.24 | E34: =IFERROR(D34/C34,0) -> 0.1799493 | F34: =IF(C34=0,"Inactive",IF(E34<10%,"Low margin",IF(C34>=AVERAGEIF($C$32:$C$41,">0"),"Scale","Develop"))) -> Develop
A35: ='Commission Summary'!A10 -> MARIVIC BRILLANTES | B35: ='Commission Summary'!B10 -> direct | C35: ='Commission Summary'!C10 -> 0 | D35: ='Commission Summary'!D10 -> 0 | E35: =IFERROR(D35/C35,0) -> 0 | F35: =IF(C35=0,"Inactive",IF(E35<10%,"Low margin",IF(C35>=AVERAGEIF($C$32:$C$41,">0"),"Scale","Develop"))) -> Inactive
A36: ='Commission Summary'!A11 -> MICHAEL PLAZA | B36: ='Commission Summary'!B11 -> direct | C36: ='Commission Summary'!C11 -> 817590.78 | D36: ='Commission Summary'!D11 -> 223600.76 | E36: =IFERROR(D36/C36,0) -> 0.27348738 | F36: =IF(C36=0,"Inactive",IF(E36<10%,"Low margin",IF(C36>=AVERAGEIF($C$32:$C$41,">0"),"Scale","Develop"))) -> Scale
A37: ='Commission Summary'!A12 -> MODESTO PAG-ARIGON | B37: ='Commission Summary'!B12 -> direct | C37: ='Commission Summary'!C12 -> 0 | D37: ='Commission Summary'!D12 -> 0 | E37: =IFERROR(D37/C37,0) -> 0 | F37: =IF(C37=0,"Inactive",IF(E37<10%,"Low margin",IF(C37>=AVERAGEIF($C$32:$C$41,">0"),"Scale","Develop"))) -> Inactive
A38: ='Commission Summary'!A13 -> MODESTO PAG-ARIGON - ONLINE | B38: ='Commission Summary'!B13 -> online | C38: ='Commission Summary'!C13 -> 48611.93 | D38: ='Commission Summary'!D13 -> 15357.74 | E38: =IFERROR(D38/C38,0) -> 0.31592533 | F38: =IF(C38=0,"Inactive",IF(E38<10%,"Low margin",IF(C38>=AVERAGEIF($C$32:$C$41,">0"),"Scale","Develop"))) -> Develop
A39: ='Commission Summary'!A14 -> RAMONITO VILLANUEVA - ONLINE | B39: ='Commission Summary'!B14 -> online | C39: ='Commission Summary'!C14 -> 44225.99 | D39: ='Commission Summary'!D14 -> 14231.88 | E39: =IFERROR(D39/C39,0) -> 0.32179901 | F39: =IF(C39=0,"Inactive",IF(E39<10%,"Low margin",IF(C39>=AVERAGEIF($C$32:$C$41,">0"),"Scale","Develop"))) -> Develop
A40: ='Commission Summary'!A15 -> ROCKY DELA PENA | B40: ='Commission Summary'!B15 -> direct | C40: ='Commission Summary'!C15 -> 45600 | D40: ='Commission Summary'!D15 -> 22038.31 | E40: =IFERROR(D40/C40,0) -> 0.48329627 | F40: =IF(C40=0,"Inactive",IF(E40<10%,"Low margin",IF(C40>=AVERAGEIF($C$32:$C$41,">0"),"Scale","Develop"))) -> Develop
A41: ='Commission Summary'!A16 -> ROD SANTIAGO | B41: ='Commission Summary'!B16 -> direct | C41: ='Commission Summary'!C16 -> 1354410 | D41: ='Commission Summary'!D16 -> 224652.49 | E41: =IFERROR(D41/C41,0) -> 0.16586742 | F41: =IF(C41=0,"Inactive",IF(E41<10%,"Low margin",IF(C41>=AVERAGEIF($C$32:$C$41,">0"),"Scale","Develop"))) -> Scale
A45: 3-MONTH SALES WINDOW | H45: GROSS VS NET SALES TREND
A47: Period | B47: Gross Sales | C47: Net Sales
A48: =EDATE($D$3,ROW()-49) -> 46204 | B48: =SUMIFS(CategoryMonthlyRecords[Gross Sales],CategoryMonthlyRecords[Period],A48) -> 5062842.5 | C48: =SUMIFS(CategoryMonthlyRecords[Net Sales],CategoryMonthlyRecords[Period],A48) -> 800129.45
A49: =EDATE($D$3,ROW()-49) -> 46235 | B49: =SUMIFS(CategoryMonthlyRecords[Gross Sales],CategoryMonthlyRecords[Period],A49) -> 5363118.7 | C49: =SUMIFS(CategoryMonthlyRecords[Net Sales],CategoryMonthlyRecords[Period],A49) -> 1192244.2
A50: =EDATE($D$3,ROW()-49) -> 46266 | B50: =SUMIFS(CategoryMonthlyRecords[Gross Sales],CategoryMonthlyRecords[Period],A50) -> 0 | C50: =SUMIFS(CategoryMonthlyRecords[Net Sales],CategoryMonthlyRecords[Period],A50) -> 0
A51: The right-hand month reflects records entered to date and may be partial.
A52: SALES ACTIONS
...

Sheet Commission Summary
A1: COMMISSION SUMMARY | D1: ➤ Executive Summary
A3: August | B3: ='Executive Summary'!B3 -> August
A5: AGENT COMMISSION
A6: Agent | B6: Mode | C6: Paid Gross Sales | D6: Net Sales (Commission Basis) | E6: Comm % | F6: Commission | G6: Expense | H6: Commission after Expense | I6: 5% Savings | J6: Final Commission
A7: ='Monthly Commission'!B6 -> ARNOLD ORTIZ | B7: ='Monthly Commission'!C6 -> direct | C7: ='Monthly Commission'!D6 -> 113401 | D7: ='Monthly Commission'!E6 -> 26067.4 | E7: ='Monthly Commission'!F6 -> 0.2 | F7: ='Monthly Commission'!G6 -> 5213.48 | G7: =IFERROR(INDEX('Agent Expense'!$B$5:$M$14,MATCH(A7,'Agent Expense'!$A$5:$A$14,0),MATCH($A$3,'Agent Expense'!$B$4:$M$4,0)),0) -> 2454 | H7: =F7-G7 -> 2759.48 | I7: =H7*Agent_Savings_Rate -> 137.974 | J7: =H7-I7 -> 2621.506
A8: ='Monthly Commission'!B7 -> JENNIFER DUM-OGAN - ONLINE | B8: ='Monthly Commission'!C7 -> online | C8: ='Monthly Commission'!D7 -> 23556.88 | D8: ='Monthly Commission'!E7 -> 7491.37 | E8: ='Monthly Commission'!F7 -> 0.2 | F8: ='Monthly Commission'!G7 -> 1498.274 | G8: =IFERROR(INDEX('Agent Expense'!$B$5:$M$14,MATCH(A8,'Agent Expense'!$A$5:$A$14,0),MATCH($A$3,'Agent Expense'!$B$4:$M$4,0)),0) -> 1000 | H8: =F8-G8 -> 498.274 | J8: =H8-I8 -> 498.274
A9: ='Monthly Commission'!B8 -> JOVY VILLANUEVA | B9: ='Monthly Commission'!C8 -> direct | C9: ='Monthly Commission'!D8 -> 33922 | D9: ='Monthly Commission'!E8 -> 6104.24 | E9: ='Monthly Commission'!F8 -> 0.2 | F9: ='Monthly Commission'!G8 -> 1220.848 | G9: =IFERROR(INDEX('Agent Expense'!$B$5:$M$14,MATCH(A9,'Agent Expense'!$A$5:$A$14,0),MATCH($A$3,'Agent Expense'!$B$4:$M$4,0)),0) -> 0 | H9: =F9-G9 -> 1220.848 | I9: =H9*Agent_Savings_Rate -> 61.0424 | J9: =H9-I9 -> 1159.8056
A10: ='Monthly Commission'!B9 -> MARIVIC BRILLANTES | B10: ='Monthly Commission'!C9 -> direct | C10: ='Monthly Commission'!D9 -> 0 | D10: ='Monthly Commission'!E9 -> 0 | E10: ='Monthly Commission'!F9 | F10: ='Monthly Commission'!G9 -> 0 | G10: =IFERROR(INDEX('Agent Expense'!$B$5:$M$14,MATCH(A10,'Agent Expense'!$A$5:$A$14,0),MATCH($A$3,'Agent Expense'!$B$4:$M$4,0)),0) -> 0 | H10: =F10-G10 -> 0 | I10: =H10*Agent_Savings_Rate -> 0 | J10: =H10-I10 -> 0
A11: ='Monthly Commission'!B10 -> MICHAEL PLAZA | B11: ='Monthly Commission'!C10 -> direct | C11: ='Monthly Commission'!D10 -> 817590.78 | D11: ='Monthly Commission'!E10 -> 223600.76 | E11: ='Monthly Commission'!F10 -> 0.3 | F11: ='Monthly Commission'!G10 -> 67080.228 | G11: =IFERROR(INDEX('Agent Expense'!$B$5:$M$14,MATCH(A11,'Agent Expense'!$A$5:$A$14,0),MATCH($A$3,'Agent Expense'!$B$4:$M$4,0)),0) -> 0 | H11: =F11-G11 -> 67080.228 | I11: =H11*Agent_Savings_Rate -> 3354.0114 | J11: =H11-I11 -> 63726.217
A12: ='Monthly Commission'!B11 -> MODESTO PAG-ARIGON | B12: ='Monthly Commission'!C11 -> direct | C12: ='Monthly Commission'!D11 -> 0 | D12: ='Monthly Commission'!E11 -> 0 | E12: ='Monthly Commission'!F11 | F12: ='Monthly Commission'!G11 -> 0 | G12: =IFERROR(INDEX('Agent Expense'!$B$5:$M$14,MATCH(A12,'Agent Expense'!$A$5:$A$14,0),MATCH($A$3,'Agent Expense'!$B$4:$M$4,0)),0) -> 0 | H12: =F12-G12 -> 0 | I12: =H12*Agent_Savings_Rate -> 0 | J12: =H12-I12 -> 0
A13: ='Monthly Commission'!B12 -> MODESTO PAG-ARIGON - ONLINE | B13: ='Monthly Commission'!C12 -> online | C13: ='Monthly Commission'!D12 -> 48611.93 | D13: ='Monthly Commission'!E12 -> 15357.74 | E13: ='Monthly Commission'!F12 -> 0.2 | F13: ='Monthly Commission'!G12 -> 3071.548 | G13: =IFERROR(INDEX('Agent Expense'!$B$5:$M$14,MATCH(A13,'Agent Expense'!$A$5:$A$14,0),MATCH($A$3,'Agent Expense'!$B$4:$M$4,0)),0) -> 1000 | H13: =F13-G13 -> 2071.548 | J13: =H13-I13 -> 2071.548
A14: ='Monthly Commission'!B13 -> RAMONITO VILLANUEVA - ONLINE | B14: ='Monthly Commission'!C13 -> online | C14: ='Monthly Commission'!D13 -> 44225.99 | D14: ='Monthly Commission'!E13 -> 14231.88 | E14: ='Monthly Commission'!F13 -> 0.2 | F14: ='Monthly Commission'!G13 -> 2846.376 | G14: =IFERROR(INDEX('Agent Expense'!$B$5:$M$14,MATCH(A14,'Agent Expense'!$A$5:$A$14,0),MATCH($A$3,'Agent Expense'!$B$4:$M$4,0)),0) -> 1000 | H14: =F14-G14 -> 1846.376 | J14: =H14-I14 -> 1846.376
A15: ='Monthly Commission'!B14 -> ROCKY DELA PENA | B15: ='Monthly Commission'!C14 -> direct | C15: ='Monthly Commission'!D14 -> 45600 | D15: ='Monthly Commission'!E14 -> 22038.31 | E15: ='Monthly Commission'!F14 -> 0.2 | F15: ='Monthly Commission'!G14 -> 4407.662 | G15: =IFERROR(INDEX('Agent Expense'!$B$5:$M$14,MATCH(A15,'Agent Expense'!$A$5:$A$14,0),MATCH($A$3,'Agent Expense'!$B$4:$M$4,0)),0) -> 0 | H15: =F15-G15 -> 4407.662 | I15: =H15*Agent_Savings_Rate -> 220.3831 | J15: =H15-I15 -> 4187.2789
A16: ='Monthly Commission'!B15 -> ROD SANTIAGO | B16: ='Monthly Commission'!C15 -> direct | C16: ='Monthly Commission'!D15 -> 1354410 | D16: ='Monthly Commission'!E15 -> 224652.49 | E16: ='Monthly Commission'!F15 -> 0.3 | F16: ='Monthly Commission'!G15 -> 67395.747 | G16: =IFERROR(INDEX('Agent Expense'!$B$5:$M$14,MATCH(A16,'Agent Expense'!$A$5:$A$14,0),MATCH($A$3,'Agent Expense'!$B$4:$M$4,0)),0) -> 0 | H16: =F16-G16 -> 67395.747 | I16: =H16*Agent_Savings_Rate -> 3369.7873 | J16: =H16-I16 -> 64025.96
A17: ='Monthly Commission'!B16 -> TOTAL | B17: ='Monthly Commission'!C16 -> 0 | C17: ='Monthly Commission'!D16 -> 2481318.6 | D17: ='Monthly Commission'!E16 -> 539544.19 | E17: ='Monthly Commission'!F16 -> 0.28307999 | F17: ='Monthly Commission'!G16 -> 152734.16 | G17: =SUM(G7:G16) -> 5454 | H17: =SUM(H7:H16) -> 147280.16 | I17: =SUM(I7:I16) -> 7143.1982 | J17: =SUM(J7:J16) -> 140136.96
A19: BACK OFFICE COMMISSION
A20: Recipient(s) | B20: Category | C20: Commission
A21: ='Back Office Commission'!A7 -> Bert | B21: ='Back Office Commission'!B7 -> Manager | C21: ='Back Office Commission'!C7 -> 33645.193
A22: ='Back Office Commission'!A8 -> Riza | B22: ='Back Office Commission'!B8 -> Sales Staff + Admin | C22: ='Back Office Commission'!C8 -> 14433.67
A23: ='Back Office Commission'!A9 -> Shiena | B23: ='Back Office Commission'!B9 -> Purchasing | C23: ='Back Office Commission'!C9 -> 4387.8036
A24: ='Back Office Commission'!A10 -> Raymart | B24: ='Back Office Commission'!B10 -> Raymart (Ikot) | C24: ='Back Office Commission'!C10 -> 2542.02
A25: ='Back Office Commission'!A11 -> Glydal | B25: ='Back Office Commission'!B11 -> Admin | C25: ='Back Office Commission'!C11 -> 2193.9018
A26: ='Back Office Commission'!A12 -> Vincent | B26: ='Back Office Commission'!B12 -> Logistics | C26: ='Back Office Commission'!C12 -> 1462.6012
A27: ='Back Office Commission'!A13 -> Jojo | B27: ='Back Office Commission'!B13 -> Logistics | C27: ='Back Office Commission'!C13 -> 1462.6012
A28: ='Back Office Commission'!A14 -> Mark | B28: ='Back Office Commission'!B14 -> Logistics | C28: ='Back Office Commission'!C14 -> 1462.6012
A29: ='Back Office Commission'!A15 -> Rod | B29: ='Back Office Commission'!B15 -> Marketing | C29: ='Back Office Commission'!C15 -> 4387.8036
A30: ='Back Office Commission'!A16 -> GRAND TOTAL | B30: ='Back Office Commission'!B16 -> 0 | C30: =SUM(C21:C29) -> 65978.196
A32: COMBINED TOTALS
A33: Agent Commission Total | C33: =F17 -> 152734.16
A34: Back Office Commission Total | C34: =C30 -> 65978.196
A35: GRAND TOTAL | C35: =ROUND(C33,2)+ROUND(C34,2) -> 218712.36

Sheet Instructions
A1: COMMISSION SYSTEM - USER GUIDE | B1: ➤ Executive Summary
A3: 1. SYSTEM OVERVIEW
A4: This workbook calculates commissions for ISHABELLA AIRCON AND REFRIGERATION PARTS TRADING.
A5: It covers two types of commissions:
A6: • Sales Agents (field agents who sell products)
A7: • Back Office Staff (manager, admin, logistics, etc.)
A9: 2. HOW TO USE
A11: Step 1: Select the Month
A12: • Go to the Executive Summary sheet (first tab)
A13: • Change cell B3 to the desired month (dropdown: January-December)
A14: • All calculations across all sheets will automatically update
A15: • Note: Monthly Commission and Back Office Commission sheets reference this selection
A17: Step 2: Review Key Metrics
... A29: SALES AGENTS (Monthly Commission sheet)
A30: =" • Direct Agents: "&TEXT(Agent_Base_Rate,"0%")&" when paid gross sales ≤ "&TEXT(Agent_High_Sales_Threshold,"₱#,##0")&"; "&TEXT(Agent_High_Rate,"0%")&" when above it" -> • Direct Agents: 20% when paid gross sales ≤ ₱200,000; 30% when above it
A31: =" • Online Agents: "&TEXT(Agent_Online_Rate,"0%")&" from the Executive Summary command center" -> • Online Agents: 20% from the Executive Summary command center
A32: • Commission amount is calculated from Net Sales × applicable rate
A34: MANAGER (Bert)
A35: • Manager commission uses the category rates in %Comm!B31:C42.
A36: • Monthly expenses and total agent commission are combined into one deduction pool.
A37: • Allocated deduction = (Monthly Expenses + Agent Commission) × Category Gross Sales ÷ Total Gross Sales.
A38: • Manager commission = (Category Gross Sales − Allocated Deduction) × matching category rate, summed across categories.
A39: SALES STAFF (Riza)
A40: =" • "&TEXT(Sales_Staff_Rate,"0.0%")&" if Store gross sales exceed "&TEXT(Sales_Staff_Threshold,"₱#,##0") -> • 0.5% if Store gross sales exceed ₱1,500,000
A41: • Net basis = Store Gross Sales - allocated monthly expenses
A42: • Allocated expenses = Monthly Expenses × Store Gross Sales ÷ Overall Monthly Sales (paid and unpaid from ItemReportsCategory)
A44: RAYMART (Ikot Sales)
A45: =" • "&TEXT(Ikot_Commission_Rate,"0.0%")&" of Net Ikot Sales (Ikot Sales - Ikot Expenses) for the month" -> • 1.0% of Net Ikot Sales (Ikot Sales - Ikot Expenses) for the month
A47: BACK OFFICE STAFF
A48: =" • Each department receives "&TEXT(Back_Office_Rate,"0.0%")&" of pre-commission Bottomline if it exceeds "&TEXT(Back_Office_Threshold,"₱#,##0") -> • Each department receives 1.0% of pre-commission Bottomline if it exceeds ₱300,000
A49: • Applies to: Purchasing (Shiena), Admin (Glydal, Riza), Logistics (Vincent, Jojo, Mark), Marketing (Rod)
A50: =" • If Bottomline before Back Office commission is ≤ "&TEXT(Back_Office_Threshold,"₱#,##0")&", no commission is paid under this category" -> • If Bottomline before Back Office commission is ≤ ₱300,000, no commission is paid under this category
A52: 4. CURRENT WORKBOOK STRUCTURE
A53: Sheet | B53: Purpose | C53: Primary Inputs
A54: Executive Summary | B54: Master month selector and management dashboard | C54: Executive Summary!B3
A55: Commission Summary | B55: Combined agent and Back Office payout report | C55: Monthly Commission; Back Office Commission
A56: Monthly Commission | B56: Agent commission from paid gross sales | C56: AgentYearlySales
A57: Back Office Commission | B57: Manager, Sales Staff, Raymart, and department commissions | C57: ItemReportsCategory; Store Expenses; Ikot Summary
A58: AgentYearlySales | B58: Monthly paid sales and historical agent records | C58: Manual/imported sales records
A59: ItemReportsCategory | B59: Overall paid and unpaid sales by category | C59: Monthly category report
...

Sheet Monthly Commission
A1: MONTHLY COMMISSION REPORT | J1: HELPER AREA
A3: Select Month: | B3: ='Executive Summary'!B3 -> August | D3: ➤ Executive Summary | J3: Month Index | K3: =MATCH(B3,{"January","February","March","April","May","June","July","August","September","October","November","December"},0) -> 8
A5: # | B5: Agent | C5: Mode | D5: Paid Gross Sales | E5: Net Sales (Commission Basis) | F5: Comm % | G5: Commission | J5: Month# | K5: Sales Col | L5: Capital Col | M5: NetSales Col | N5: Comm Col
A6: 1 | B6: ARNOLD ORTIZ | C6: direct | D6: {=IFERROR(VALUE(INDIRECT("AgentYearlySales!"&VLOOKUP($K$3,$J$6:$N$16,2,FALSE)&11)),0)} -> 113401 | E6: {=IFERROR(VALUE(INDIRECT("AgentYearlySales!"&VLOOKUP($K$3,$J$6:$N$16,4,FALSE)&11)),0)} -> 26067.4 | F6: =IF(D6=0,"",IF(LOWER(C6)="online",Agent_Online_Rate,IF(D6>Agent_High_Sales_Threshold,Agent_High_Rate,Agent_Base_Rate))) -> 0.2 | G6: =IF(E6<=0,0,E6*F6) -> 5213.48 | J6: 1 | K6: C | L6: D | M6: F | N6: H
A7: 2 | B7: JENNIFER DUM-OGAN - ONLINE | C7: online | D7: {=IFERROR(VALUE(INDIRECT("AgentYearlySales!"&VLOOKUP($K$3,$J$6:$N$16,2,FALSE)&12)),0)} -> 23556.88 | E7: {=IFERROR(VALUE(INDIRECT("AgentYearlySales!"&VLOOKUP($K$3,$J$6:$N$16,4,FALSE)&12)),0)} -> 7491.37 | F7: =IF(D7=0,"",IF(LOWER(C7)="online",Agent_Online_Rate,IF(D7>Agent_High_Sales_Threshold,Agent_High_Rate,Agent_Base_Rate))) -> 0.2 | G7: =IF(E7<=0,0,E7*F7) -> 1498.274 | J7: 2 | K7: I | L7: J | M7: L | N7: O
A8: 3 | B8: JOVY VILLANUEVA | C8: direct | D8: {=IFERROR(VALUE(INDIRECT("AgentYearlySales!"&VLOOKUP($K$3,$J$6:$N$16,2,FALSE)&13)),0)} -> 33922 | E8: {=IFERROR(VALUE(INDIRECT("AgentYearlySales!"&VLOOKUP($K$3,$J$6:$N$16,4,FALSE)&13)),0)} -> 6104.24 | F8: 0.2 | G8: =IF(E8<=0,0,E8*F8) -> 1220.848 | J8: 3 | K8: P | L8: Q | M8: S | N8: U
A9: 4 | B9: MARIVIC BRILLANTES | C9: direct | D9: {=IFERROR(VALUE(INDIRECT("AgentYearlySales!"&VLOOKUP($K$3,$J$6:$N$16,2,FALSE)&14)),0)} -> 0 | E9: {=IFERROR(VALUE(INDIRECT("AgentYearlySales!"&VLOOKUP($K$3,$J$6:$N$16,4,FALSE)&14)),0)} -> 0 | F9: =IF(D9=0,"",IF(LOWER(C9)="online",Agent_Online_Rate,IF(D9>Agent_High_Sales_Threshold,Agent_High_Rate,Agent_Base_Rate))) | G9: =IF(E9<=0,0,E9*F9) -> 0 | J9: 4 | K9: V | L9: W | M9: Y | N9: AA
A10: 5 | B10: MICHAEL PLAZA | C10: direct | D10: {=IFERROR(VALUE(INDIRECT("AgentYearlySales!"&VLOOKUP($K$3,$J$6:$N$16,2,FALSE)&15)),0)} -> 817590.78 | E10: {=IFERROR(VALUE(INDIRECT("AgentYearlySales!"&VLOOKUP($K$3,$J$6:$N$16,4,FALSE)&15)),0)} -> 223600.76 | F10: =IF(D10=0,"",IF(LOWER(C10)="online",Agent_Online_Rate,IF(D10>Agent_High_Sales_Threshold,Agent_High_Rate,Agent_Base_Rate))) -> 0.3 | G10: =IF(E10<=0,0,E10*F10) -> 67080.228 | J10: 5 | K10: AB | L10: AC | M10: AE | N10: AG
A11: 6 | B11: MODESTO PAG-ARIGON | C11: direct | D11: {=IFERROR(VALUE(INDIRECT("AgentYearlySales!"&VLOOKUP($K$3,$J$6:$N$16,2,FALSE)&16)),0)} -> 0 | E11: {=IFERROR(VALUE(INDIRECT("AgentYearlySales!"&VLOOKUP($K$3,$J$6:$N$16,4,FALSE)&16)),0)} -> 0 | F11: =IF(D11=0,"",IF(LOWER(C11)="online",Agent_Online_Rate,IF(D11>Agent_High_Sales_Threshold,Agent_High_Rate,Agent_Base_Rate))) | G11: =IF(E11<=0,0,E11*F11) -> 0 | J11: 6 | K11: AH | L11: AI | M11: AK | N11: AM
A12: 7 | B12: MODESTO PAG-ARIGON - ONLINE | C12: online | D12: {=IFERROR(VALUE(INDIRECT("AgentYearlySales!"&VLOOKUP($K$3,$J$6:$N$16,2,FALSE)&17)),0)} -> 48611.93 | E12: {=IFERROR(VALUE(INDIRECT("AgentYearlySales!"&VLOOKUP($K$3,$J$6:$N$16,4,FALSE)&17)),0)} -> 15357.74 | F12: =IF(D12=0,"",IF(LOWER(C12)="online",Agent_Online_Rate,IF(D12>Agent_High_Sales_Threshold,Agent_High_Rate,Agent_Base_Rate))) -> 0.2 | G12: =IF(E12<=0,0,E12*F12) -> 3071.548 | J12: 7 | K12: AN | L12: AO | M12: AQ | N12: AS
A13: 8 | B13: RAMONITO VILLANUEVA - ONLINE | C13: online | D13: {=IFERROR(VALUE(INDIRECT("AgentYearlySales!"&VLOOKUP($K$3,$J$6:$N$16,2,FALSE)&18)),0)} -> 44225.99 | E13: {=IFERROR(VALUE(INDIRECT("AgentYearlySales!"&VLOOKUP($K$3,$J$6:$N$16,4,FALSE)&18)),0)} -> 14231.88 | F13: =IF(D13=0,"",IF(LOWER(C13)="online",Agent_Online_Rate,IF(D13>Agent_High_Sales_Threshold,Agent_High_Rate,Agent_Base_Rate))) -> 0.2 | G13: =IF(E13<=0,0,E13*F13) -> 2846.376 | J13: 8 | K13: AT | L13: AU | M13: AW | N13: AY
A14: 9 | B14: ROCKY DELA PENA | C14: direct | D14: {=IFERROR(VALUE(INDIRECT("AgentYearlySales!"&VLOOKUP($K$3,$J$6:$N$16,2,FALSE)&19)),0)} -> 45600 | E14: {=IFERROR(VALUE(INDIRECT("AgentYearlySales!"&VLOOKUP($K$3,$J$6:$N$16,4,FALSE)&19)),0)} -> 22038.31 | F14: =IF(D14=0,"",IF(LOWER(C14)="online",Agent_Online_Rate,IF(D14>Agent_High_Sales_Threshold,Agent_High_Rate,Agent_Base_Rate))) -> 0.2 | G14: =IF(E14<=0,0,E14*F14) -> 4407.662 | J14: 9 | K14: AZ | L14: BA | M14: BC | N14: BE
A15: 10 | B15: ROD SANTIAGO | C15: direct | D15: {=IFERROR(VALUE(INDIRECT("AgentYearlySales!"&VLOOKUP($K$3,$J$6:$N$16,2,FALSE)&20)),0)} -> 1354410 | E15: {=IFERROR(VALUE(INDIRECT("AgentYearlySales!"&VLOOKUP($K$3,$J$6:$N$16,4,FALSE)&20)),0)} -> 224652.49 | F15: =IF(D15=0,"",IF(LOWER(C15)="online",Agent_Online_Rate,IF(D15>Agent_High_Sales_Threshold,Agent_High_Rate,Agent_Base_Rate))) -> 0.3 | G15: =IF(E15<=0,0,E15*F15) -> 67395.747 | J15: 10 | K15: BF | L15: BG | M15: BI | N15: BK
B16: TOTAL | D16: =SUM(D6:D15) -> 2481318.6 | E16: =SUM(E6:E15) -> 539544.19 | F16: =IFERROR(G16/E16,0) -> 0.28307999 | G16: =SUM(G6:G15) -> 152734.16 | J16: 12 | K16: BR | L16: BS | M16: BU | N16: BW
A18: COMPARISON: Calculated vs Recorded (AgentYearlySales)
A19: # | B19: Agent | C19: Mode | D19: Calculated Comm | E19: Recorded Commission | F19: Difference | G19: Status
A20: 1 | B20: ARNOLD ORTIZ | C20: direct | D20: =G6 -> 5213.48 | E20: {=IFERROR(VALUE(INDIRECT("AgentYearlySales!"&VLOOKUP($K$3,$J$6:$N$16,5,FALSE)&11)),0)} -> 5213.48 | F20: =D20-E20 -> 0 | G20: =IF(ABS(F20)<1,"✓ Match",IF(F20>0,"Underpaid","Overpaid")) -> ✓ Match
A21: 2 | B21: JENNIFER DUM-OGAN - ONLINE | C21: online | D21: =G7 -> 1498.274 | E21: {=IFERROR(VALUE(INDIRECT("AgentYearlySales!"&VLOOKUP($K$3,$J$6:$N$16,5,FALSE)&12)),0)} -> 1498.274 | F21: =D21-E21 -> 0 | G21: =IF(ABS(F21)<1,"✓ Match",IF(F21>0,"Underpaid","Overpaid")) -> ✓ Match
A22: 3 | B22: JOVY VILLANUEVA | C22: direct | D22: =G8 -> 1220.848 | E22: {=IFERROR(VALUE(INDIRECT("AgentYearlySales!"&VLOOKUP($K$3,$J$6:$N$16,5,FALSE)&13)),0)} -> 1220.848 | F22: =D22-E22 -> 0 | G22: =IF(ABS(F22)<1,"✓ Match",IF(F22>0,"Underpaid","Overpaid")) -> ✓ Match
A23: 4 | B23: MARIVIC BRILLANTES | C23: direct | D23: =G9 -> 0 | E23: {=IFERROR(VALUE(INDIRECT("AgentYearlySales!"&VLOOKUP($K$3,$J$6:$N$16,5,FALSE)&14)),0)} -> 0 | F23: =D23-E23 -> 0 | G23: =IF(ABS(F23)<1,"✓ Match",IF(F23>0,"Underpaid","Overpaid")) -> ✓ Match
A24: 5 | B24: MICHAEL PLAZA | C24: direct | D24: =G10 -> 67080.228 | E24: {=IFERROR(VALUE(INDIRECT("AgentYearlySales!"&VLOOKUP($K$3,$J$6:$N$16,5,FALSE)&15)),0)} -> 67080.228 | F24: =D24-E24 -> 0 | G24: =IF(ABS(F24)<1,"✓ Match",IF(F24>0,"Underpaid","Overpaid")) -> ✓ Match
A25: 6 | B25: MODESTO PAG-ARIGON | C25: direct | D25: =G11 -> 0 | E25: {=IFERROR(VALUE(INDIRECT("AgentYearlySales!"&VLOOKUP($K$3,$J$6:$N$16,5,FALSE)&16)),0)} -> 0 | F25: =D25-E25 -> 0 | G25: =IF(ABS(F25)<1,"✓ Match",IF(F25>0,"Underpaid","Overpaid")) -> ✓ Match
A26: 7 | B26: MODESTO PAG-ARIGON - ONLINE | C26: online | D26: =G12 -> 3071.548 | E26: {=IFERROR(VALUE(INDIRECT("AgentYearlySales!"&VLOOKUP($K$3,$J$6:$N$16,5,FALSE)&17)),0)} -> 3071.548 | F26: =D26-E26 -> 0 | G26: =IF(ABS(F26)<1,"✓ Match",IF(F26>0,"Underpaid","Overpaid")) -> ✓ Match
A27: 8 | B27: RAMONITO VILLANUEVA - ONLINE | C27: online | D27: =G13 -> 2846.376 | E27: {=IFERROR(VALUE(INDIRECT("AgentYearlySales!"&VLOOKUP($K$3,$J$6:$N$16,5,FALSE)&18)),0)} -> 2846.376 | F27: =D27-E27 -> 0 | G27: =IF(ABS(F27)<1,"✓ Match",IF(F27>0,"Underpaid","Overpaid")) -> ✓ Match
A28: 9 | B28: ROCKY DELA PENA | C28: direct | D28: =G14 -> 4407.662 | E28: {=IFERROR(VALUE(INDIRECT("AgentYearlySales!"&VLOOKUP($K$3,$J$6:$N$16,5,FALSE)&19)),0)} -> 4407.662 | F28: =D28-E28 -> 0 | G28: =IF(ABS(F28)<1,"✓ Match",IF(F28>0,"Underpaid","Overpaid")) -> ✓ Match
A29: 10 | B29: ROD SANTIAGO | C29: direct | D29: =G15 -> 67395.747 | E29: {=IFERROR(VALUE(INDIRECT("AgentYearlySales!"&VLOOKUP($K$3,$J$6:$N$16,5,FALSE)&20)),0)} -> 67395.747 | F29: =D29-E29 -> 0 | G29: =IF(ABS(F29)<1,"✓ Match",IF(F29>0,"Underpaid","Overpaid")) -> ✓ Match
B30: TOTAL | D30: =SUM(D20:D29) -> 152734.16 | E30: =SUM(E20:E29) -> 152734.16 | F30: =SUM(F20:F29) -> 0 | G30: =IF(ABS(F30)<1,"✓ Match",IF(F30>0,"Underpaid","Overpaid")) -> ✓ Match
A32: 📋 NOTES:
A33: • Agent commission is calculated from net sales using the existing rate per agent
A34: • Direct agents: 20% if monthly sales ≤ ₱199,999 | 30% if > ₱200,000

Sheet Back Office Commission
A1: BACK OFFICE COMMISSION | C1: ➤ Executive Summary
A3: Select Month: | B3: ='Executive Summary'!B3 -> August | J3: Month Index | K3: =MATCH(B3,{"January","February","March","April","May","June","July","August","September","October","November","December"},0) -> 8
A5: BACK OFFICE COMMISSION SUMMARY
A6: Recipient(s) | B6: Category | C6: Commission
A7: Bert | B7: Manager | C7: =E38 -> 33645.193
A8: Riza | B8: Sales Staff + Admin | C8: =E43+F53 -> 14433.67
A9: Shiena | B9: Purchasing | C9: =F52 -> 4387.8036
A10: Raymart | B10: Raymart (Ikot) | C10: =E48 -> 2542.02
A11: Glydal | B11: Admin | C11: =F53 -> 2193.9018
A12: Vincent | B12: Logistics | C12: =F54 -> 1462.6012
A13: Jojo | B13: Logistics | C13: =F54 -> 1462.6012
A14: Mark | B14: Logistics | C14: =F54 -> 1462.6012
A15: Rod | B15: Marketing | C15: =F55 -> 4387.8036
A16: GRAND TOTAL | C16: =SUM(C7:C15) -> 65978.196
A19: KEY METRICS FOR SELECTED MONTH | J19: Month# | K19: Sales Col | L19: Capital Col | M19: NetSales Col | N19: Comm Col
A20: Metric | B20: Source | C20: Formula | D20: Value | J20: 1 | K20: C | L20: D | M20: F | N20: H
A21: Store Gross Sales (Paid) | B21: AgentYearlySales | C21: INDIRECT | D21: {=IFERROR(VALUE(INDIRECT("AgentYearlySales!"&VLOOKUP($K$3,$J$20:$N$37,2,FALSE)&21)),0)} -> 2848080.1 | J21: 2 | K21: I | L21: J | M21: L | N21: O
A22: Overall Net Sales (Paid & Unpaid) | B22: ItemReportsCategory | C22: DIRECT | D22: =SUMIFS(CategoryMonthlyRecords[Net Sales],CategoryMonthlyRecords[Period],">="&DATE(2026,$K$3,1),CategoryMonthlyRecords[Period],"<"&EDATE(DATE(2026,$K$3,1),1)) -> 1192244.2 | J22: 3 | K22: P | L22: Q | M22: S | N22: U
A23: Monthly Expenses | B23: Store Expenses | C23: INDEX | D23: {=INDEX('Store Expenses'!D34:O34,1,K3)} -> 753463.83 | J23: 4 | K23: V | L23: W | M23: Y | N23: AA
A24: Operating Net Income | B24: Calculated | C24: Net Sales - Expenses | D24: =D22-D23 -> 438780.36 | J24: 5 | K24: AB | L24: AC | M24: AE | N24: AG
A25: Raymart Ikot Sales | B25: Ikot Summary | C25: INDEX/MATCH | D25: {=INDEX('Ikot Summary'!$B$27:$M$28,2,K3)} -> 265250 | J25: 6 | K25: AH | L25: AI | M25: AK | N25: AM
A26: Raymart Ikot Expenses | B26: Ikot Sales | C26: SUMIFS | D26: =SUMIFS('Ikot Sales'!I:I,'Ikot Sales'!A:A,"RAYMART",'Ikot Sales'!B:B,">="&DATE(2026,$K$3,1),'Ikot Sales'!B:B,"<"&EDATE(DATE(2026,$K$3,1),1)) -> 11048 | J26: 7 | K26: AN | L26: AO | M26: AQ | N26: AS
A27: Overall Gross Sales (Paid & Unpaid) | B27: ItemReportsCategory | C27: DIRECT | D27: =SUMIFS(CategoryMonthlyRecords[Gross Sales],CategoryMonthlyRecords[Period],">="&DATE(2026,$K$3,1),CategoryMonthlyRecords[Period],"<"&EDATE(DATE(2026,$K$3,1),1)) -> 5363118.7 | J27: 8 | K27: AT | L27: AU | M27: AW | N27: AY
A28: Bottomline Before Back Office Commission | B28: Calculated | C28: Operating Net Income | D28: =D24 -> 438780.36 | J28: 10 | K28: BF | L28: BG | M28: BI | N28: BK
A29: True Bottomline After Back Office Commission | B29: Calculated | C29: Pre-Comm Bottomline - BO Comm | D29: =D28-C16 -> 372802.16
A30: Tithes | B30: Calculated | C30: True Bottomline × command-center rate | D30: =D29*Tithes_Rate -> 37280.216 | J30: 11 | K30: BL | L30: BM | M30: BO | N30: BQ
A31: Offering | B31: Calculated | C31: Tithes × command-center multiplier | D31: =D30*Offering_Multiplier -> 37280.216 | J31: 12 | K31: BR | L31: BS | M31: BU | N31: BW
A34: 1. MANAGER COMMISSION — BREAKDOWN BY RATE
A35: Rate Tier | B35: Category Gross Sales | C35: Allocated Expenses + Agent Comm | D35: Net Commission Basis | E35: Commission
A36: 0.005 | B36: {=SUMPRODUCT((MONTH(CategoryMonthlyRecords[Period])=$K$3)*CategoryMonthlyRecords[Gross Sales]*(SUMIF('%Comm'!$B$31:$B$42,CategoryMonthlyRecords[Category],'%Comm'!$C$31:$C$42)=$A36))} -> 2629025 | C36: =IF($B$38=0,0,($D$23+'Commission Summary'!$C$33)*B36/$B$38) -> 444222.35 | D36: =MAX(B36-C36,0) -> 2184802.6 | E36: =D36*A36 -> 10924.013
A37: 0.01 | B37: {=SUMPRODUCT((MONTH(CategoryMonthlyRecords[Period])=$K$3)*CategoryMonthlyRecords[Gross Sales]*(SUMIF('%Comm'!$B$31:$B$42,CategoryMonthlyRecords[Category],'%Comm'!$C$31:$C$42)=$A37))} -> 2734093.7 | C37: =IF($B$38=0,0,($D$23+'Commission Summary'!$C$33)*B37/$B$38) -> 461975.64 | D37: =MAX(B37-C37,0) -> 2272118 | E37: =D37*A37 -> 22721.18
A38: TOTAL | B38: =SUM(B36:B37) -> 5363118.7 | C38: =SUM(C36:C37) -> 906198 | D38: =SUM(D36:D37) -> 4456920.7 | E38: =SUM(E36:E37) -> 33645.193
A40: 2. SALES STAFF COMMISSION
A41: Component | B41: Basis | C41: Rate | D41: Amount | E41: Commission
A42: Store Gross Sales qualification | B42: =D21 -> 2848080.1 | C42: =Sales_Staff_Rate -> 0.005 | D42: =IF(AND(D21>Sales_Staff_Threshold,D27>0),MAX(D21-(D23*D21/D27),0),0) -> 2447953.7 | E42: =D42*C42 -> 12239.768
A43: TOTAL | E43: =SUM(E42:E42) -> 12239.768
A45: 3. RAYMART COMMISSION (NET IKOT SALES)
A46: Component | B46: Basis | C46: Rate | D46: Amount | E46: Commission
A47: Raymart Net Ikot Sales | B47: =D25-D26 -> 254202 | C47: =Ikot_Commission_Rate -> 0.01 | D47: =D25-D26 -> 254202 | E47: =D47*C47 -> 2542.02
A48: TOTAL | E48: =E47 -> 2542.02
...

Sheet ItemReportsCategory
A1: MONTHLY CATEGORY RECORDS | F1: ➤ Executive Summary
A2: Recommended layout: append one row per category per month; enter only the input columns and let calculated columns update automatically.
A4: INPUTS: Period, Category, Quantity, Gross Sales, Base Cost, Add-on %, Channel, Commission Rate, Notes | CALCULATED: Add-on Amount, Capital, Markup, Agent Commission, Net Sales
A6: Period | B6: Category | C6: Quantity | D6: Gross Sales | E6: Base Cost | F6: Add-on % | G6: Add-on Amount | H6: Capital | I6: Markup | J6: Channel | K6: Commission Rate | L6: Agent Commission | M6: Net Sales | N6: Notes
A7: 46174 | B7: BATTERY | C7: 23 | D7: 1540200 | E7: 1284640 | F7: 0.01 | G7: =CategoryMonthlyRecords[[#This Row],[Base Cost]]*CategoryMonthlyRecords[[#This Row],[Add-on %]] -> 12846.4 | H7: =CategoryMonthlyRecords[[#This Row],[Base Cost]]+CategoryMonthlyRecords[[#This Row],[Add-on Amount]] -> 1297486.4 | I7: =CategoryMonthlyRecords[[#This Row],[Gross Sales]]-CategoryMonthlyRecords[[#This Row],[Capital]] -> 242713.6 | J7: Store | K7: 0 | L7: =MAX(0,CategoryMonthlyRecords[[#This Row],[Markup]]*CategoryMonthlyRecords[[#This Row],[Commission Rate]]) -> 0 | M7: =CategoryMonthlyRecords[[#This Row],[Markup]]-CategoryMonthlyRecords[[#This Row],[Agent Commission]]+CategoryMonthlyRecords[[#This Row],[Add-on Amount]] -> 255560 | N7: Imported from ItemReportsCategory
A8: 46174 | B8: CAR AIRCON | C8: 1944 | D8: 751895.6 | E8: 522676.98 | F8: 0.07 | G8: =CategoryMonthlyRecords[[#This Row],[Base Cost]]*CategoryMonthlyRecords[[#This Row],[Add-on %]] -> 36587.389 | H8: =CategoryMonthlyRecords[[#This Row],[Base Cost]]+CategoryMonthlyRecords[[#This Row],[Add-on Amount]] -> 559264.37 | I8: =CategoryMonthlyRecords[[#This Row],[Gross Sales]]-CategoryMonthlyRecords[[#This Row],[Capital]] -> 192631.23 | J8: Agent | K8: 0.15 | L8: =MAX(0,CategoryMonthlyRecords[[#This Row],[Markup]]*CategoryMonthlyRecords[[#This Row],[Commission Rate]]) -> 28894.685 | M8: =CategoryMonthlyRecords[[#This Row],[Markup]]-CategoryMonthlyRecords[[#This Row],[Agent Commission]]+CategoryMonthlyRecords[[#This Row],[Add-on Amount]] -> 200323.94 | N8: Imported from ItemReportsCategory
A9: 46174 | B9: INSTALLATION MATERIALS | C9: 5421.93 | D9: 1012643.2 | E9: 786462.09 | F9: 0.01 | G9: =CategoryMonthlyRecords[[#This Row],[Base Cost]]*CategoryMonthlyRecords[[#This Row],[Add-on %]] -> 7864.6209 | H9: =CategoryMonthlyRecords[[#This Row],[Base Cost]]+CategoryMonthlyRecords[[#This Row],[Add-on Amount]] -> 794326.71 | I9: =CategoryMonthlyRecords[[#This Row],[Gross Sales]]-CategoryMonthlyRecords[[#This Row],[Capital]] -> 218316.48 | J9: Agent | K9: 0.15 | L9: =MAX(0,CategoryMonthlyRecords[[#This Row],[Markup]]*CategoryMonthlyRecords[[#This Row],[Commission Rate]]) -> 32747.472 | M9: =CategoryMonthlyRecords[[#This Row],[Markup]]-CategoryMonthlyRecords[[#This Row],[Agent Commission]]+CategoryMonthlyRecords[[#This Row],[Add-on Amount]] -> 193433.63 | N9: Imported from ItemReportsCategory
A10: 46174 | B10: REFRIGERANTS | C10: 628 | D10: 1531349.1 | E10: 1402649.1 | F10: 0.01 | G10: =CategoryMonthlyRecords[[#This Row],[Base Cost]]*CategoryMonthlyRecords[[#This Row],[Add-on %]] -> 14026.491 | H10: =CategoryMonthlyRecords[[#This Row],[Base Cost]]+CategoryMonthlyRecords[[#This Row],[Add-on Amount]] -> 1416675.6 | I10: =CategoryMonthlyRecords[[#This Row],[Gross Sales]]-CategoryMonthlyRecords[[#This Row],[Capital]] -> 114673.53 | J10: Agent | K10: 0.15 | L10: =MAX(0,CategoryMonthlyRecords[[#This Row],[Markup]]*CategoryMonthlyRecords[[#This Row],[Commission Rate]]) -> 17201.029 | M10: =CategoryMonthlyRecords[[#This Row],[Markup]]-CategoryMonthlyRecords[[#This Row],[Agent Commission]]+CategoryMonthlyRecords[[#This Row],[Add-on Amount]] -> 111498.99 | N10: Imported from ItemReportsCategory
A11: 46174 | B11: PV PANELS | C11: 36 | D11: 309600 | E11: 253368 | F11: 0.01 | G11: =CategoryMonthlyRecords[[#This Row],[Base Cost]]*CategoryMonthlyRecords[[#This Row],[Add-on %]] -> 2533.68 | H11: =CategoryMonthlyRecords[[#This Row],[Base Cost]]+CategoryMonthlyRecords[[#This Row],[Add-on Amount]] -> 255901.68 | I11: =CategoryMonthlyRecords[[#This Row],[Gross Sales]]-CategoryMonthlyRecords[[#This Row],[Capital]] -> 53698.32 | J11: Store | K11: 0 | L11: =MAX(0,CategoryMonthlyRecords[[#This Row],[Markup]]*CategoryMonthlyRecords[[#This Row],[Commission Rate]]) -> 0 | M11: =CategoryMonthlyRecords[[#This Row],[Markup]]-CategoryMonthlyRecords[[#This Row],[Agent Commission]]+CategoryMonthlyRecords[[#This Row],[Add-on Amount]] -> 56232 | N11: Imported from ItemReportsCategory
A12: 46174 | B12: GENERAL | C12: 1454 | D12: 114627.84 | E12: 71853.7 | F12: 0.02 | G12: =CategoryMonthlyRecords[[#This Row],[Base Cost]]*CategoryMonthlyRecords[[#This Row],[Add-on %]] -> 1437.074 | H12: =CategoryMonthlyRecords[[#This Row],[Base Cost]]+CategoryMonthlyRecords[[#This Row],[Add-on Amount]] -> 73290.774 | I12: =CategoryMonthlyRecords[[#This Row],[Gross Sales]]-CategoryMonthlyRecords[[#This Row],[Capital]] -> 41337.066 | J12: Agent | K12: 0.3 | L12: =MAX(0,CategoryMonthlyRecords[[#This Row],[Markup]]*CategoryMonthlyRecords[[#This Row],[Commission Rate]]) -> 12401.12 | M12: =CategoryMonthlyRecords[[#This Row],[Markup]]-CategoryMonthlyRecords[[#This Row],[Agent Commission]]+CategoryMonthlyRecords[[#This Row],[Add-on Amount]] -> 30373.02 | N12: Imported from ItemReportsCategory
A13: 46174 | B13: AIRCON UNIT | C13: 2 | D13: 135760 | E13: 115720.93 | F13: 0 | G13: =CategoryMonthlyRecords[[#This Row],[Base Cost]]*CategoryMonthlyRecords[[#This Row],[Add-on %]] -> 0 | H13: =CategoryMonthlyRecords[[#This Row],[Base Cost]]+CategoryMonthlyRecords[[#This Row],[Add-on Amount]] -> 115720.93 | I13: =CategoryMonthlyRecords[[#This Row],[Gross Sales]]-CategoryMonthlyRecords[[#This Row],[Capital]] -> 20039.07 | J13: Store | K13: 0 | L13: =MAX(0,CategoryMonthlyRecords[[#This Row],[Markup]]*CategoryMonthlyRecords[[#This Row],[Commission Rate]]) -> 0 | M13: =CategoryMonthlyRecords[[#This Row],[Markup]]-CategoryMonthlyRecords[[#This Row],[Agent Commission]]+CategoryMonthlyRecords[[#This Row],[Add-on Amount]] -> 20039.07 | N13: Imported from ItemReportsCategory
A14: 46174 | B14: TOOLS | C14: 80 | D14: 45818.5 | E14: 25873.14 | F14: 0.03 | G14: =CategoryMonthlyRecords[[#This Row],[Base Cost]]*CategoryMonthlyRecords[[#This Row],[Add-on %]] -> 776.1942 | H14: =CategoryMonthlyRecords[[#This Row],[Base Cost]]+CategoryMonthlyRecords[[#This Row],[Add-on Amount]] -> 26649.334 | I14: =CategoryMonthlyRecords[[#This Row],[Gross Sales]]-CategoryMonthlyRecords[[#This Row],[Capital]] -> 19169.166 | J14: Agent | K14: 0.3 | L14: =MAX(0,CategoryMonthlyRecords[[#This Row],[Markup]]*CategoryMonthlyRecords[[#This Row],[Commission Rate]]) -> 5750.7497 | M14: =CategoryMonthlyRecords[[#This Row],[Markup]]-CategoryMonthlyRecords[[#This Row],[Agent Commission]]+CategoryMonthlyRecords[[#This Row],[Add-on Amount]] -> 14194.61 | N14: Imported from ItemReportsCategory
A15: 46174 | B15: ELECTRICAL | C15: 222 | D15: 56748.03 | E15: 42979.57 | F15: 0.03 | G15: =CategoryMonthlyRecords[[#This Row],[Base Cost]]*CategoryMonthlyRecords[[#This Row],[Add-on %]] -> 1289.3871 | H15: =CategoryMonthlyRecords[[#This Row],[Base Cost]]+CategoryMonthlyRecords[[#This Row],[Add-on Amount]] -> 44268.957 | I15: =CategoryMonthlyRecords[[#This Row],[Gross Sales]]-CategoryMonthlyRecords[[#This Row],[Capital]] -> 12479.073 | J15: Agent | K15: 0.3 | L15: =MAX(0,CategoryMonthlyRecords[[#This Row],[Markup]]*CategoryMonthlyRecords[[#This Row],[Commission Rate]]) -> 3743.7219 | M15: =CategoryMonthlyRecords[[#This Row],[Markup]]-CategoryMonthlyRecords[[#This Row],[Agent Commission]]+CategoryMonthlyRecords[[#This Row],[Add-on Amount]] -> 10024.738 | N15: Imported from ItemReportsCategory
A16: 46174 | B16: AIRCON PARTS | C16: 20 | D16: 46840 | E16: 33964 | F16: 0.03 | G16: =CategoryMonthlyRecords[[#This Row],[Base Cost]]*CategoryMonthlyRecords[[#This Row],[Add-on %]] -> 1018.92 | H16: =CategoryMonthlyRecords[[#This Row],[Base Cost]]+CategoryMonthlyRecords[[#This Row],[Add-on Amount]] -> 34982.92 | I16: =CategoryMonthlyRecords[[#This Row],[Gross Sales]]-CategoryMonthlyRecords[[#This Row],[Capital]] -> 11857.08 | J16: Agent | K16: 0.3 | L16: =MAX(0,CategoryMonthlyRecords[[#This Row],[Markup]]*CategoryMonthlyRecords[[#This Row],[Commission Rate]]) -> 3557.124 | M16: =CategoryMonthlyRecords[[#This Row],[Markup]]-CategoryMonthlyRecords[[#This Row],[Agent Commission]]+CategoryMonthlyRecords[[#This Row],[Add-on Amount]] -> 9318.876 | N16: Imported from ItemReportsCategory
A17: 46174 | B17: INVERTER | C17: 5 | D17: 2040 | E17: 1560 | F17: 0.01 | G17: =CategoryMonthlyRecords[[#This Row],[Base Cost]]*CategoryMonthlyRecords[[#This Row],[Add-on %]] -> 15.6 | H17: =CategoryMonthlyRecords[[#This Row],[Base Cost]]+CategoryMonthlyRecords[[#This Row],[Add-on Amount]] -> 1575.6 | I17: =CategoryMonthlyRecords[[#This Row],[Gross Sales]]-CategoryMonthlyRecords[[#This Row],[Capital]] -> 464.4 | J17: Store | K17: 0 | L17: =MAX(0,CategoryMonthlyRecords[[#This Row],[Markup]]*CategoryMonthlyRecords[[#This Row],[Commission Rate]]) -> 0 | M17: =CategoryMonthlyRecords[[#This Row],[Markup]]-CategoryMonthlyRecords[[#This Row],[Agent Commission]]+CategoryMonthlyRecords[[#This Row],[Add-on Amount]] -> 480 | N17: Imported from ItemReportsCategory
A18: 46174 | B18: CONSTRUCTION | C18: 2 | D18: 550 | E18: 301 | F18: 0.03 | G18: =CategoryMonthlyRecords[[#This Row],[Base Cost]]*CategoryMonthlyRecords[[#This Row],[Add-on %]] -> 9.03 | H18: =CategoryMonthlyRecords[[#This Row],[Base Cost]]+CategoryMonthlyRecords[[#This Row],[Add-on Amount]] -> 310.03 | I18: =CategoryMonthlyRecords[[#This Row],[Gross Sales]]-CategoryMonthlyRecords[[#This Row],[Capital]] -> 239.97 | J18: Agent | K18: 0.3 | L18: =MAX(0,CategoryMonthlyRecords[[#This Row],[Markup]]*CategoryMonthlyRecords[[#This Row],[Commission Rate]]) -> 71.991 | M18: =CategoryMonthlyRecords[[#This Row],[Markup]]-CategoryMonthlyRecords[[#This Row],[Agent Commission]]+CategoryMonthlyRecords[[#This Row],[Add-on Amount]] -> 177.009 | N18: Imported from ItemReportsCategory
... A34: 46235 | B34: ELECTRICAL | C34: 46 | D34: 59985.68 | E34: 41719.3 | F34: 0.03 | G34: =CategoryMonthlyRecords[[#This Row],[Base Cost]]*CategoryMonthlyRecords[[#This Row],[Add-on %]] -> 1251.579 | H34: =CategoryMonthlyRecords[[#This Row],[Base Cost]]+CategoryMonthlyRecords[[#This Row],[Add-on Amount]] -> 42970.879 | I34: =CategoryMonthlyRecords[[#This Row],[Gross Sales]]-CategoryMonthlyRecords[[#This Row],[Capital]] -> 17014.801 | J34: Agent | K34: 0.3 | L34: =MAX(0,CategoryMonthlyRecords[[#This Row],[Markup]]*CategoryMonthlyRecords[[#This Row],[Commission Rate]]) -> 5104.4403 | M34: =CategoryMonthlyRecords[[#This Row],[Markup]]-CategoryMonthlyRecords[[#This Row],[Agent Commission]]+CategoryMonthlyRecords[[#This Row],[Add-on Amount]] -> 13161.94 | N34: Imported from August 2026 sales report
A35: 46235 | B35: AIRCON UNIT | C35: 13 | D35: 1058025 | E35: 715429 | F35: 0 | G35: =CategoryMonthlyRecords[[#This Row],[Base Cost]]*CategoryMonthlyRecords[[#This Row],[Add-on %]] -> 0 | H35: =CategoryMonthlyRecords[[#This Row],[Base Cost]]+CategoryMonthlyRecords[[#This Row],[Add-on Amount]] -> 715429 | I35: =CategoryMonthlyRecords[[#This Row],[Gross Sales]]-CategoryMonthlyRecords[[#This Row],[Capital]] -> 342596 | J35: Store | K35: 0 | L35: =MAX(0,CategoryMonthlyRecords[[#This Row],[Markup]]*CategoryMonthlyRecords[[#This Row],[Commission Rate]]) -> 0 | M35: =CategoryMonthlyRecords[[#This Row],[Markup]]-CategoryMonthlyRecords[[#This Row],[Agent Commission]]+CategoryMonthlyRecords[[#This Row],[Add-on Amount]] -> 342596
A36: 46235 | B36: TOOLS | C36: 26 | D36: 18235.76 | E36: 12498.88 | F36: 0.03 | G36: =CategoryMonthlyRecords[[#This Row],[Base Cost]]*CategoryMonthlyRecords[[#This Row],[Add-on %]] -> 374.9664 | H36: =CategoryMonthlyRecords[[#This Row],[Base Cost]]+CategoryMonthlyRecords[[#This Row],[Add-on Amount]] -> 12873.846 | I36: =CategoryMonthlyRecords[[#This Row],[Gross Sales]]-CategoryMonthlyRecords[[#This Row],[Capital]] -> 5361.9136 | J36: Agent | K36: 0.3 | L36: =MAX(0,CategoryMonthlyRecords[[#This Row],[Markup]]*CategoryMonthlyRecords[[#This Row],[Commission Rate]]) -> 1608.5741 | M36: =CategoryMonthlyRecords[[#This Row],[Markup]]-CategoryMonthlyRecords[[#This Row],[Agent Commission]]+CategoryMonthlyRecords[[#This Row],[Add-on Amount]] -> 4128.3059
A37: 46235 | B37: CONSTRUCTION | C37: 6 | D37: 1670 | E37: 1104.89 | F37: 0.03 | G37: =CategoryMonthlyRecords[[#This Row],[Base Cost]]*CategoryMonthlyRecords[[#This Row],[Add-on %]] -> 33.1467 | H37: =CategoryMonthlyRecords[[#This Row],[Base Cost]]+CategoryMonthlyRecords[[#This Row],[Add-on Amount]] -> 1138.0367 | I37: =CategoryMonthlyRecords[[#This Row],[Gross Sales]]-CategoryMonthlyRecords[[#This Row],[Capital]] -> 531.9633 | J37: Agent | K37: 0.3 | L37: =MAX(0,CategoryMonthlyRecords[[#This Row],[Markup]]*CategoryMonthlyRecords[[#This Row],[Commission Rate]]) -> 159.58899 | M37: =CategoryMonthlyRecords[[#This Row],[Markup]]-CategoryMonthlyRecords[[#This Row],[Agent Commission]]+CategoryMonthlyRecords[[#This Row],[Add-on Amount]] -> 405.52101
A38: 46235 | B38: PV PANELS | F38: 0.01 | G38: =CategoryMonthlyRecords[[#This Row],[Base Cost]]*CategoryMonthlyRecords[[#This Row],[Add-on %]] -> 0 | H38: =CategoryMonthlyRecords[[#This Row],[Base Cost]]+CategoryMonthlyRecords[[#This Row],[Add-on Amount]] -> 0 | I38: =CategoryMonthlyRecords[[#This Row],[Gross Sales]]-CategoryMonthlyRecords[[#This Row],[Capital]] -> 0 | J38: Store | K38: 0 | L38: =MAX(0,CategoryMonthlyRecords[[#This Row],[Markup]]*CategoryMonthlyRecords[[#This Row],[Commission Rate]]) -> 0 | M38: =CategoryMonthlyRecords[[#This Row],[Markup]]-CategoryMonthlyRecords[[#This Row],[Agent Commission]]+CategoryMonthlyRecords[[#This Row],[Add-on Amount]] -> 0 | N38: No August activity — zero record
A39: 46235 | B39: INVERTER | F39: 0.01 | G39: =CategoryMonthlyRecords[[#This Row],[Base Cost]]*CategoryMonthlyRecords[[#This Row],[Add-on %]] -> 0 | H39: =CategoryMonthlyRecords[[#This Row],[Base Cost]]+CategoryMonthlyRecords[[#This Row],[Add-on Amount]] -> 0 | I39: =CategoryMonthlyRecords[[#This Row],[Gross Sales]]-CategoryMonthlyRecords[[#This Row],[Capital]] -> 0 | J39: Store | K39: 0 | L39: =MAX(0,CategoryMonthlyRecords[[#This Row],[Markup]]*CategoryMonthlyRecords[[#This Row],[Commission Rate]]) -> 0 | M39: =CategoryMonthlyRecords[[#This Row],[Markup]]-CategoryMonthlyRecords[[#This Row],[Agent Commission]]+CategoryMonthlyRecords[[#This Row],[Add-on Amount]] -> 0 | N39: No August activity — zero record
A40: 46266 | B40: BATTERY | F40: 0.01 | G40: =CategoryMonthlyRecords[[#This Row],[Base Cost]]*CategoryMonthlyRecords[[#This Row],[Add-on %]] -> 0 | H40: =CategoryMonthlyRecords[[#This Row],[Base Cost]]+CategoryMonthlyRecords[[#This Row],[Add-on Amount]] -> 0 | I40: =CategoryMonthlyRecords[[#This Row],[Gross Sales]]-CategoryMonthlyRecords[[#This Row],[Capital]] -> 0 | J40: Store | K40: 0 | L40: =MAX(0,CategoryMonthlyRecords[[#This Row],[Markup]]*CategoryMonthlyRecords[[#This Row],[Commission Rate]]) -> 0 | M40: =CategoryMonthlyRecords[[#This Row],[Markup]]-CategoryMonthlyRecords[[#This Row],[Agent Commission]]+CategoryMonthlyRecords[[#This Row],[Add-on Amount]] -> 0 | N40: Template for September 2026 — enter input columns
A41: 46266 | B41: CAR AIRCON | F41: 0.07 | G41: =CategoryMonthlyRecords[[#This Row],[Base Cost]]*CategoryMonthlyRecords[[#This Row],[Add-on %]] -> 0 | H41: =CategoryMonthlyRecords[[#This Row],[Base Cost]]+CategoryMonthlyRecords[[#This Row],[Add-on Amount]] -> 0 | I41: =CategoryMonthlyRecords[[#This Row],[Gross Sales]]-CategoryMonthlyRecords[[#This Row],[Capital]] -> 0 | J41: Agent | K41: 0.15 | L41: =MAX(0,CategoryMonthlyRecords[[#This Row],[Markup]]*CategoryMonthlyRecords[[#This Row],[Commission Rate]]) -> 0 | M41: =CategoryMonthlyRecords[[#This Row],[Markup]]-CategoryMonthlyRecords[[#This Row],[Agent Commission]]+CategoryMonthlyRecords[[#This Row],[Add-on Amount]] -> 0 | N41: Template for September 2026 — enter input columns
A42: 46266 | B42: INSTALLATION MATERIALS | F42: 0.01 | G42: =CategoryMonthlyRecords[[#This Row],[Base Cost]]*CategoryMonthlyRecords[[#This Row],[Add-on %]] -> 0 | H42: =CategoryMonthlyRecords[[#This Row],[Base Cost]]+CategoryMonthlyRecords[[#This Row],[Add-on Amount]] -> 0 | I42: =CategoryMonthlyRecords[[#This Row],[Gross Sales]]-CategoryMonthlyRecords[[#This Row],[Capital]] -> 0 | J42: Agent | K42: 0.15 | L42: =MAX(0,CategoryMonthlyRecords[[#This Row],[Markup]]*CategoryMonthlyRecords[[#This Row],[Commission Rate]]) -> 0 | M42: =CategoryMonthlyRecords[[#This Row],[Markup]]-CategoryMonthlyRecords[[#This Row],[Agent Commission]]+CategoryMonthlyRecords[[#This Row],[Add-on Amount]] -> 0 | N42: Template for September 2026 — enter input columns
